Workbook
Name AMENAZARAS: [1]CÁLCULOS!$B$29:$B$30
Name Entorno: Ponderación!$A$2:$B$11
Name Impacto: [2]Ponderación!$G$2:$H$4
Name Impacto: Ponderación!$G$2:$H$5
Name INTENSIDAD: [1]CÁLCULOS!$B$22:$B$26
Name Menor: "Severidad"
Name Naturaleza: [2]Ponderación!$A$2:$B$8
Name Naturaleza: Ponderación!$A$2:$B$11
Name Probabilidad: [2]Ponderación!$D$2:$E$4
Name Probabilidad: Ponderación!$D$2:$E$4

Sheet Matriz Riesgo y Op
D2: INSTITUTO NACIONAL ELECTORAL JLE PUEBLA SISTEMA DE GESTIÓN DE LA CALIDAD | L2: Versión: 0
D3: ANÁLISIS DE RIESGOS/OPORTUNIDADES PROCESO DE RECLUTAMIENTO Y SELECCIÓN | L3: Fecha de emisión: 06/03/2020
A5: ATENCIÓN A RIESGOS
A6: IDENTIFICACIÓN | I6: EVALUACIÓN | L6: SEGUIMIENTO
A7: CLASIFICACIÓN RIESGO | B7: ACTIVIDAD DEL PROCESO | C7: ¿CUAL ES EL RIESGO DE QUE NO SE REALICE LA ACTIVIDAD? | D7: PROBABILIDAD DE QUE PASE | E7: ¿QUÉ LO ORIGINO? | F7: CONSECUENCIAS | G7: IMPACTO AL PROCESO | H7: ENTORNO DEL RIESGO | I7: NIVEL DE OPORTUNIDAD | J7: CLASIFICACIÓN | K7: DICTAMEN | L7: CONCLUSIONES | M7: ACCIONES DE RESPUESTA | N7: RESPONSABLE
A8: Riesgo | B8: Notificación de la vacante | C8: Módulo operando con la plantilla incompleta | D8: Baja | E8: * La mala comunicación entre las instancias involucradas y responsables del área donde se generó la vacante (Responsable de Módulo y Vocal Distrital). | F8: * Incremento en los tiempos de atención por la falta de personal. * La observación por parte de las áreas encargadas del seguimiento de las actividades. | G8: Grave | H8: Operativo | I8: =IFERROR(VLOOKUP(H8,Naturaleza,2,FALSE)*VLOOKUP('[3]Matriz Riesgo y Op'!D8,Probabilidad,2,FALSE)*VLOOKUP('[3]Matriz Riesgo y Op'!G8,Impacto,2,FALSE),"") -> 70 | J8: =IF(A8="Riesgo",IF(I8="","",IF(AND(I8>0,I8<200),"Trivial",IF(OR(I8=200,AND(I8>200,I8<400)),"Tolerable",IF(OR(I8=400,AND(I8>400,I8<600)),"Moderado",IF(OR(I8=600,AND(I8>600,I8<800)),"Importante",IF(OR(I8=800,I8>800,I8<1000,I8=1000),"Intolerable","")))))),IF(A8="Oportunidad",IF(I8="","",IF(AND(I8>0,I8<250),"Limitada",IF(OR(I8=250,AND(I8>250,I8<500)),"Media",IF(OR(I8=500,AND(I8>500,I8<750)),"Potencial",IF(OR(I8=750,AND(I8>750,I8<=1000)),"Sobresaliente",""))))),"")) -> Trivial | K8: =IFERROR(VLOOKUP(J8,'[3]Parámetros de riesgo'!$B$27:$C$31,2,FALSE),IFERROR(VLOOKUP(J8,'[3]Parámetros de riesgo'!$H$27:$I$30,2,FALSE),"")) -> VIGILARLO | L8: =IFERROR(VLOOKUP(K8,'[3]Parámetros de riesgo'!$C$27:$D$31,2,FALSE),IFERROR(VLOOKUP(K8,'[3]Parámetros de riesgo'!$I$27:$J$30,2,FALSE),"")) -> Control rutinario, no afecta la secuencia e integridad del proceso y/o Partes Interesadas. Documentar las acciones de respuesta en la Evaluación de Efectividad de riesgos y oportunidades. | M8: Oficios y correos electrónicos de la renuncia. | N8: VED y VDRFE
M9: Oficios y correos electrónicos de la rescisión del contrato, en su caso, las constancias que justifiquen dicha acción. | N9: VED y VDRFE
A13: Riesgo | B13: Convocatoria Pública | C13: Aspirantes a cubrir la plaza nulos o limitados | D13: Baja | E13: * Omisión por parte de los vocales involucrados (VE y VRFE). | F13: * Que no se tengan Aspirantes o que el proceso de selección tienda a ser parcial. | G13: Grave | H13: Operativo | I13: =IFERROR(VLOOKUP(H13,Naturaleza,2,FALSE)*VLOOKUP('[3]Matriz Riesgo y Op'!D13,Probabilidad,2,FALSE)*VLOOKUP('[3]Matriz Riesgo y Op'!G13,Impacto,2,FALSE),"") -> 100 | J13: =IF(A13="Riesgo",IF(I13="","",IF(AND(I13>0,I13<200),"Trivial",IF(OR(I13=200,AND(I13>200,I13<400)),"Tolerable",IF(OR(I13=400,AND(I13>400,I13<600)),"Moderado",IF(OR(I13=600,AND(I13>600,I13<800)),"Importante",IF(OR(I13=800,I13>800,I13<1000,I13=1000),"Intolerable","")))))),IF(A13="Oportunidad",IF(I13="","",IF(AND(I13>0,I13<250),"Limitada",IF(OR(I13=250,AND(I13>250,I13<500)),"Media",IF(OR(I13=500,AND(I13>500,I13<750)),"Potencial",IF(OR(I13=750,AND(I13>750,I13<=1000)),"Sobresaliente",""))))),"")) -> Trivial | K13: =IFERROR(VLOOKUP(J13,'[3]Parámetros de riesgo'!$B$27:$C$31,2,FALSE),IFERROR(VLOOKUP(J13,'[3]Parámetros de riesgo'!$H$27:$I$30,2,FALSE),"")) -> VIGILARLO | L13: =IFERROR(VLOOKUP(K13,'[3]Parámetros de riesgo'!$C$27:$D$31,2,FALSE),IFERROR(VLOOKUP(K13,'[3]Parámetros de riesgo'!$I$27:$J$30,2,FALSE),"")) -> Control rutinario, no afecta la secuencia e integridad del proceso y/o Partes Interesadas. Documentar las acciones de respuesta en la Evaluación de Efectividad de riesgos y oportunidades. | M13: Realizar la difusión en los medios existentes. | N13: VED y VDRFE
M14: Asegurar evidencias por medio de Oficios y correos electrónicos sobre la publicación de la convocatoria. | N14: VED y VDRFE
M15: Constancias de evidencias de los medios mediante los cuales se difunda la invitación o convocatoria. | N15: VED y VDRFE
N16: VDE y VDRFE
N17: VDE y VDRFE
A18: Riesgo | B18: Verificar el perfil del cargo | C18: Selección de personal con el perfil no adecuado | D18: Baja | E18: * Omisión por parte del personal encargado de la recepción y revisión de la documentación de los Aspirantes. | F18: * Destitución del personal contratado. * Nueva convocatoria. * Resultados negativos y adversos en los intereses y metas del Instituto. | G18: Moderado | H18: Operativo | I18: =IFERROR(VLOOKUP(H18,Naturaleza,2,FALSE)*VLOOKUP('[3]Matriz Riesgo y Op'!D18,Probabilidad,2,FALSE)*VLOOKUP('[3]Matriz Riesgo y Op'!G18,Impacto,2,FALSE),"") -> 70 | J18: =IF(A18="Riesgo",IF(I18="","",IF(AND(I18>0,I18<200),"Trivial",IF(OR(I18=200,AND(I18>200,I18<400)),"Tolerable",IF(OR(I18=400,AND(I18>400,I18<600)),"Moderado",IF(OR(I18=600,AND(I18>600,I18<800)),"Importante",IF(OR(I18=800,I18>800,I18<1000,I18=1000),"Intolerable","")))))),IF(A18="Oportunidad",IF(I18="","",IF(AND(I18>0,I18<250),"Limitada",IF(OR(I18=250,AND(I18>250,I18<500)),"Media",IF(OR(I18=500,AND(I18>500,I18<750)),"Potencial",IF(OR(I18=750,AND(I18>750,I18<=1000)),"Sobresaliente",""))))),"")) -> Trivial | K18: =IFERROR(VLOOKUP(J18,'[3]Parámetros de riesgo'!$B$27:$C$31,2,FALSE),IFERROR(VLOOKUP(J18,'[3]Parámetros de riesgo'!$H$27:$I$30,2,FALSE),"")) -> VIGILARLO | L18: =IFERROR(VLOOKUP(K18,'[3]Parámetros de riesgo'!$C$27:$D$31,2,FALSE),IFERROR(VLOOKUP(K18,'[3]Parámetros de riesgo'!$I$27:$J$30,2,FALSE),"")) -> Control rutinario, no afecta la secuencia e integridad del proceso y/o Partes Interesadas. Documentar las acciones de respuesta en la Evaluación de Efectividad de riesgos y oportunidades. | M18: Solicitudes y Cédulas del Cargo debidamente requisitadas (que el perfil, funciones y responsabilidades correspondan al cargo vacante). | N18: VED y VDRFE
A23: Riesgo | B23: Evaluación de los Aspirantes | C23: Seleccionar a Aspirantes para continuar en el proceso, que no cubran el perfil requerido para el cargo | D23: Baja | E23: * No contar con las herramientas necesarias, para llevar a cabo una evaluación adecuada con los Aspirantes (no tener el examen, no tener red, fallas en el equipo de cómputo). | F23: * Reprogramación de fechas para la aplicación de exámenes lo que conlleva a retraso en la contratación del personal. | G23: Grave | H23: Operativo | I23: =IFERROR(VLOOKUP(H23,Naturaleza,2,FALSE)*VLOOKUP('[3]Matriz Riesgo y Op'!D23,Probabilidad,2,FALSE)*VLOOKUP('[3]Matriz Riesgo y Op'!G23,Impacto,2,FALSE),"") -> 100 | J23: =IF(A23="Riesgo",IF(I23="","",IF(AND(I23>0,I23<200),"Trivial",IF(OR(I23=200,AND(I23>200,I23<400)),"Tolerable",IF(OR(I23=400,AND(I23>400,I23<600)),"Moderado",IF(OR(I23=600,AND(I23>600,I23<800)),"Importante",IF(OR(I23=800,I23>800,I23<1000,I23=1000),"Intolerable","")))))),IF(A23="Oportunidad",IF(I23="","",IF(AND(I23>0,I23<250),"Limitada",IF(OR(I23=250,AND(I23>250,I23<500)),"Media",IF(OR(I23=500,AND(I23>500,I23<750)),"Potencial",IF(OR(I23=750,AND(I23>750,I23<=1000)),"Sobresaliente",""))))),"")) -> Trivial | K23: =IFERROR(VLOOKUP(J23,'[3]Parámetros de riesgo'!$B$27:$C$31,2,FALSE),IFERROR(VLOOKUP(J23,'[3]Parámetros de riesgo'!$H$27:$I$30,2,FALSE),"")) -> VIGILARLO | L23: =IFERROR(VLOOKUP(K23,'[3]Parámetros de riesgo'!$C$27:$D$31,2,FALSE),IFERROR(VLOOKUP(K23,'[3]Parámetros de riesgo'!$I$27:$J$30,2,FALSE),"")) -> Control rutinario, no afecta la secuencia e integridad del proceso y/o Partes Interesadas. Documentar las acciones de respuesta en la Evaluación de Efectividad de riesgos y oportunidades. | M23: Oficios y correos electrónicos sobre la aplicación de los exámenes y test al VRFEL y área administrativa. | N23: VED y VDRFE
A28: Riesgo | B28: Resultados | C28: No se cuenta con la certeza del conocimiento del personal evaluado | D28: Baja | E28: * Omisión en la publicación de los resultados. * Que no se publiquen o difundan los resultados y los Aspirantes no se presenten a la siguiente etapa por desconocimiento. | F28: * Retraso en la contratación. * Incumplimiento al principio de máxima publicidad. | G28: Grave | H28: Operativo | I28: =IFERROR(VLOOKUP(H28,Naturaleza,2,FALSE)*VLOOKUP('[3]Matriz Riesgo y Op'!D28,Probabilidad,2,FALSE)*VLOOKUP('[3]Matriz Riesgo y Op'!G28,Impacto,2,FALSE),"") -> 100 | J28: =IF(A28="Riesgo",IF(I28="","",IF(AND(I28>0,I28<200),"Trivial",IF(OR(I28=200,AND(I28>200,I28<400)),"Tolerable",IF(OR(I28=400,AND(I28>400,I28<600)),"Moderado",IF(OR(I28=600,AND(I28>600,I28<800)),"Importante",IF(OR(I28=800,I28>800,I28<1000,I28=1000),"Intolerable","")))))),IF(A28="Oportunidad",IF(I28="","",IF(AND(I28>0,I28<250),"Limitada",IF(OR(I28=250,AND(I28>250,I28<500)),"Media",IF(OR(I28=500,AND(I28>500,I28<750)),"Potencial",IF(OR(I28=750,AND(I28>750,I28<=1000)),"Sobresaliente",""))))),"")) -> Trivial | K28: =IFERROR(VLOOKUP(J28,'[3]Parámetros de riesgo'!$B$27:$C$31,2,FALSE),IFERROR(VLOOKUP(J28,'[3]Parámetros de riesgo'!$H$27:$I$30,2,FALSE),"")) -> VIGILARLO | L28: =IFERROR(VLOOKUP(K28,'[3]Parámetros de riesgo'!$C$27:$D$31,2,FALSE),IFERROR(VLOOKUP(K28,'[3]Parámetros de riesgo'!$I$27:$J$30,2,FALSE),"")) -> Control rutinario, no afecta la secuencia e integridad del proceso y/o Partes Interesadas. Documentar las acciones de respuesta en la Evaluación de Efectividad de riesgos y oportunidades. | M28: Oficios y correos electrónicos de estatus al VED. | N28: VED y VDRFE
A33: Riesgo | B33: Entrevista | C33: Seleccionar personal sin que se identifiquen sus cualidades o debilidades. | D33: Baja | E33: * Falta de cumplimiento a la normatividad establecida. * Aspirante no llega a entrevista, limitando las cantidad de Aspirantes al cargo. | F33: * No tener la certeza de que la persona cubre con el perfil del cargo. | G33: Grave | H33: Operativo | I33: =IFERROR(VLOOKUP(H33,Naturaleza,2,FALSE)*VLOOKUP('[3]Matriz Riesgo y Op'!D33,Probabilidad,2,FALSE)*VLOOKUP('[3]Matriz Riesgo y Op'!G33,Impacto,2,FALSE),"") -> 700 | J33: =IF(A33="Riesgo",IF(I33="","",IF(AND(I33>0,I33<200),"Trivial",IF(OR(I33=200,AND(I33>200,I33<400)),"Tolerable",IF(OR(I33=400,AND(I33>400,I33<600)),"Moderado",IF(OR(I33=600,AND(I33>600,I33<800)),"Importante",IF(OR(I33=800,I33>800,I33<1000,I33=1000),"Intolerable","")))))),IF(A33="Oportunidad",IF(I33="","",IF(AND(I33>0,I33<250),"Limitada",IF(OR(I33=250,AND(I33>250,I33<500)),"Media",IF(OR(I33=500,AND(I33>500,I33<750)),"Potencial",IF(OR(I33=750,AND(I33>750,I33<=1000)),"Sobresaliente",""))))),"")) -> Importante | K33: =IFERROR(VLOOKUP(J33,'[3]Parámetros de riesgo'!$B$27:$C$31,2,FALSE),IFERROR(VLOOKUP(J33,'[3]Parámetros de riesgo'!$H$27:$I$30,2,FALSE),"")) -> MINIMIZARLO | L33: =IFERROR(VLOOKUP(K33,'[3]Parámetros de riesgo'!$C$27:$D$31,2,FALSE),IFERROR(VLOOKUP(K33,'[3]Parámetros de riesgo'!$I$27:$J$30,2,FALSE),"")) -> Acción de contención inmediata, es importante generar una Cédula de no Conformidad eficaz y eficiente donde se realice un control específico y permanente ya que el riesgo es alto en la secuencia y la integridad del proceso y/o Partes interesadas. | M33: Generar cédula de no conformidad. | N33: VED y VDRFE
A38: Riesgo | B38: Designación de personal y lista de reserva | C38: Que el cargo aparezca vacante, cuando ya está designado | D38: Baja | E38: * Falta de cumplimiento a la normatividad establecida. * Omisión por parte de los vocales involucrados (VE y VRFE) para enviar propuesta de contratación. * Atraso en la contratación. | F38: * La observación por parte de las áreas encargadas del seguimiento de las actividades. * No contar con lista de reserva conlleva a emitir nuevas convocatorias, y en los módulos, a trabajar sin el total del personal requerido. | G38: Grave | H38: Operativo | I38: =IFERROR(VLOOKUP(H38,Naturaleza,2,FALSE)*VLOOKUP('[3]Matriz Riesgo y Op'!D38,Probabilidad,2,FALSE)*VLOOKUP('[3]Matriz Riesgo y Op'!G38,Impacto,2,FALSE),"") -> 490 | J38: =IF(A38="Riesgo",IF(I38="","",IF(AND(I38>0,I38<200),"Trivial",IF(OR(I38=200,AND(I38>200,I38<400)),"Tolerable",IF(OR(I38=400,AND(I38>400,I38<600)),"Moderado",IF(OR(I38=600,AND(I38>600,I38<800)),"Importante",IF(OR(I38=800,I38>800,I38<1000,I38=1000),"Intolerable","")))))),IF(A38="Oportunidad",IF(I38="","",IF(AND(I38>0,I38<250),"Limitada",IF(OR(I38=250,AND(I38>250,I38<500)),"Media",IF(OR(I38=500,AND(I38>500,I38<750)),"Potencial",IF(OR(I38=750,AND(I38>750,I38<=1000)),"Sobresaliente",""))))),"")) -> Moderado | K38: =IFERROR(VLOOKUP(J38,'[3]Parámetros de riesgo'!$B$27:$C$31,2,FALSE),IFERROR(VLOOKUP(J38,'[3]Parámetros de riesgo'!$H$27:$I$30,2,FALSE),"")) -> CONTROLARLO | L38: =IFERROR(VLOOKUP(K38,'[3]Parámetros de riesgo'!$C$27:$D$31,2,FALSE),IFERROR(VLOOKUP(K38,'[3]Parámetros de riesgo'!$I$27:$J$30,2,FALSE),"")) -> Documentar las acciones de respuesta en la Evaluación de Efectividad de riesgos y oportunidades e incluir controles permanentes ya que existe un riesgo moderado en la secuencia y la integridad del proceso y/o Partes Interesadas. | M38: Oficios y correos electrónicos sobre Aspirantes, designados al área administrativa. | N38: VED y VDRFE
M39: Envío de la Lista de reserva al VED, para su publicación. | N39: VED y VDRFE
A44: ATENCIÓN A OPORTUNIDADES
A45: IDENTIFICACIÓN | I45: EVALUACIÓN | L45: SEGUIMIENTO
A46: CLASIFICACIÓN OPORTUNIDAD | B46: ACTIVIDAD DEL PROCESO | C46: ¿CUÁL ES LA OPORTUNIDAD Y/O MEJORA EN LA ACTIVIDAD? | D46: PROBABILIDAD DE MEJORA | E46: ¿QUÉ ORIGINARÍA LA OPORTUNIDAD? | F46: BENEFICIOS | G46: IMPACTO DE LA MEJORA | H46: ENTORNO DE LA MEJORA | I46: NIVEL DE OPORTUNIDAD | J46: CLASIFICACIÓN | K46: DICTAMEN | L46: CONCLUSIONES | M46: ACCIONES DE RESPUESTA | N46: RESPONSABLE
A47: Oportunidad | B47: Notificación de la vacante | C47: Tener un seguimiento de la situación de los Funcionarios del Módulo que implique una vacante, para anticiparse a iniciar el proceso | D47: Baja | E47: * Planear con anticipación la convocatoria. | F47: * Tener mayor cantidad de Aspirantes. | G47: Leve | H47: Operativo | I47: =IFERROR(VLOOKUP(H47,Naturaleza,2,FALSE)*VLOOKUP('Matriz Riesgo y Op'!D47,Probabilidad,2,FALSE)*VLOOKUP('Matriz Riesgo y Op'!G47,Impacto,2,FALSE),"") -> 10 | J47: =IF(A47="Riesgo",IF(I47="","",IF(AND(I47>0,I47<200),"Trivial",IF(OR(I47=200,AND(I47>200,I47<400)),"Tolerable",IF(OR(I47=400,AND(I47>400,I47<600)),"Moderado",IF(OR(I47=600,AND(I47>600,I47<800)),"Importante",IF(OR(I47=800,I47>800,I47<1000,I47=1000),"Intolerable","")))))),IF(A47="Oportunidad",IF(I47="","",IF(AND(I47>0,I47<250),"Limitada",IF(OR(I47=250,AND(I47>250,I47<500)),"Media",IF(OR(I47=500,AND(I47>500,I47<750)),"Potencial",IF(OR(I47=750,AND(I47>750,I47<=1000)),"Sobresaliente",""))))),"")) -> Limitada | K47: =IFERROR(VLOOKUP(J47,'Parámetros de riesgo'!$B$27:$C$31,2,FALSE),IFERROR(VLOOKUP(J47,'Parámetros de riesgo'!$H$27:$I$30,2,FALSE),"")) -> A CONSIDERAR | L47: =IFERROR(VLOOKUP(K47,'Parámetros de riesgo'!$C$27:$D$31,2,FALSE),IFERROR(VLOOKUP(K47,'Parámetros de riesgo'!$I$27:$J$30,2,FALSE),"")) -> Oportunidad que genera un beneficio mínimo en el proceso y/o Partes Interesadas de la cual se espera un resultado inmediato. Documentar las acciones de respuesta en la Evaluación de Efectividad de riesgos y oportunidades. | M47: Mantener comunicación continúa con el Responsable de Módulo. | N47: VED y VDRFE
A52: Oportunidad | B52: Convocatoria Pública | C52: Asegurar la publicación de la convocatoria a través del mayor número de medios disponibles: la página oficial del INE, carteles, redes sociales, boletines de radio, etc. | D52: Alta | E52: * Ampliar la cobertura para poder llegar a más Ciudadanos con interés de trabajar en el INE. | F52: * Tener mayor cantidad de Aspirantes, para llevar a cabo una optima selección del personal. | G52: Moderado | H52: Operativo | I52: =IFERROR(VLOOKUP(H52,Naturaleza,2,FALSE)*VLOOKUP('Matriz Riesgo y Op'!D52,Probabilidad,2,FALSE)*VLOOKUP('Matriz Riesgo y Op'!G52,Impacto,2,FALSE),"") -> 700 | J52: =IF(A52="Riesgo",IF(I52="","",IF(AND(I52>0,I52<200),"Trivial",IF(OR(I52=200,AND(I52>200,I52<400)),"Tolerable",IF(OR(I52=400,AND(I52>400,I52<600)),"Moderado",IF(OR(I52=600,AND(I52>600,I52<800)),"Importante",IF(OR(I52=800,I52>800,I52<1000,I52=1000),"Intolerable","")))))),IF(A52="Oportunidad",IF(I52="","",IF(AND(I52>0,I52<250),"Limitada",IF(OR(I52=250,AND(I52>250,I52<500)),"Media",IF(OR(I52=500,AND(I52>500,I52<750)),"Potencial",IF(OR(I52=750,AND(I52>750,I52<=1000)),"Sobresaliente",""))))),"")) -> Potencial | K52: =IFERROR(VLOOKUP(J52,'Parámetros de riesgo'!$B$27:$C$31,2,FALSE),IFERROR(VLOOKUP(J52,'Parámetros de riesgo'!$H$27:$I$30,2,FALSE),"")) -> APROPIARSE | L52: =IFERROR(VLOOKUP(K52,'Parámetros de riesgo'!$C$27:$D$31,2,FALSE),IFERROR(VLOOKUP(K52,'Parámetros de riesgo'!$I$27:$J$30,2,FALSE),"")) -> Oportunidad con beneficios claros y específicos en el proceso de una o varias áreas y/o Partes Interesadas, de la cual se espera un resultado a corto y mediano plazo. Documentar las acciones de respuesta en la Evaluación de Efectividad de riesgos y oportunidades. | M52: Asegurar que la Convocatoria se emita con los requisitos claramente detallados, etapas del proceso, etc., así como que se difunda a través de los canales disponibles. | N52: VED y VDRFE
M53: Seguimiento a la Convocatoria en las plataformas en que se haya difundido la misma. | N53: VED y VDRFE
A57: Oportunidad | B57: Verificar el perfil del cargo | C57: Hacer hincapié al Aspirante de los requisitos solicitados en la convocatoria | D57: Baja | E57: * No invertir tiempo en Aspirantes que no cubren con el perfil del cargo. | F57: * Cubrir la vacante con Aspirantes que cumplan el perfil. | G57: Importante | H57: Operativo | I57: =IFERROR(VLOOKUP(H57,Naturaleza,2,FALSE)*VLOOKUP('Matriz Riesgo y Op'!D57,Probabilidad,2,FALSE)*VLOOKUP('Matriz Riesgo y Op'!G57,Impacto,2,FALSE),"") -> 100 | J57: =IF(A57="Riesgo",IF(I57="","",IF(AND(I57>0,I57<200),"Trivial",IF(OR(I57=200,AND(I57>200,I57<400)),"Tolerable",IF(OR(I57=400,AND(I57>400,I57<600)),"Moderado",IF(OR(I57=600,AND(I57>600,I57<800)),"Importante",IF(OR(I57=800,I57>800,I57<1000,I57=1000),"Intolerable","")))))),IF(A57="Oportunidad",IF(I57="","",IF(AND(I57>0,I57<250),"Limitada",IF(OR(I57=250,AND(I57>250,I57<500)),"Media",IF(OR(I57=500,AND(I57>500,I57<750)),"Potencial",IF(OR(I57=750,AND(I57>750,I57<=1000)),"Sobresaliente",""))))),"")) -> Limitada | K57: =IFERROR(VLOOKUP(J57,'Parámetros de riesgo'!$B$27:$C$31,2,FALSE),IFERROR(VLOOKUP(J57,'Parámetros de riesgo'!$H$27:$I$30,2,FALSE),"")) -> A CONSIDERAR | L57: =IFERROR(VLOOKUP(K57,'Parámetros de riesgo'!$C$27:$D$31,2,FALSE),IFERROR(VLOOKUP(K57,'Parámetros de riesgo'!$I$27:$J$30,2,FALSE),"")) -> Oportunidad que genera un beneficio mínimo en el proceso y/o Partes Interesadas de la cual se espera un resultado inmediato. Documentar las acciones de respuesta en la Evaluación de Efectividad de riesgos y oportunidades. | M57: Revisar y descartar los perfiles de los Aspirantes que no cumplan con el perfil requerido del cargo. | N57: VED y VDRFE
A62: Oportunidad | B62: Evaluación de los Aspirantes | C62: Instrumentar un modelo de evaluación, que considere todos los criterios a evaluar de acuerdo con lo establecido en la estrategia para obtener el mejor Aspirante | D62: Media | E62: * Que el contenido de la evaluación, sea de acuerdo con los requerimientos del cargo. | F62: * Seleccionar al Aspirante que cumpla con los requisitos establecidos para el cargo. | G62: Leve | H62: Operativo | I62: =IFERROR(VLOOKUP(H62,Naturaleza,2,FALSE)*VLOOKUP('Matriz Riesgo y Op'!D62,Probabilidad,2,FALSE)*VLOOKUP('Matriz Riesgo y Op'!G62,Impacto,2,FALSE),"") -> 70 | J62: =IF(A62="Riesgo",IF(I62="","",IF(AND(I62>0,I62<200),"Trivial",IF(OR(I62=200,AND(I62>200,I62<400)),"Tolerable",IF(OR(I62=400,AND(I62>400,I62<600)),"Moderado",IF(OR(I62=600,AND(I62>600,I62<800)),"Importante",IF(OR(I62=800,I62>800,I62<1000,I62=1000),"Intolerable","")))))),IF(A62="Oportunidad",IF(I62="","",IF(AND(I62>0,I62<250),"Limitada",IF(OR(I62=250,AND(I62>250,I62<500)),"Media",IF(OR(I62=500,AND(I62>500,I62<750)),"Potencial",IF(OR(I62=750,AND(I62>750,I62<=1000)),"Sobresaliente",""))))),"")) -> Limitada | K62: =IFERROR(VLOOKUP(J62,'Parámetros de riesgo'!$B$27:$C$31,2,FALSE),IFERROR(VLOOKUP(J62,'Parámetros de riesgo'!$H$27:$I$30,2,FALSE),"")) -> A CONSIDERAR | L62: =IFERROR(VLOOKUP(K62,'Parámetros de riesgo'!$C$27:$D$31,2,FALSE),IFERROR(VLOOKUP(K62,'Parámetros de riesgo'!$I$27:$J$30,2,FALSE),"")) -> Oportunidad que genera un beneficio mínimo en el proceso y/o Partes Interesadas de la cual se espera un resultado inmediato. Documentar las acciones de respuesta en la Evaluación de Efectividad de riesgos y oportunidades. | M62: Solicitar la herramienta que proporcione perfiles específicos, comportamientos, etc., a la Dirección de Operación y Seguimiento. | N62: VEL y VRFEL
A67: Oportunidad | B67: Resultados | C67: Asegurar se difundan ampliamente los resultados, ya sea en estrado o hablar directamente con los Aspirantes, para notificar quien pasa a la siguiente etapa | D67: Media | E67: * Que la difusión se lleve a cabo en los tiempos establecidos. | F67: * Asistencia de Aspirantes que pasan a siguiente etapa. * Con la publicación de resultados se da veracidad al proceso de selección. | G67: Importante | H67: Operativo | I67: =IFERROR(VLOOKUP(H67,Naturaleza,2,FALSE)*VLOOKUP('Matriz Riesgo y Op'!D67,Probabilidad,2,FALSE)*VLOOKUP('Matriz Riesgo y Op'!G67,Impacto,2,FALSE),"") -> 700 | J67: =IF(A67="Riesgo",IF(I67="","",IF(AND(I67>0,I67<200),"Trivial",IF(OR(I67=200,AND(I67>200,I67<400)),"Tolerable",IF(OR(I67=400,AND(I67>400,I67<600)),"Moderado",IF(OR(I67=600,AND(I67>600,I67<800)),"Importante",IF(OR(I67=800,I67>800,I67<1000,I67=1000),"Intolerable","")))))),IF(A67="Oportunidad",IF(I67="","",IF(AND(I67>0,I67<250),"Limitada",IF(OR(I67=250,AND(I67>250,I67<500)),"Media",IF(OR(I67=500,AND(I67>500,I67<750)),"Potencial",IF(OR(I67=750,AND(I67>750,I67<=1000)),"Sobresaliente",""))))),"")) -> Potencial | K67: =IFERROR(VLOOKUP(J67,'Parámetros de riesgo'!$B$27:$C$31,2,FALSE),IFERROR(VLOOKUP(J67,'Parámetros de riesgo'!$H$27:$I$30,2,FALSE),"")) -> APROPIARSE | L67: =IFERROR(VLOOKUP(K67,'Parámetros de riesgo'!$C$27:$D$31,2,FALSE),IFERROR(VLOOKUP(K67,'Parámetros de riesgo'!$I$27:$J$30,2,FALSE),"")) -> Oportunidad con beneficios claros y específicos en el proceso de una o varias áreas y/o Partes Interesadas, de la cual se espera un resultado a corto y mediano plazo. Documentar las acciones de respuesta en la Evaluación de Efectividad de riesgos y oportunidades. | M67: Asegurar que los resultados se hagan en estrado y en los medios utilizados para la convocatoria. | N67: VED y VDRFE
A72: Oportunidad | B72: Entrevista | C72: Asegurar que la entrevista sea aplicada simultáneamente por el VE y el VRFE | D72: Media | E72: * Mayor objetividad en la evaluación del Aspirante. | F72: * Que se seleccione al Aspirante idóneo. | G72: Moderado | H72: Operativo | I72: =IFERROR(VLOOKUP(H72,Naturaleza,2,FALSE)*VLOOKUP('Matriz Riesgo y Op'!D72,Probabilidad,2,FALSE)*VLOOKUP('Matriz Riesgo y Op'!G72,Impacto,2,FALSE),"") -> 490 | J72: =IF(A72="Riesgo",IF(I72="","",IF(AND(I72>0,I72<200),"Trivial",IF(OR(I72=200,AND(I72>200,I72<400)),"Tolerable",IF(OR(I72=400,AND(I72>400,I72<600)),"Moderado",IF(OR(I72=600,AND(I72>600,I72<800)),"Importante",IF(OR(I72=800,I72>800,I72<1000,I72=1000),"Intolerable","")))))),IF(A72="Oportunidad",IF(I72="","",IF(AND(I72>0,I72<250),"Limitada",IF(OR(I72=250,AND(I72>250,I72<500)),"Media",IF(OR(I72=500,AND(I72>500,I72<750)),"Potencial",IF(OR(I72=750,AND(I72>750,I72<=1000)),"Sobresaliente",""))))),"")) -> Media | K72: =IFERROR(VLOOKUP(J72,'Parámetros de riesgo'!$B$27:$C$31,2,FALSE),IFERROR(VLOOKUP(J72,'Parámetros de riesgo'!$H$27:$I$30,2,FALSE),"")) -> ABORDAR | L72: =IFERROR(VLOOKUP(K72,'Parámetros de riesgo'!$C$27:$D$31,2,FALSE),IFERROR(VLOOKUP(K72,'Parámetros de riesgo'!$I$27:$J$30,2,FALSE),"")) -> Oportunidad con buena posibilidad de abordarse siempre y cuando se profundice en los beneficios esperados en el proceso de una o varias áreas y/o Partes Interesadas de la cual se espera un resultado a corto plazo. Documentar las acciones de respuesta en la Evaluación de Efectividad de riesgos y oportunidades. | M72: Planear la entrevista para asegurar la participación de los involucrados. | N72: VED y VDRFE
A77: Oportunidad | B77: Designación de personal y lista de reserva | C77: Asegurar que la designación del Aspirante y lista de reserva sea confirmada | D77: Media | E77: * Contratación oportuna. | F77: * Contar con lista de reserva con personal que cumpla con el perfil. | G77: Importante | H77: Operativo | I77: =IFERROR(VLOOKUP(H77,Naturaleza,2,FALSE)*VLOOKUP('Matriz Riesgo y Op'!D77,Probabilidad,2,FALSE)*VLOOKUP('Matriz Riesgo y Op'!G77,Impacto,2,FALSE),"") -> 700 | J77: =IF(A77="Riesgo",IF(I77="","",IF(AND(I77>0,I77<200),"Trivial",IF(OR(I77=200,AND(I77>200,I77<400)),"Tolerable",IF(OR(I77=400,AND(I77>400,I77<600)),"Moderado",IF(OR(I77=600,AND(I77>600,I77<800)),"Importante",IF(OR(I77=800,I77>800,I77<1000,I77=1000),"Intolerable","")))))),IF(A77="Oportunidad",IF(I77="","",IF(AND(I77>0,I77<250),"Limitada",IF(OR(I77=250,AND(I77>250,I77<500)),"Media",IF(OR(I77=500,AND(I77>500,I77<750)),"Potencial",IF(OR(I77=750,AND(I77>750,I77<=1000)),"Sobresaliente",""))))),"")) -> Potencial | K77: =IFERROR(VLOOKUP(J77,'Parámetros de riesgo'!$B$27:$C$31,2,FALSE),IFERROR(VLOOKUP(J77,'Parámetros de riesgo'!$H$27:$I$30,2,FALSE),"")) -> APROPIARSE | L77: =IFERROR(VLOOKUP(K77,'Parámetros de riesgo'!$C$27:$D$31,2,FALSE),IFERROR(VLOOKUP(K77,'Parámetros de riesgo'!$I$27:$J$30,2,FALSE),"")) -> Oportunidad con beneficios claros y específicos en el proceso de una o varias áreas y/o Partes Interesadas, de la cual se espera un resultado a corto y mediano plazo. Documentar las acciones de respuesta en la Evaluación de Efectividad de riesgos y oportunidades. | M77: Notificar la designación al Aspirante. | N77: VDRFE

Sheet Parámetros de riesgo
D1: INSTITUTO NACIONAL ELECTORAL JLE PUEBLA SISTEMA DE GESTIÓN DE LA CALIDAD | K1: Versión: 0
D2: PARÁMETROS DE RIESGOS | K2: Fecha de emisión: 06/03/2020
A4: RIESGOS | G4: OPORTUNIDADES
A5: NATURALEZA | B5: DEFINICIONES | G5: NATURALEZA | H5: DEFINICIONES
A6: Operativa | B6: Riesgo cuyos efectos están relacionados con la nula o mala prestación del servicio y/o entrega de la credencial para votar durante la operación y a la entrega a la Ciudadanía. Puede incluir maquinaria, equipo, infraestructura, Recurso Humano, Insumos, servicios de apoyo (agua potable, electricidad, redes, internet, Sistema SIIRFE-MAC) y Partes Interesadas. | G6: Operativa | H6: Oportunidad cuyos efectos están relacionados con la prestación del servicio y/o entrega de la credencial para votar durante la operación y a la entrega a la Ciudadanía de forma eficiente. Puede incluir maquinaria, equipo, infraestructura, Recurso Humano, Insumos, servicios de apoyo (agua potable, electricidad, redes, internet, Sistema SIIRFE-MAC, etc.) y Partes Interesadas.
A7: Ambiental | B7: Cualquier riesgo cuyo efecto negativo está relacionado con la salud física, medio ambiente y seguridad laboral de cualquier Parte Interesada (interna o externa), así como el ambiente laboral de los funcionarios dentro de los MAC´s. | G7: Ambiental | H7: Oportunidad cuyo efecto está relacionado con mantener e incrementar los beneficios en la salud física, medio ambiente y seguridad laboral de cualquier Parte Interesada (interna y externa), así como el ambiente laboral de los Funcionarios dentro de los MAC´s.
A8: Legal y Reglamentario | B8: Riesgo cuyos efectos están relacionados con los cambios de las normatividades legales y reglamentarias aplicables al instituto en el ámbito federal, local y del ramo que no permitan acceder, mantener o mejorar las relaciones con las Partes Interesadas y esto afecte a la operación y a la entrega de la credencial para votar y/o trámite a la Ciudadanía. | G8: Legal y Reglamentario | H8: Oportunidad cuyos efectos están relacionados con el aprovechamiento de los cambios en las normatividades legales y reglamentarias aplicables en el Instituto en el ámbito federal, local y del ramo que permitan mantener y mejorar las relaciones con las Partes Interesadas durante la operación y a la entrega de la credencial para votar y/o trámite a la Ciudadanía.
A9: Política | B9: Riesgo cuyos efectos están relacionados con la probabilidad de que las fuerzas políticas generen cambios negativos en el entorno Institucional y obstaculicen o minimicen relaciones con Partes Interesadas. | G9: Política | H9: Oportunidad cuyos efectos están relacionados con la probabilidad de que las fuerzas políticas generen cambios positivos en el entorno Institucional y apoyen a mejorar las relaciones con las Partes Interesadas.
A10: Industrial | B10: Riesgo cuyos efectos están relacionados con Partes Interesadas que generan una desventaja frente a la competencia en el mismo ramo, zona geográfica, Ciudad, Estado y/o País en la prestación del producto / servicio brindado a la Ciudadanía. | G10: Industrial | H10: Oportunidad cuyos efectos están relacionados con Partes Interesadas que generan una ventaja competitiva en el mismo ramo, zona geográfica, Ciudad, Estado y/o País en la prestación del producto / servicio brindado a la Ciudadanía.
A11: Institucional | B11: Riesgo cuyos efectos están relacionados con cambios en la planeación y ejecución estratégica del INE, DOS, DERFE, que provocan limitantes tangibles e intangibles en los resultados de los MAC´s. | G11: Institucional | H11: Oportunidad cuyos efectos están relacionados con cambios en la planeación y ejecución estratégica del INE, DERFE, DOS, que provocan beneficios tangibles e intangibles en los resultados de los MAC´s.
A12: Social/Cultural | B12: Riesgo en los integrantes del mercado y su influencia en el entorno. Variables como la evolución demográfica, Movilidad social, Cambios en el estilo de vida, Actitud consumista, Nivel educativo, Patrones culturales y la Religión. | G12: Social/Cultural | H12: Oportunidad que los integrantes del mercado y su influencia en el entorno sean de beneficio con la evolución demográfica, Movilidad social, Cambios en el estilo de vida, Actitud consumista, Nivel educativo, Patrones culturales y la Religión.
A13: Tecnológicos | B13: Riesgo del desarrollo tecnológico y sus aportes en la actividad Institucional. Depende de su estado la cifra en gasto público en investigación, Preocupación gubernamental y de industria por la tecnología, Grado de obsolescencia, Madurez de las tecnologías convencionales, Desarrollo de nuevos productos, Velocidad de transmisión de la tecnología. | G13: Tecnológicos | H13: Oportunidad en el desarrollo tecnológico y sus aportes en la actividad de los MAC´s, Madurez de las tecnologías convencionales, Desarrollo de nuevos productos, Velocidad de transmisión de la tecnología.
A14: Económico / Financiero | B14: Riesgo cuyos efectos están relacionados con limitar o detener la sostenibilidad financiera de los MAC´s, las cuales pueden ser generadas en conjunto por una o unas de las Partes Interesadas. | G14: Económico / Financiero | H14: Oportunidad cuyos efectos están relacionados con mantener e incrementar la sostenibilidad financiera del Instituto, las cuales pueden ser generadas en conjunto por una o varias de las Partes Interesadas.
A16: PROBABILIDAD | B16: DEFINICIONES | G16: PROBABILIDAD | H16: DEFINICIONES
A17: Baja | B17: Remotamente posible. El daño ocurre muy rara vez. | G17: Baja | H17: Remotamente posible. La oportunidad ocurre muy rara vez.
... A24: Grave | B24: Riesgo negativo que afecta gravemente la integridad para otorgar la prestación del servicio determinado por el proceso. Pocas veces puede revertirse en un mediano o largo tiempo y genera costos de no calidad altos y con daños visiblemente permanentes. | G24: Importante | H24: Impacto positivo garantizado que potencializa la integridad para otorgar la prestación del servicio determinado por el proceso. Puede implementarse en un mediano o largo tiempo y genera costos de calidad considerables y posiblemente permanentes.
A26: RANGOS | B26: CLASIFICACIÓN | C26: DICTAMEN | D26: ACCIONES | G26: RANGOS | H26: CLASIFICACIÓN | I26: DICTAMEN | J26: ACCIONES
A27: 0 - 199 | B27: TRIVIAL | C27: VIGILARLO | D27: Control rutinario, no afecta la secuencia e integridad del proceso y/o Partes Interesadas. Documentar las acciones de respuesta en la Evaluación de Efectividad de riesgos y oportunidades. | G27: 0 - 250 | H27: LIMITADA | I27: A CONSIDERAR | J27: Oportunidad que genera un beneficio mínimo en el proceso y/o Partes Interesadas de la cual se espera un resultado inmediato. Documentar las acciones de respuesta en la Evaluación de Efectividad de riesgos y oportunidades.
A28: 200 - 399 | B28: TOLERABLE | C28: ASUMIRLO | D28: Monitorear el riesgo, afecta mínimamente la secuencia y la integridad del proceso. Documentar las acciones de respuesta en la Evaluación de Efectividad de riesgos y oportunidades. | G28: 251 - 500 | H28: MEDIA | I28: ABORDAR | J28: Oportunidad con buena posibilidad de abordarse siempre y cuando se profundice en los beneficios esperados en el proceso de una o varias áreas y/o Partes Interesadas de la cual se espera un resultado a corto plazo. Documentar las acciones de respuesta en la Evaluación de Efectividad de riesgos y oportunidades.
A29: 400 - 599 | B29: MODERADO | C29: CONTROLARLO | D29: Documentar las acciones de respuesta en la Evaluación de Efectividad de riesgos y oportunidades e incluir controles permanentes ya que existe un riesgo moderado en la secuencia y la integridad del proceso y/o Partes Interesadas. | G29: 501 - 750 | H29: POTENCIAL | I29: APROPIARSE | J29: Oportunidad con beneficios claros y específicos en el proceso de una o varias áreas y/o Partes Interesadas, de la cual se espera un resultado a corto y mediano plazo. Documentar las acciones de respuesta en la Evaluación de Efectividad de riesgos y oportunidades.
A30: 600 - 799 | B30: IMPORTANTE | C30: MINIMIZARLO | D30: Acción de contención inmediata, es importante generar una Cédula de no Conformidad eficaz y eficiente donde se realice un control específico y permanente ya que el riesgo es alto en la secuencia y la integridad del proceso y/o Partes interesadas. | G30: 751 - 1000 | H30: SOBRESALIENTE | I30: EXPLOTARLA | J30: Oportunidad con beneficios claros, generales y específicos en el proceso de varias o todas las áreas y/o Partes Interesadas de la cual se obtiene un resultado a corto, mediano y/o largo plazo. Documentar las acciones de respuesta en la Evaluación de Efectividad de riesgos y oportunidades.
A31: 800 - 1000 | B31: INTOLERABLE | C31: ATENCIÓN INMEDIATA | D31: Acción de contención inmediata, es urgente generar una Cédula de no Conformidad y revisión del proceso (aplicar reingeniería si es necesario) eficaz y eficiente donde se realice un control específico y permanente ya que el riesgo es grave en la secuencia y la integridad del proceso y/o Partes interesadas.

Sheet Ponderación
A1: Entorno | D1: Probabilidad | G1: Impacto
A2: Político | B2: 5 | D2: Baja | E2: 1 | G2: Leve | H2: 1
A3: Industrial | B3: 5 | D3: Media | E3: 7 | G3: Moderado | H3: 7
A4: Operativo | B4: 10 | D4: Alta | E4: 10 | G4: Grave | H4: 10
A5: Institucional | B5: 8 | G5: Importante | H5: 10
A6: Financiera | B6: 7
A7: Ambiental | B7: 8
A8: Legal y Reglamentario | B8: 9
A9: Salud | B9: 10
A10: Social/Cultural | B10: 6
A11: Tecnológicos | B11: 6

Sheet E de efectividad Ri
C1: INSTITUTO NACIONAL ELECTORAL JLE PUEBLA SISTEMA DE GESTIÓN DE LA CALIDAD | G1: Versión: 0
C2: EVALUACIÓN DE LA EFECTIVIDAD DE LOS RIESGOS | G2: Fecha de emisión: 06/03/2020
A4: Fecha: | C4: Proceso: | F4: Responsable:
A5: Referencia documental:
A7: Acciones de Respuesta | B7: Riesgo | C7: Criterio de evaluación | G7: Evidencia de soporte | H7: Observaciones
C8: 1 | D8: 2 | E8: 3 | F8: 4
A9: ='Matriz Riesgo y Op'!M8 -> Oficios y correos electrónicos de la renuncia. | B9: ='Matriz Riesgo y Op'!C8 -> Módulo operando con la plantilla incompleta
A10: ='Matriz Riesgo y Op'!M9 -> Oficios y correos electrónicos de la rescisión del contrato, en su caso, las constancias que justifiquen dicha acción.
A11: ='Matriz Riesgo y Op'!M10 -> 0
A12: ='Matriz Riesgo y Op'!M11 -> 0
A13: ='Matriz Riesgo y Op'!M12 -> 0
A14: ='Matriz Riesgo y Op'!M13 -> Realizar la difusión en los medios existentes. | B14: ='Matriz Riesgo y Op'!C13 -> Aspirantes a cubrir la plaza nulos o limitados
A15: ='Matriz Riesgo y Op'!M14 -> Asegurar evidencias por medio de Oficios y correos electrónicos sobre la publicación de la convocatoria.
A16: ='Matriz Riesgo y Op'!M15 -> Constancias de evidencias de los medios mediante los cuales se difunda la invitación o convocatoria.
A17: ='Matriz Riesgo y Op'!M16 -> 0
A18: ='Matriz Riesgo y Op'!M17 -> 0
A19: ='Matriz Riesgo y Op'!M18 -> Solicitudes y Cédulas del Cargo debidamente requisitadas (que el perfil, funciones y responsabilidades correspondan al cargo vacante). | B19: ='Matriz Riesgo y Op'!C18 -> Selección de personal con el perfil no adecuado
A20: ='Matriz Riesgo y Op'!M19 -> 0
A21: ='Matriz Riesgo y Op'!M20 -> 0
A22: ='Matriz Riesgo y Op'!M21 -> 0
A23: ='Matriz Riesgo y Op'!M22 -> 0
A24: ='Matriz Riesgo y Op'!M23 -> Oficios y correos electrónicos sobre la aplicación de los exámenes y test al VRFEL y área administrativa. | B24: ='Matriz Riesgo y Op'!C23 -> Seleccionar a Aspirantes para continuar en el proceso, que no cubran el perfil requerido para el cargo
A25: ='Matriz Riesgo y Op'!M24 -> 0
A26: ='Matriz Riesgo y Op'!M25 -> 0
A27: ='Matriz Riesgo y Op'!M26 -> 0
A28: ='Matriz Riesgo y Op'!M27 -> 0
A29: ='Matriz Riesgo y Op'!M28 -> Oficios y correos electrónicos de estatus al VED. | B29: ='Matriz Riesgo y Op'!C28 -> No se cuenta con la certeza del conocimiento del personal evaluado
A30: ='Matriz Riesgo y Op'!M29 -> 0
A31: ='Matriz Riesgo y Op'!M30 -> 0
A32: ='Matriz Riesgo y Op'!M31 -> 0
A33: ='Matriz Riesgo y Op'!M32 -> 0
A34: ='Matriz Riesgo y Op'!M33 -> Generar cédula de no conformidad. | B34: ='Matriz Riesgo y Op'!C33 -> Seleccionar personal sin que se identifiquen sus cualidades o debilidades.
A35: ='Matriz Riesgo y Op'!M34 -> 0
A36: ='Matriz Riesgo y Op'!M35 -> 0
A37: ='Matriz Riesgo y Op'!M36 -> 0
A38: ='Matriz Riesgo y Op'!M37 -> 0
A39: ='Matriz Riesgo y Op'!M38 -> Oficios y correos electrónicos sobre Aspirantes, designados al área administrativa. | B39: ='Matriz Riesgo y Op'!C38 -> Que el cargo aparezca vacante, cuando ya está designado
A40: ='Matriz Riesgo y Op'!M39 -> Envío de la Lista de reserva al VED, para su publicación.
A41: ='Matriz Riesgo y Op'!M40 -> 0
A42: ='Matriz Riesgo y Op'!M41 -> 0
...

Sheet E de efectividad Op
C1: INSTITUTO NACIONAL ELECTORAL JLE PUEBLA SISTEMA DE GESTIÓN DE LA CALIDAD | G1: Versión: 0
C2: EVALUACIÓN DE LA EFECTIVIDAD DE LOS OPORTUNIDADES | G2: Fecha de emisión: 06/03/2020
A4: Fecha: | C4: Proceso: | F4: Responsable:
A5: Referencia documental:
A7: Acciones de Respuesta | B7: Oportunidad | C7: Criterio de evaluación | G7: Evidencia de soporte | H7: Observaciones
C8: 1 | D8: 2 | E8: 3 | F8: 4
A9: ='Matriz Riesgo y Op'!M47 -> Mantener comunicación continúa con el Responsable de Módulo. | B9: ='Matriz Riesgo y Op'!C47 -> Tener un seguimiento de la situación de los Funcionarios del Módulo que implique una vacante, para anticiparse a iniciar el proceso
A10: ='Matriz Riesgo y Op'!M48
A11: ='Matriz Riesgo y Op'!M49 -> 0
A12: ='Matriz Riesgo y Op'!M50 -> 0
A13: ='Matriz Riesgo y Op'!M51 -> 0
A14: ='Matriz Riesgo y Op'!M52 -> Asegurar que la Convocatoria se emita con los requisitos claramente detallados, etapas del proceso, etc., así como que se difunda a través de los canales disponibles. | B14: ='Matriz Riesgo y Op'!C52 -> Asegurar la publicación de la convocatoria a través del mayor número de medios disponibles: la página oficial del INE, carteles, redes sociales, boletines de radio, etc.
A15: ='Matriz Riesgo y Op'!M53 -> Seguimiento a la Convocatoria en las plataformas en que se haya difundido la misma.
A16: ='Matriz Riesgo y Op'!M54 -> 0
A17: ='Matriz Riesgo y Op'!M55 -> 0
A18: ='Matriz Riesgo y Op'!M56 -> 0
A19: ='Matriz Riesgo y Op'!M57 -> Revisar y descartar los perfiles de los Aspirantes que no cumplan con el perfil requerido del cargo. | B19: ='Matriz Riesgo y Op'!C57 -> Hacer hincapié al Aspirante de los requisitos solicitados en la convocatoria
A20: ='Matriz Riesgo y Op'!M58 -> 0
A21: ='Matriz Riesgo y Op'!M59 -> 0
A22: ='Matriz Riesgo y Op'!M60 -> 0
A23: ='Matriz Riesgo y Op'!M61 -> 0
A24: ='Matriz Riesgo y Op'!M62 -> Solicitar la herramienta que proporcione perfiles específicos, comportamientos, etc., a la Dirección de Operación y Seguimiento. | B24: ='Matriz Riesgo y Op'!C62 -> Instrumentar un modelo de evaluación, que considere todos los criterios a evaluar de acuerdo con lo establecido en la estrategia para obtener el mejor Aspirante
A25: ='Matriz Riesgo y Op'!M63 -> 0
A26: ='Matriz Riesgo y Op'!M64 -> 0
A27: ='Matriz Riesgo y Op'!M65 -> 0
A28: ='Matriz Riesgo y Op'!M66 -> 0
A29: ='Matriz Riesgo y Op'!M67 -> Asegurar que los resultados se hagan en estrado y en los medios utilizados para la convocatoria. | B29: ='Matriz Riesgo y Op'!C67 -> Asegurar se difundan ampliamente los resultados, ya sea en estrado o hablar directamente con los Aspirantes, para notificar quien pasa a la siguiente etapa
A30: ='Matriz Riesgo y Op'!M68 -> 0
A31: ='Matriz Riesgo y Op'!M69 -> 0
A32: ='Matriz Riesgo y Op'!M70 -> 0
A33: ='Matriz Riesgo y Op'!M71 -> 0
A34: ='Matriz Riesgo y Op'!M72 -> Planear la entrevista para asegurar la participación de los involucrados. | B34: ='Matriz Riesgo y Op'!C72 -> Asegurar que la entrevista sea aplicada simultáneamente por el VE y el VRFE
A35: ='Matriz Riesgo y Op'!M73 -> 0
A36: ='Matriz Riesgo y Op'!M74 -> 0
A37: ='Matriz Riesgo y Op'!M75 -> 0
A38: ='Matriz Riesgo y Op'!M76 -> 0
A39: ='Matriz Riesgo y Op'!M77 -> Notificar la designación al Aspirante. | B39: ='Matriz Riesgo y Op'!C77 -> Asegurar que la designación del Aspirante y lista de reserva sea confirmada
A40: ='Matriz Riesgo y Op'!M78 -> 0
A41: ='Matriz Riesgo y Op'!M79 -> 0
A42: ='Matriz Riesgo y Op'!M80 -> 0
...
