Workbook

Sheet Proceso de Apoyo
A1: INSTITUTO NACIONAL ELECTORAL SISTEMA DE GESTIÓN DE LA CALIDAD PUEBLA
A3: TABLERO DE CONTROL DE PROCESOS DE APOYO DEL SISTEMA DE GESTIÓN DE LA CALIDAD
A5: Número | B5: PROCESOS DE APOYO E INDICADORES | H5: Resultados Mensuales | U5: % AVANCE REGISTRADO
B6: DESCRIPCIÓN | D6: MEDICIÓN | H6: CAMPAÑA ANUAL PERMENENTE 2019-2020 | Q6: CAI 2020
B7: Proceso | C7: Indicador | D7: Cálculo | E7: Periodo | F7: Estimado | G7: Nominativo | H7: Dic | I7: Ene | J7: Feb | K7: Mar | L7: Abr | M7: May | N7: Jun | O7: Jul | P7: Ago | Q7: Sep | R7: Oct | S7: Nov | T7: Dic
A8: 1 | B8: Reclutamiento y Selección | C8: Permanencia de personal | D8: ((Plantilla de personal autorizado de MAC-Vacantes generadas)/Plantilla de personal autorizado de MAC) * 100 | E8: Plantilla de personal autorizado MAC | U8: =(((H8+I8+J8+K8+L8+M8+N8+O8+P8+Q8+R8+S8+T8)-(H9+I9+J9+K9+L9+M9+N9+O9+P9+Q9+R9+S9+T9))/(H8+I8+J8+K8+L8+M8+N8+O8+P8+Q8+R8+S8+T8))*100 -> #DIV/0!
E9: Total de vacantes generadas | H9: =SUM(H10:H24) -> 0 | I9: =SUM(I10:I24) -> 0 | J9: =SUM(J10:J24) -> 0 | K9: =SUM(K10:K24) -> 0 | L9: =SUM(L10:L24) -> 0 | M9: =SUM(M10:M24) -> 0 | N9: =SUM(N10:N24) -> 0 | O9: =SUM(O10:O24) -> 0 | ... T9: =SUM(T10:T24) -> 0
E10: Por campaña | F10: 0.9 | G10: Distrito 01 | H10: 0 | I10: 0 | J10: 0 | K10: 0 | L10: 0 | M10: 0 | N10: 0 | O10: 0 | P10: 0 | Q10: 0 | R10: 0 | S10: 0 | T10: 0
G11: Distrito 02 | H11: 0 | I11: 0 | J11: 0 | K11: 0 | L11: 0 | M11: 0 | N11: 0 | O11: 0 | P11: 0 | Q11: 0 | R11: 0 | S11: 0 | T11: 0
G12: Distrito 03 | H12: 0 | I12: 0 | J12: 0 | K12: 0 | L12: 0 | M12: 0 | N12: 0 | O12: 0 | P12: 0 | Q12: 0 | R12: 0 | S12: 0 | T12: 0
G13: Distrito 04 | H13: 0 | I13: 0 | J13: 0 | K13: 0 | L13: 0 | M13: 0 | N13: 0 | O13: 0 | P13: 0 | Q13: 0 | R13: 0 | S13: 0 | T13: 0
G14: Distrito 05 | H14: 0 | I14: 0 | J14: 0 | K14: 0 | L14: 0 | M14: 0 | N14: 0 | O14: 0 | P14: 0 | Q14: 0 | R14: 0 | S14: 0 | T14: 0
G15: Distrito 06 | H15: 0 | I15: 0 | J15: 0 | K15: 0 | L15: 0 | M15: 0 | N15: 0 | O15: 0 | P15: 0 | Q15: 0 | R15: 0 | S15: 0 | T15: 0
G16: Distrito 07 | H16: 0 | I16: 0 | J16: 0 | K16: 0 | L16: 0 | M16: 0 | N16: 0 | O16: 0 | P16: 0 | Q16: 0 | R16: 0 | S16: 0 | T16: 0
G17: Distrito 08 | H17: 0 | I17: 0 | J17: 0 | K17: 0 | L17: 0 | M17: 0 | N17: 0 | O17: 0 | P17: 0 | Q17: 0 | R17: 0 | S17: 0 | T17: 0
G18: Distrito 09 | H18: 0 | I18: 0 | J18: 0 | K18: 0 | L18: 0 | M18: 0 | N18: 0 | O18: 0 | P18: 0 | Q18: 0 | R18: 0 | S18: 0 | T18: 0
G19: Distrito 10 | H19: 0 | I19: 0 | J19: 0 | K19: 0 | L19: 0 | M19: 0 | N19: 0 | O19: 0 | P19: 0 | Q19: 0 | R19: 0 | S19: 0 | T19: 0
G20: Distrito 11 | H20: 0 | I20: 0 | J20: 0 | K20: 0 | L20: 0 | M20: 0 | N20: 0 | O20: 0 | P20: 0 | Q20: 0 | R20: 0 | S20: 0 | T20: 0
G21: Distrito 12 | H21: 0 | I21: 0 | J21: 0 | K21: 0 | L21: 0 | M21: 0 | N21: 0 | O21: 0 | P21: 0 | Q21: 0 | R21: 0 | S21: 0 | T21: 0
G22: Distrito 13 | H22: 0 | I22: 0 | J22: 0 | K22: 0 | L22: 0 | M22: 0 | N22: 0 | O22: 0 | P22: 0 | Q22: 0 | R22: 0 | S22: 0 | T22: 0
... G24: Distrito 15 | H24: 0 | I24: 0 | J24: 0 | K24: 0 | L24: 0 | M24: 0 | N24: 0 | O24: 0 | P24: 0 | Q24: 0 | R24: 0 | S24: 0 | T24: 0
A26: 2 | B26: Capacitación | C26: Capacitación efectiva | D26: (Participantes efectivos en el curso/Participantes inscritos al curso) * 100 | E26: Participantes inscritos al curso | U26: =((H27+I27+J27+K27+L27+M27+N27+O27+P27+Q27+R27+S27+T27)/(H26+I26+J26+K26+L26+M26+N26+O26+P26+Q26+R26+S26+T26))*100 -> #DIV/0!
E27: Por campaña | F27: 0.98 | G27: Participantes efectivos en el curso | H27: 0 | I27: 0 | J27: 0 | K27: 0 | L27: 0 | M27: 0 | N27: 0 | O27: 0 | P27: 0 | Q27: 0 | R27: 0 | S27: 0 | T27: 0
C28: Aprovechamiento | D28: (Sumatoria de calificaciones obtenidas/Participantes efectivos en el curso | E28: Participantes efectivos en el curso | U28: =((H29+I29+J29+K29+L29+M29+N29+O29+P29+Q29+R29+S29+T29)/(H28+I28+J28+K28+L28+M28+N28+O28+P28+Q28+R28+S28+T28)) -> #DIV/0!
E29: Por campaña | F29: 80 pts | G29: Sumatoria de calificaciones obtenida | H29: 0 | I29: 0 | J29: 0 | K29: 0 | L29: 0 | M29: 0 | N29: 0 | O29: 0 | P29: 0 | Q29: 0 | R29: 0 | S29: 0 | T29: 0
A31: 3 | B31: Desempeño del Personal | C31: Promedio de evaluación de desempeño | D31: (Promedio de la evaluación de la plantilla/Número de distritos) * 10 | E31: Total de plantilla evaluada | P31: 15 | T31: 15 | U31: =(P32/P31)*10 -> 0
E32: Sumatoria de evaluaciones de la plantilla | H32: 0 | I32: 0 | J32: 0 | K32: 0 | L32: 0 | M32: 0 | N32: 0 | O32: 0 | P32: =SUM(P33:P47) -> 0 | Q32: 0 | R32: 0 | S32: 0 | T32: =SUM(T33:T47) -> 0
E33: Por campaña | F33: 80 pts | G33: Distrito 01 | H33: 0 | I33: 0 | J33: 0 | K33: 0 | L33: 0 | M33: 0 | N33: 0 | O33: 0 | P33: ='RECLUTAMIENTO, CAPA Y EVAL'!K19 -> 0 | Q33: 0 | R33: 0 | S33: 0 | T33: ='RECLUTAMIENTO, CAPA Y EVAL'!O19 -> 0
G34: Distrito 02 | H34: 0 | I34: 0 | J34: 0 | K34: 0 | L34: 0 | M34: 0 | N34: 0 | O34: 0 | P34: ='RECLUTAMIENTO, CAPA Y EVAL'!K20 -> 0 | Q34: 0 | R34: 0 | S34: 0 | T34: ='RECLUTAMIENTO, CAPA Y EVAL'!O20 -> 0
G35: Distrito 03 | H35: 0 | I35: 0 | J35: 0 | K35: 0 | L35: 0 | M35: 0 | N35: 0 | O35: 0 | P35: ='RECLUTAMIENTO, CAPA Y EVAL'!K21 -> 0 | Q35: 0 | R35: 0 | S35: 0 | T35: ='RECLUTAMIENTO, CAPA Y EVAL'!O21 -> 0
G36: Distrito 04 | H36: 0 | I36: 0 | J36: 0 | K36: 0 | L36: 0 | M36: 0 | N36: 0 | O36: 0 | P36: ='RECLUTAMIENTO, CAPA Y EVAL'!K22 -> 0 | Q36: 0 | R36: 0 | S36: 0 | T36: ='RECLUTAMIENTO, CAPA Y EVAL'!O22 -> 0
G37: Distrito 05 | H37: 0 | I37: 0 | J37: 0 | K37: 0 | L37: 0 | M37: 0 | N37: 0 | O37: 0 | P37: ='RECLUTAMIENTO, CAPA Y EVAL'!K23 -> 0 | Q37: 0 | R37: 0 | S37: 0 | T37: ='RECLUTAMIENTO, CAPA Y EVAL'!O23 -> 0
G38: Distrito 06 | H38: 0 | I38: 0 | J38: 0 | K38: 0 | L38: 0 | M38: 0 | N38: 0 | O38: 0 | P38: ='RECLUTAMIENTO, CAPA Y EVAL'!K24 -> 0 | Q38: 0 | R38: 0 | S38: 0 | T38: ='RECLUTAMIENTO, CAPA Y EVAL'!O24 -> 0
G39: Distrito 07 | H39: 0 | I39: 0 | J39: 0 | K39: 0 | L39: 0 | M39: 0 | N39: 0 | O39: 0 | P39: ='RECLUTAMIENTO, CAPA Y EVAL'!K25 -> 0 | Q39: 0 | R39: 0 | S39: 0 | T39: ='RECLUTAMIENTO, CAPA Y EVAL'!O25 -> 0
G40: Distrito 08 | H40: 0 | I40: 0 | J40: 0 | K40: 0 | L40: 0 | M40: 0 | N40: 0 | O40: 0 | P40: ='RECLUTAMIENTO, CAPA Y EVAL'!K26 -> 0 | Q40: 0 | R40: 0 | S40: 0 | T40: ='RECLUTAMIENTO, CAPA Y EVAL'!O26 -> 0
G41: Distrito 09 | H41: 0 | I41: 0 | J41: 0 | K41: 0 | L41: 0 | M41: 0 | N41: 0 | O41: 0 | P41: ='RECLUTAMIENTO, CAPA Y EVAL'!K27 -> 0 | Q41: 0 | R41: 0 | S41: 0 | T41: ='RECLUTAMIENTO, CAPA Y EVAL'!O27 -> 0
G42: Distrito 10 | H42: 0 | I42: 0 | J42: 0 | K42: 0 | L42: 0 | M42: 0 | N42: 0 | O42: 0 | P42: ='RECLUTAMIENTO, CAPA Y EVAL'!K28 -> 0 | Q42: 0 | R42: 0 | S42: 0 | T42: ='RECLUTAMIENTO, CAPA Y EVAL'!O28 -> 0
G43: Distrito 11 | H43: 0 | I43: 0 | J43: 0 | K43: 0 | L43: 0 | M43: 0 | N43: 0 | O43: 0 | P43: ='RECLUTAMIENTO, CAPA Y EVAL'!K29 -> 0 | Q43: 0 | R43: 0 | S43: 0 | T43: ='RECLUTAMIENTO, CAPA Y EVAL'!O29 -> 0
G44: Distrito 12 | H44: 0 | I44: 0 | J44: 0 | K44: 0 | L44: 0 | M44: 0 | N44: 0 | O44: 0 | P44: ='RECLUTAMIENTO, CAPA Y EVAL'!K30 -> 0 | Q44: 0 | R44: 0 | S44: 0 | T44: ='RECLUTAMIENTO, CAPA Y EVAL'!O30 -> 0
G45: Distrito 13 | H45: 0 | I45: 0 | J45: 0 | K45: 0 | L45: 0 | M45: 0 | N45: 0 | O45: 0 | P45: ='RECLUTAMIENTO, CAPA Y EVAL'!K31 -> 0 | Q45: 0 | R45: 0 | S45: 0 | T45: ='RECLUTAMIENTO, CAPA Y EVAL'!O31 -> 0
...

Sheet RECLUTAMIENTO, CAPA Y EVAL
A2: PLANTILLA DE PERSONAL DE LA CAMPAÑA ANUAL
A3: No. | B3: Puesto | C3: Nombre | D3: Vacante | E3: Nombre de la sustitucion | F3: Capacitación | I3: Evaluación
F4: CAP | G4: CAI | H4: CAP | I4: CAP | J4: CAI | K4: Promedio anual
A19: Total | I19: =SUM(I5:I18)/D19 -> #DIV/0!
A31: Total | I31: =SUM(I20:I30)/11 -> 0
A61: Total | I61: =SUM(I32:I60)/D61 -> #DIV/0!
A65: Total | I65: =SUM(I36:I64)/D65 -> #DIV/0!

Sheet capacitacion 
A1: Registro Federal de Electores
A4: Curso presencial de reforzamiento Tema: Identificación de registros en la base de datos del Padrón Electoral Agosto 2019
A5: REGISTRO DE CALIFICACIONES
A6: Entidad | D6: Distrito | F6: Fecha
A8: Nombre del Instructor | E8: Cargo / Puesto | G8: JLEVRFE
A10: ID | B10: NOMBRE | D10: CORREO INSTITUCIONAL | F10: PUESTO | G10: CALIFICACIÓN
A11: 1
A12: 2
A13: 3
A14: 4
A15: 5
A16: 6
A17: 7
A18: 8
A19: 9
A20: 10
A21: 11
A22: 12
... A109: 99
