Workbook

Sheet PANEL DE CONTROL DISTRITAL
A1: INSTITUTO NACIONAL ELECTORAL SISTEMA DE GESTIÓN DE LA CALIDAD PUEBLA
D2: Tablero de Control Estatal | M2: Fecha de corte 07 / 12 / 2020 | Q2: Version 0
A4: TABLERO DE CONTROL DISTRITAL DE PROCESOS SUSTANTIVOS DEL SISTEMA DE GESTIÓN DE LA CALIDAD
I5: CAMPAÑA ANUAL INTENSA 2020-2021
A6: Número | B6: PROCESOS SUSTANTIVOS E INDICADORES | I6: % AVANCE REGISTRADO | K6: % AVANCE REGISTRADO | M6: % AVANCE REGISTRADO | O6: % AVANCE REGISTRADO | Q6: % AVANCE REGISTRADO | S6: % AVANCE REGISTRADO | U6: % AVANCE REGISTRADO | W6: % AVANCE REGISTRADO | Y6: % AVANCE REGISTRADO | AA6: % AVANCE REGISTRADO | AC6: % AVANCE REGISTRADO | AE6: % AVANCE REGISTRADO | AG6: % AVANCE REGISTRADO | AI6: % AVANCE REGISTRADO | AK6: % AVANCE REGISTRADO | AM6: % AVANCE REGISTRADO
B7: DESCRIPCIÓN | E7: MEDICIÓN
B8: Proceso | C8: Dueño de Proceso | D8: Indicador | E8: Cálculo | F8: Periodo | G8: Estimado | H8: Nominativo | I8: Distrito 01 | K8: Distrito 02 | M8: Distrito 03 | O8: Distrito 04 | Q8: Distrito 05 | S8: Distrito 06 | U8: Distrito 07 | W8: Distrito 08 | Y8: Distrito 09 | AA8: Distrito 10 | AC8: Distrito 11 | AE8: Distrito 12 | AG8: Distrito 13 | AI8: Distrito 14 | AK8: Distrito 15 | AM8: Estatal
A9: 1 | B9: ENTREVISTA | C9: Auxiliar de Atención Ciudadana | D9: Efectividad de la entrevista = | E9: (Número de fichas requisitadas- tramites no identificados por huella / Número de trámites aplicados) x 100 | F9: Semanal (remesa) | G9: 0.9 | H9: Número de trámites aplicados | I9: =AVERAGE('210151'!H34:H35,'210152'!H34:H35,'210153'!H34:H35,'210154'!H34:H35,'210155'!H34:H35) -> 0.79863269 | K9: =AVERAGE('210251'!H34:H35,'210252 '!H34:H35,'210253'!H34:H35,'210254'!H34:H35,'210255'!H34:H35) -> 0.19050523 | M9: =AVERAGE('210351'!H34:H35,'210352'!H34:H35,'210353'!H34:H35,'210354'!H34:H35) -> 0.50721961 | O9: =AVERAGE('210451'!H34:H35,'210452'!H34:H35,'210453'!H34:H35,'210454'!H34:H35) -> 1 | Q9: =AVERAGE('210551'!H34:H35,'210552'!H34:H35,'210553'!H34:H35) -> 1.0001393 | S9: =AVERAGE('210651'!H34:H35) -> 1.0422422 | U9: =AVERAGE('210751'!H34:H35,'210752'!H34:H35,'210753'!H34:H35) -> 0.66666667 | W9: =AVERAGE('210851'!H34:H35,'210852'!H34:H35,'210853'!H34:H35,'210854'!H34:H35,'210855'!H34:H35) -> 1 | Y9: =AVERAGE('210951'!H34:H35,'210952'!H34:H35) -> 1 | AA9: =AVERAGE('211051'!H34:H35,'211052'!H34:H35) -> 0.5 | AC9: =AVERAGE('211151'!H34:H35) -> 1.0379415 | AE9: =AVERAGE('211251'!H34:H35,'211252'!H34:H35) -> 1 | AG9: =AVERAGE('211351'!H34:H35,'211352'!H34:H35,'211353'!H34:H35) -> 1.0476162 | AI9: =AVERAGE('211451'!H34:H35,'211452'!H34:H35,'211453'!H34:H35,'211454'!H34:H35,'211455'!H34:H35,'211456'!H34:H35) -> 1 | AK9: =AVERAGE('211551'!H34:H35,'211552'!H34:H35) -> 0.99982123 | AM9: =(I9+K9+M9+O9+Q9+S9+U9+W9+Y9+AA9+AC9+AE9+AG9+AI9+AK9)/15 -> 0.85271898
H10: Número de fichas requisitadas- tramites no identificados por huella
A12: 2 | B12: TRÁMITE | C12: Operador de Equipo Tecnológico | D12: Trámites exitosos efectivos= | E12: (Número de trámites exitosos/ Número de trámites aplicados) x 100 | F12: Semanal (remesa) | G12: 0.9 | H12: Número de trámites aplicados | I12: =AVERAGE('210151'!H37:H38,'210152'!H37:H38,'210153'!H37:H38,'210154'!H37:H38,'210155'!H37:H38) -> 0.79408363 | K12: =AVERAGE('210251'!H37:H38,'210252 '!H37:H38,'210253'!H37:H38,'210254'!H37:H38,'210255'!H37:H38) -> 0.98061449 | M12: =AVERAGE('210351'!H37:H38,'210352'!H37:H38,'210353'!H37:H38,'210354'!H37:H38) -> 0.98523243 | O12: =AVERAGE('210451'!H37:H38,'210452'!H37:H38,'210453'!H37:H38,'210454'!H37:H38) -> 0.99519048 | Q12: =AVERAGE('210551'!H37:H38,'210552'!H37:H38,'210553'!H37:H38) -> 0.98975977 | S12: =AVERAGE('210651'!H37:H38) -> 0.99284202 | U12: =AVERAGE('210751'!H37:H38,'210752'!H37:H38,'210753'!H37:H38) -> 0.66157899 | W12: =AVERAGE('210851'!H37:H38,'210852'!H37:H38,'210853'!H37:H38,'210854'!H37:H38,'210855'!H37:H38) -> 0.80113886 | Y12: =AVERAGE('210951'!H37:H38,'210952'!H37:H38) -> 0.99414645 | AA12: =AVERAGE('211051'!H37:H38,'211052'!H37:H38) -> 0.49679003 | AC12: =AVERAGE('211151'!H37:H38) -> 0.9924117 | AE12: =AVERAGE('211251'!H37:H38,'211252'!H37:H38) -> 0.99307695 | AG12: =AVERAGE('211351'!H37:H38,'211352'!H37:H38,'211353'!H37:H38) -> 0.98659668 | AI12: =AVERAGE('211451'!H37:H38,'211452'!H37:H38,'211453'!H37:H38,'211454'!H37:H38,'211455'!H37:H38,'211456'!H37:H38) -> 0.98662713 | AK12: =AVERAGE('211551'!H37:H38,'211552'!H37:H38) -> 0.99207359 | AM12: =(I12+K12+M12+O12+Q12+S12+U12+W12+Y12+AA12+AC12+AE12+AG12+AI12+AK12)/15 -> 0.90947755
H13: Número de trámites exitosos
A15: 3 | B15: TRANSFERENCIA | C15: Responsable de Módulo | D15: Transacciones exitosas = | E15: (Número de Archivos de Transacción aceptados /Total de Archivos de Transacción procesados) x100 | F15: Semanal (remesa) | G15: 0.9 | H15: Total de Archivos de Transacción procesados | I15: =AVERAGE('210151'!H40:H41,'210152'!H40:H41,'210153'!H40:H41,'210154'!H40:H41,'210155'!H40:H41) -> 1 | K15: =AVERAGE('210251'!H40:H41,'210252 '!H40:H41,'210253'!H40:H41,'210254'!H40:H41,'210255'!H40:H41) -> 1 | M15: =AVERAGE('210351'!H40:H41,'210352'!H40:H41,'210353'!H40:H41,'210354'!H40:H41) -> 0.98951776 | O15: =AVERAGE('210451'!H40:H41,'210452'!H40:H41,'210453'!H40:H41,'210454'!H40:H41) -> 1 | Q15: =AVERAGE('210551'!H40:H41,'210552'!H40:H41,'210553'!H40:H41) -> 1 | S15: =AVERAGE('210651'!H40:H41) -> 1 | U15: =AVERAGE('210751'!H40:H41,'210752'!H40:H41,'210753'!H40:H41) -> 0.66666667 | W15: =AVERAGE('210851'!H40:H41,'210852'!H40:H41,'210853'!H40:H41,'210854'!H40:H41,'210855'!H40:H41) -> 1 | Y15: =AVERAGE('210951'!H40:H41,'210952'!H40:H41) -> 1 | AA15: =AVERAGE('211051'!H40:H41,'211052'!H40:H41) -> 1.0000664 | AC15: =AVERAGE('211151'!H40:H41) -> 1 | AE15: =AVERAGE('211251'!H40:H41,'211252'!H40:H41) -> 1 | AG15: =AVERAGE('211351'!H40:H41,'211352'!H40:H41,'211353'!H40:H41) -> 1 | AI15: =AVERAGE('211451'!H40:H41,'211452'!H40:H41,'211453'!H40:H41,'211454'!H40:H41,'211455'!H40:H41,'211456'!H40:H41) -> 1 | AK15: =AVERAGE('211551'!H40:H41,'211552'!H40:H41) -> 1 | AM15: =(I12+K12+M12+O12+Q12+S12+U12+W12+Y12+AA12+AC12+AE12+AG12+AI12+AK12)/15 -> 0.90947755
H16: Número de Archivos de Transacción aceptados
A18: 4 | B18: CONCILIACIÓN | C18: Responsable de Módulo | D18: Credenciales disponibles para entrega = | E18: ((Credenciales recibidas - credenciales inconsistentes )/ Credenciales Recibidas) x 100 | F18: Semanal (remesa) | G18: 0.9 | H18: Credenciales Recibidas | I18: =AVERAGE('210151'!H43:H44,'210152'!H43:H44,'210153'!H43:H44,'210154'!H43:H44,'210155'!H43:H44) -> 1 | K18: =AVERAGE('210251'!H43:H44,'210252 '!H43:H44,'210253'!H43:H44,'210254'!H43:H44,'210255'!H43:H44) -> 1 | M18: =AVERAGE('210351'!H43:H44,'210352'!H43:H44,'210353'!H43:H44,'210354'!H43:H44) -> 0.98951776 | O18: =AVERAGE('210451'!H43:H44,'210452'!H43:H44,'210453'!H43:H44,'210454'!H43:H44) -> 1 | Q18: =AVERAGE('210551'!H43:H44,'210552'!H43:H44,'210553'!H43:H44) -> 1 | S18: =AVERAGE('210651'!H43:H44) -> 1 | U18: =AVERAGE('210751'!H43:H44,'210752'!H43:H44,'210753'!H43:H44) -> 1 | W18: =AVERAGE('210851'!H43:H44,'210852'!H43:H44,'210853'!H43:H44,'210854'!H43:H44,'210855'!H43:H44) -> 1 | Y18: =AVERAGE('210951'!H43:H44,'210952'!H43:H44) -> 1 | AA18: =AVERAGE('211051'!H43:H44,'211052'!H43:H44) -> 0.50006641 | AC18: =AVERAGE('211151'!H43:H44) -> 1 | AE18: =AVERAGE('211251'!H43:H44,'211252'!H43:H44) -> 1 | AG18: =AVERAGE('211351'!H43:H44,'211352'!H43:H44,'211353'!H43:H44) -> 1 | AI18: =AVERAGE('211451'!H43:H44,'211452'!H43:H44,'211453'!H43:H44,'211454'!H43:H44,'211455'!H43:H44,'211456'!H43:H44) -> 1 | AK18: =AVERAGE('211551'!H43:H44,'211552'!H43:H44) -> 1 | AM18: =(I18+K18+M18+O18+Q18+S18+U18+W18+Y18+AA18+AC18+AE18+AG18+AI18+AK18)/15 -> 0.96597228
H19: Credenciales recibidas - credenciales inconsistentes
A21: 5 | B21: ENTREGA | C21: Operador de Equipo Tecnológico | D21: Efectividad de entrega de CPV en MAC = | E21: Total de credenciales entregadas – reimpresiones por error de captura en MAC)/Total de credenciales entregadas ) x 100 | F21: Semanal (remesa) | G21: 0.9 | H21: Total de credenciales entregadas | I21: =AVERAGE('210151'!H46:H47,'210152'!H46:H47,'210153'!H46:H47,'210154'!H46:H47,'210155'!H46:H47) -> 1 | K21: =AVERAGE('210251'!H46:H47,'210252 '!H46:H47,'210253'!H46:H47,'210254'!H46:H47,'210255'!H46:H47) -> 1 | M21: =AVERAGE('210351'!H46:H47,'210352'!H46:H47,'210353'!H46:H47,'210354'!H46:H47) -> 1 | O21: =AVERAGE('210451'!H46:H47,'210452'!H46:H47,'210453'!H46:H47,'210454'!H46:H47) -> 1 | Q21: =AVERAGE('210551'!H46:H47,'210552'!H46:H47,'210553'!H46:H47) -> 0.99978536 | S21: =AVERAGE('210651'!H46:H47) -> 1 | U21: =AVERAGE('210751'!H46:H47,'210752'!H46:H47,'210753'!H46:H47) -> 1 | W21: =AVERAGE('210851'!H46:H47,'210852'!H46:H47,'210853'!H46:H47,'210854'!H46:H47,'210855'!H46:H47) -> 0.99996061 | Y21: =AVERAGE('210951'!H46:H47,'210952'!H46:H47) -> 1 | AA21: =AVERAGE('211051'!H46:H47,'211052'!H46:H47) -> 0.99988604 | AC21: =AVERAGE('211151'!H46:H47) -> 1 | AE21: =AVERAGE('211251'!H46:H47,'211252'!H46:H47) -> 1 | AG21: =AVERAGE('211351'!H46:H47,'211352'!H46:H47,'211353'!H46:H47) -> 0.99991405 | AI21: =AVERAGE('211451'!H46:H47,'211452'!H46:H47,'211453'!H46:H47,'211454'!H46:H47,'211455'!H46:H47,'211456'!H46:H47) -> 1 | AK21: =AVERAGE('211551'!H46:H47,'211552'!H46:H47) -> 1 | AM21: =(I21+K21+M21+O21+Q21+S21+U21+W21+Y21+AA21+AC21+AE21+AG21+AI21+AK21)/15 -> 0.99996974
H22: Total de credenciales entregadas – reimpresiones por error de captura en MAC

Sheet 210151
A1: ='PANEL DE CONTROL DISTRITAL'!A1:Q1 -> INSTITUTO NACIONAL ELECTORAL SISTEMA DE GESTIÓN DE LA CALIDAD PUEBLA
D2: Distrito | E2: 1 | F2: Módulo | H2: 210151 | W2: ='PANEL DE CONTROL DISTRITAL'!M2 -> Fecha de corte 07 / 12 / 2020
A4: TABLERO DE CONTROL DE PROCESOS SUSTANTIVOS DEL SISTEMA DE GESTIÓN DE LA CALIDAD
A6: ='PANEL DE CONTROL DISTRITAL'!A6:A8 -> Número | B6: ='PANEL DE CONTROL DISTRITAL'!B6:H6 -> PROCESOS SUSTANTIVOS E INDICADORES | I6: SEMANA OPERATIVA | AG6: % AVANCE REGISTRADO
B7: ='PANEL DE CONTROL DISTRITAL'!B7:D7 -> DESCRIPCIÓN | E7: ='PANEL DE CONTROL DISTRITAL'!E7:H7 -> MEDICIÓN | I7: ='PANEL DE CONTROL DISTRITAL'!I5 -> CAMPAÑA ANUAL INTENSA 2020-2021
B9: ='PANEL DE CONTROL DISTRITAL'!B8 -> Proceso | C9: ='PANEL DE CONTROL DISTRITAL'!C8 -> Dueño de Proceso | D9: ='PANEL DE CONTROL DISTRITAL'!D8 -> Indicador | E9: ='PANEL DE CONTROL DISTRITAL'!E8 -> Cálculo | F9: ='PANEL DE CONTROL DISTRITAL'!F8 -> Periodo | G9: ='PANEL DE CONTROL DISTRITAL'!G8 -> Estimado | H9: ='PANEL DE CONTROL DISTRITAL'!H8 -> Nominativo | I9: 2020-36 | J9: 2020-37 | K9: 2020-38 | L9: 2020-39 | M9: 2020-40 | N9: 2020-41 | O9: 2020-42 | P9: 2020-43 | Q9: 2020-44 | R9: 2020-45 | S9: 2020-46 | T9: 2020-47 | U9: 2020-48 | V9: 2020-49 | W9: 2020-50 | X9: 2020-51 | Y9: 2020-52 | Z9: 2020-53 | AA9: 2021-01 | AB9: 2021-02 | AC9: 2021-03 | AD9: 2021-04 | AE9: 2021-05 | AF9: 2021-06
A10: ='PANEL DE CONTROL DISTRITAL'!A9 -> 1 | B10: ='PANEL DE CONTROL DISTRITAL'!B9 -> ENTREVISTA | C10: ='PANEL DE CONTROL DISTRITAL'!C9 -> Auxiliar de Atención Ciudadana | D10: ='PANEL DE CONTROL DISTRITAL'!D9 -> Efectividad de la entrevista = | E10: ='PANEL DE CONTROL DISTRITAL'!E9 -> (Número de fichas requisitadas- tramites no identificados por huella / Número de trámites aplicados) x 100 | F10: ='PANEL DE CONTROL DISTRITAL'!F9 -> Semanal (remesa) | G10: ='PANEL DE CONTROL DISTRITAL'!G9 -> 0.9 | H10: ='PANEL DE CONTROL DISTRITAL'!H10 -> Número de fichas requisitadas- tramites no identificados por huella | I10: 0 | J10: 251 | K10: 328 | L10: 274 | M10: 325 | N10: 359 | O10: 476 | P10: 459 | Q10: 440 | R10: 429 | S10: 322 | T10: 464 | U10: 415 | V10: 545 | W10: 515 | X10: 0 | Y10: 0 | Z10: 0 | AA10: 0 | AB10: 0 | AC10: 0 | AD10: 0 | AE10: 0 | AF10: 0 | AG10: =IFERROR(SUM(I10:AF10)/SUM(I11:AF11),0) -> 0.99203117
H11: ='PANEL DE CONTROL DISTRITAL'!H9 -> Número de trámites aplicados | I11: 0 | J11: 251 | K11: 328 | L11: 274 | M11: 325 | N11: 404 | O11: 476 | P11: 459 | Q11: 440 | R11: 429 | S11: 322 | T11: 464 | U11: 415 | V11: 545 | W11: 515 | X11: 0 | Y11: 0 | Z11: 0 | AA11: 0 | AB11: 0 | AC11: 0 | AD11: 0 | AE11: 0 | AF11: 0
A12: 0
A13: ='PANEL DE CONTROL DISTRITAL'!A12 -> 2 | B13: ='PANEL DE CONTROL DISTRITAL'!B12 -> TRÁMITE | C13: ='PANEL DE CONTROL DISTRITAL'!C12 -> Operador de Equipo Tecnológico | D13: ='PANEL DE CONTROL DISTRITAL'!D12 -> Trámites exitosos efectivos= | E13: ='PANEL DE CONTROL DISTRITAL'!E12 -> (Número de trámites exitosos/ Número de trámites aplicados) x 100 | F13: ='PANEL DE CONTROL DISTRITAL'!F12 -> Semanal (remesa) | G13: ='PANEL DE CONTROL DISTRITAL'!G12 -> 0.9 | H13: ='PANEL DE CONTROL DISTRITAL'!H13 -> Número de trámites exitosos | I13: 0 | J13: 250 | K13: 326 | L13: 274 | M13: 322 | N13: 403 | O13: 475 | P13: 457 | Q13: 440 | R13: 429 | S13: 320 | T13: 464 | U13: 415 | V13: 542 | W13: 511 | X13: 0 | Y13: 0 | Z13: 0 | AA13: 0 | AB13: 0 | AC13: 0 | AD13: 0 | AE13: 0 | AF13: 0 | AG13: =IFERROR(SUM(I13:AF13)/SUM(I14:AF14),0) -> 0.99663538
H14: ='PANEL DE CONTROL DISTRITAL'!H12 -> Número de trámites aplicados | I14: 0 | J14: 251 | K14: 328 | L14: 274 | M14: 325 | N14: 404 | O14: 476 | P14: 459 | Q14: 440 | R14: 429 | S14: 322 | T14: 464 | U14: 415 | V14: 545 | W14: 515 | X14: 0 | Y14: 0 | Z14: 0 | AA14: 0 | AB14: 0 | AC14: 0 | AD14: 0 | AE14: 0 | AF14: 0
A16: ='PANEL DE CONTROL DISTRITAL'!A15 -> 3 | B16: ='PANEL DE CONTROL DISTRITAL'!B15 -> TRANSFERENCIA | C16: ='PANEL DE CONTROL DISTRITAL'!C15 -> Responsable de Módulo | D16: ='PANEL DE CONTROL DISTRITAL'!D15 -> Transacciones exitosas = | E16: ='PANEL DE CONTROL DISTRITAL'!E15 -> (Número de Archivos de Transacción aceptados /Total de Archivos de Transacción procesados) x100 | F16: ='PANEL DE CONTROL DISTRITAL'!F15 -> Semanal (remesa) | G16: ='PANEL DE CONTROL DISTRITAL'!G15 -> 0.9 | H16: ='PANEL DE CONTROL DISTRITAL'!H16 -> Número de Archivos de Transacción aceptados | I16: 0 | J16: 411 | K16: 593 | L16: 660 | M16: 679 | N16: 738 | O16: 886 | P16: 888 | Q16: 872 | R16: 906 | S16: 726 | T16: 855 | U16: 854 | V16: 1009 | W16: 977 | X16: 0 | Y16: 0 | Z16: 0 | AA16: 0 | AB16: 0 | AC16: 0 | AD16: 0 | AE16: 0 | AF16: 0 | AG16: =IFERROR(SUM(I16:AF16)/SUM(I17:AF17),0) -> 1
H17: ='PANEL DE CONTROL DISTRITAL'!H15 -> Total de Archivos de Transacción procesados | I17: 0 | J17: 411 | K17: 593 | L17: 660 | M17: 679 | N17: 738 | O17: 886 | P17: 888 | Q17: 872 | R17: 906 | S17: 726 | T17: 855 | U17: 854 | V17: 1009 | W17: 977 | X17: 0 | Y17: 0 | Z17: 0 | AA17: 0 | AB17: 0 | AC17: 0 | AD17: 0 | AE17: 0 | AF17: 0
A19: ='PANEL DE CONTROL DISTRITAL'!A18 -> 4 | B19: ='PANEL DE CONTROL DISTRITAL'!B18 -> CONCILIACIÓN | C19: ='PANEL DE CONTROL DISTRITAL'!C18 -> Responsable de Módulo | D19: ='PANEL DE CONTROL DISTRITAL'!D18 -> Credenciales disponibles para entrega = | E19: ='PANEL DE CONTROL DISTRITAL'!E18 -> ((Credenciales recibidas - credenciales inconsistentes )/ Credenciales Recibidas) x 100 | F19: ='PANEL DE CONTROL DISTRITAL'!F18 -> Semanal (remesa) | G19: ='PANEL DE CONTROL DISTRITAL'!G18 -> 0.9 | H19: ='PANEL DE CONTROL DISTRITAL'!H19 -> Credenciales recibidas - credenciales inconsistentes | I19: 0 | J19: 108 | K19: 343 | L19: 225 | M19: 383 | N19: 322 | O19: 404 | P19: 507 | Q19: 375 | R19: 614 | S19: 336 | T19: 332 | U19: 357 | V19: 546 | W19: 503 | X19: 0 | Y19: 0 | Z19: 0 | AA19: 0 | AB19: 0 | AC19: 0 | AD19: 0 | AE19: 0 | AF19: 0 | AG19: =IFERROR(SUM(I16:AF16)/SUM(I17:AF17),0) -> 1
H20: ='PANEL DE CONTROL DISTRITAL'!H18 -> Credenciales Recibidas | I20: 0 | J20: 108 | K20: 343 | L20: 225 | M20: 383 | N20: 322 | O20: 404 | P20: 507 | Q20: 375 | R20: 614 | S20: 336 | T20: 332 | U20: 357 | V20: 546 | W20: 503 | X20: 0 | Y20: 0 | Z20: 0 | AA20: 0 | AB20: 0 | AC20: 0 | AD20: 0 | AE20: 0 | AF20: 0
A22: ='PANEL DE CONTROL DISTRITAL'!A21 -> 5 | B22: ='PANEL DE CONTROL DISTRITAL'!B21 -> ENTREGA | C22: ='PANEL DE CONTROL DISTRITAL'!C21 -> Operador de Equipo Tecnológico | D22: ='PANEL DE CONTROL DISTRITAL'!D21 -> Efectividad de entrega de CPV en MAC = | E22: ='PANEL DE CONTROL DISTRITAL'!E21 -> Total de credenciales entregadas – reimpresiones por error de captura en MAC)/Total de credenciales entregadas ) x 100 | F22: ='PANEL DE CONTROL DISTRITAL'!F21 -> Semanal (remesa) | G22: ='PANEL DE CONTROL DISTRITAL'!G21 -> 0.9 | H22: ='PANEL DE CONTROL DISTRITAL'!H22 -> Total de credenciales entregadas – reimpresiones por error de captura en MAC | I22: 0 | J22: 160 | K22: 265 | L22: 386 | M22: 354 | N22: 334 | O22: 410 | P22: 429 | Q22: 432 | R22: 477 | S22: 404 | T22: 391 | U22: 439 | V22: 464 | W22: 462 | X22: 0 | Y22: 0 | Z22: 0 | AA22: 0 | AB22: 0 | AC22: 0 | AD22: 0 | AE22: 0 | AF22: 0 | AG22: =IFERROR(SUM(I22:AF22)/SUM(I23:AF23),0) -> 1
H23: ='PANEL DE CONTROL DISTRITAL'!H21 -> Total de credenciales entregadas | I23: 0 | J23: 160 | K23: 265 | L23: 386 | M23: 354 | N23: 334 | O23: 410 | P23: 429 | Q23: 432 | R23: 477 | S23: 404 | T23: 391 | U23: 439 | V23: 464 | W23: 462 | X23: 0 | Y23: 0 | Z23: 0 | AA23: 0 | AB23: 0 | AC23: 0 | AD23: 0 | AE23: 0 | AF23: 0
B24: *Registre el valor nominal solicitado en la celda, el resultado proporcional esta automatizado.
I26: Semaforización
J27: Valor que requiere atención y justificación en el apartado de observaciones
J28: Valor suficiente
J29: Valor esperado
A31: ='PANEL DE CONTROL DISTRITAL'!A6 -> Número | B31: ='PANEL DE CONTROL DISTRITAL'!B6:H6 -> PROCESOS SUSTANTIVOS E INDICADORES | I31: CUADRO DE OBSERVACIONES
B32: ='PANEL DE CONTROL DISTRITAL'!B7:D7 -> DESCRIPCIÓN | E32: ='PANEL DE CONTROL DISTRITAL'!E7:H7 -> MEDICIÓN
B33: ='PANEL DE CONTROL DISTRITAL'!B8 -> Proceso | C33: ='PANEL DE CONTROL DISTRITAL'!C8 -> Dueño de Proceso | D33: ='PANEL DE CONTROL DISTRITAL'!D8 -> Indicador | E33: ='PANEL DE CONTROL DISTRITAL'!E8 -> Cálculo | F33: ='PANEL DE CONTROL DISTRITAL'!F8 -> Periodo | G33: ='PANEL DE CONTROL DISTRITAL'!G8 -> Estimado | H33: =AG6 -> % AVANCE REGISTRADO | I33: Descripción | O33: No conformidad
A34: ='PANEL DE CONTROL DISTRITAL'!A9 -> 1 | B34: ='PANEL DE CONTROL DISTRITAL'!B9 -> ENTREVISTA | C34: ='PANEL DE CONTROL DISTRITAL'!C9 -> Auxiliar de Atención Ciudadana | D34: ='PANEL DE CONTROL DISTRITAL'!D9 -> Efectividad de la entrevista = | E34: ='PANEL DE CONTROL DISTRITAL'!E9 -> (Número de fichas requisitadas- tramites no identificados por huella / Número de trámites aplicados) x 100 | F34: ='PANEL DE CONTROL DISTRITAL'!F9 -> Semanal (remesa) | G34: ='PANEL DE CONTROL DISTRITAL'!G9 -> 0.9 | H34: =AG10 -> 0.99203117
A37: ='PANEL DE CONTROL DISTRITAL'!A12 -> 2 | B37: ='PANEL DE CONTROL DISTRITAL'!B12 -> TRÁMITE | C37: ='PANEL DE CONTROL DISTRITAL'!C12 -> Operador de Equipo Tecnológico | D37: ='PANEL DE CONTROL DISTRITAL'!D12 -> Trámites exitosos efectivos= | E37: ='PANEL DE CONTROL DISTRITAL'!E12 -> (Número de trámites exitosos/ Número de trámites aplicados) x 100 | F37: ='PANEL DE CONTROL DISTRITAL'!F12 -> Semanal (remesa) | G37: ='PANEL DE CONTROL DISTRITAL'!G12 -> 0.9 | H37: =AG13 -> 0.99663538
A40: ='PANEL DE CONTROL DISTRITAL'!A15 -> 3 | B40: ='PANEL DE CONTROL DISTRITAL'!B15 -> TRANSFERENCIA | C40: ='PANEL DE CONTROL DISTRITAL'!C15 -> Responsable de Módulo | D40: ='PANEL DE CONTROL DISTRITAL'!D15 -> Transacciones exitosas = | E40: ='PANEL DE CONTROL DISTRITAL'!E15 -> (Número de Archivos de Transacción aceptados /Total de Archivos de Transacción procesados) x100 | F40: ='PANEL DE CONTROL DISTRITAL'!F15 -> Semanal (remesa) | G40: ='PANEL DE CONTROL DISTRITAL'!G15 -> 0.9 | H40: =AG16 -> 1
A43: ='PANEL DE CONTROL DISTRITAL'!A18 -> 4 | B43: ='PANEL DE CONTROL DISTRITAL'!B18 -> CONCILIACIÓN | C43: ='PANEL DE CONTROL DISTRITAL'!C18 -> Responsable de Módulo | D43: ='PANEL DE CONTROL DISTRITAL'!D18 -> Credenciales disponibles para entrega = | E43: ='PANEL DE CONTROL DISTRITAL'!E18 -> ((Credenciales recibidas - credenciales inconsistentes )/ Credenciales Recibidas) x 100 | F43: ='PANEL DE CONTROL DISTRITAL'!F18 -> Semanal (remesa) | G43: ='PANEL DE CONTROL DISTRITAL'!G18 -> 0.9 | H43: =AG19 -> 1
A46: ='PANEL DE CONTROL DISTRITAL'!A21 -> 5 | B46: ='PANEL DE CONTROL DISTRITAL'!B21 -> ENTREGA | C46: ='PANEL DE CONTROL DISTRITAL'!C21 -> Operador de Equipo Tecnológico | D46: ='PANEL DE CONTROL DISTRITAL'!D21 -> Efectividad de entrega de CPV en MAC = | E46: ='PANEL DE CONTROL DISTRITAL'!E21 -> Total de credenciales entregadas – reimpresiones por error de captura en MAC)/Total de credenciales entregadas ) x 100 | F46: ='PANEL DE CONTROL DISTRITAL'!F21 -> Semanal (remesa) | G46: ='PANEL DE CONTROL DISTRITAL'!G21 -> 0.9 | H46: =AG22 -> 1

Sheet 210152
A1: ='PANEL DE CONTROL DISTRITAL'!A1:Q1 -> INSTITUTO NACIONAL ELECTORAL SISTEMA DE GESTIÓN DE LA CALIDAD PUEBLA
D2: Distrito | E2: 1 | F2: Módulo | H2: 210152 | W2: ='PANEL DE CONTROL DISTRITAL'!M2 -> Fecha de corte 07 / 12 / 2020
A4: ='210151'!A4:AG4 -> TABLERO DE CONTROL DE PROCESOS SUSTANTIVOS DEL SISTEMA DE GESTIÓN DE LA CALIDAD
A6: ='PANEL DE CONTROL DISTRITAL'!A6:A8 -> Número | B6: ='PANEL DE CONTROL DISTRITAL'!B6:H6 -> PROCESOS SUSTANTIVOS E INDICADORES | I6: ='210151'!I6:AF6 -> SEMANA OPERATIVA | AG6: ='210151'!AG6:AG9 -> % AVANCE REGISTRADO
B7: ='PANEL DE CONTROL DISTRITAL'!B7:D7 -> DESCRIPCIÓN | E7: ='PANEL DE CONTROL DISTRITAL'!E7:H7 -> MEDICIÓN | I7: ='PANEL DE CONTROL DISTRITAL'!I5 -> CAMPAÑA ANUAL INTENSA 2020-2021
B9: ='PANEL DE CONTROL DISTRITAL'!B8 -> Proceso | C9: ='PANEL DE CONTROL DISTRITAL'!C8 -> Dueño de Proceso | D9: ='PANEL DE CONTROL DISTRITAL'!D8 -> Indicador | E9: ='PANEL DE CONTROL DISTRITAL'!E8 -> Cálculo | F9: ='PANEL DE CONTROL DISTRITAL'!F8 -> Periodo | G9: ='PANEL DE CONTROL DISTRITAL'!G8 -> Estimado | H9: ='PANEL DE CONTROL DISTRITAL'!H8 -> Nominativo | I9: ='210151'!I9 -> 2020-36 | J9: ='210151'!J9 -> 2020-37 | K9: ='210151'!K9 -> 2020-38 | L9: ='210151'!L9 -> 2020-39 | M9: ='210151'!M9 -> 2020-40 | N9: ='210151'!N9 -> 2020-41 | O9: ='210151'!O9 -> 2020-42 | P9: ='210151'!P9 -> 2020-43 | ... AF9: ='210151'!AF9 -> 2021-06
A10: ='PANEL DE CONTROL DISTRITAL'!A9 -> 1 | B10: ='PANEL DE CONTROL DISTRITAL'!B9 -> ENTREVISTA | C10: ='PANEL DE CONTROL DISTRITAL'!C9 -> Auxiliar de Atención Ciudadana | D10: ='PANEL DE CONTROL DISTRITAL'!D9 -> Efectividad de la entrevista = | E10: ='PANEL DE CONTROL DISTRITAL'!E9 -> (Número de fichas requisitadas- tramites no identificados por huella / Número de trámites aplicados) x 100 | F10: ='PANEL DE CONTROL DISTRITAL'!F9 -> Semanal (remesa) | G10: ='PANEL DE CONTROL DISTRITAL'!G9 -> 0.9 | H10: ='PANEL DE CONTROL DISTRITAL'!H10 -> Número de fichas requisitadas- tramites no identificados por huella | I10: 0 | J10: 299 | K10: 406 | L10: 321 | M10: 448 | N10: 427 | O10: 403 | P10: 405 | Q10: 412 | R10: 332 | S10: 310 | T10: 423 | U10: 314 | V10: 413 | W10: 392 | X10: 0 | Y10: 0 | Z10: 0 | AA10: 0 | AB10: 0 | AC10: 0 | AD10: 0 | AE10: 0 | AF10: 0 | AG10: =IFERROR(SUM(I10:AF10)/SUM(I11:AF11),0) -> 1.0011323
H11: ='PANEL DE CONTROL DISTRITAL'!H9 -> Número de trámites aplicados | I11: 0 | J11: 299 | K11: 406 | L11: 321 | M11: 442 | N11: 427 | O11: 403 | P11: 405 | Q11: 412 | R11: 332 | S11: 310 | T11: 423 | U11: 314 | V11: 413 | W11: 392 | X11: 0 | Y11: 0 | Z11: 0 | AA11: 0 | AB11: 0 | AC11: 0 | AD11: 0 | AE11: 0 | AF11: 0
A12: 0
A13: ='PANEL DE CONTROL DISTRITAL'!A12 -> 2 | B13: ='PANEL DE CONTROL DISTRITAL'!B12 -> TRÁMITE | C13: ='PANEL DE CONTROL DISTRITAL'!C12 -> Operador de Equipo Tecnológico | D13: ='PANEL DE CONTROL DISTRITAL'!D12 -> Trámites exitosos efectivos= | E13: ='PANEL DE CONTROL DISTRITAL'!E12 -> (Número de trámites exitosos/ Número de trámites aplicados) x 100 | F13: ='PANEL DE CONTROL DISTRITAL'!F12 -> Semanal (remesa) | G13: ='PANEL DE CONTROL DISTRITAL'!G12 -> 0.9 | H13: ='PANEL DE CONTROL DISTRITAL'!H13 -> Número de trámites exitosos | I13: 0 | J13: 295 | K13: 406 | L13: 317 | M13: 440 | N13: 425 | O13: 402 | P13: 403 | Q13: 410 | R13: 329 | S13: 310 | T13: 420 | U13: 312 | V13: 411 | W13: 390 | X13: 0 | Y13: 0 | Z13: 0 | AA13: 0 | AB13: 0 | AC13: 0 | AD13: 0 | AE13: 0 | AF13: 0 | AG13: =IFERROR(SUM(I13:AF13)/SUM(I14:AF14),0) -> 0.99452727
H14: ='PANEL DE CONTROL DISTRITAL'!H12 -> Número de trámites aplicados | I14: 0 | J14: 299 | K14: 406 | L14: 321 | M14: 442 | N14: 427 | O14: 403 | P14: 405 | Q14: 412 | R14: 332 | S14: 310 | T14: 423 | U14: 314 | V14: 413 | W14: 392 | X14: 0 | Y14: 0 | Z14: 0 | AA14: 0 | AB14: 0 | AC14: 0 | AD14: 0 | AE14: 0 | AF14: 0
A15: 0
A16: ='PANEL DE CONTROL DISTRITAL'!A15 -> 3 | B16: ='PANEL DE CONTROL DISTRITAL'!B15 -> TRANSFERENCIA | C16: ='PANEL DE CONTROL DISTRITAL'!C15 -> Responsable de Módulo | D16: ='PANEL DE CONTROL DISTRITAL'!D15 -> Transacciones exitosas = | E16: ='PANEL DE CONTROL DISTRITAL'!E15 -> (Número de Archivos de Transacción aceptados /Total de Archivos de Transacción procesados) x100 | F16: ='PANEL DE CONTROL DISTRITAL'!F15 -> Semanal (remesa) | G16: ='PANEL DE CONTROL DISTRITAL'!G15 -> 0.9 | H16: ='PANEL DE CONTROL DISTRITAL'!H16 -> Número de Archivos de Transacción aceptados | I16: 0 | J16: 533 | K16: 713 | L16: 691 | M16: 839 | N16: 777 | O16: 913 | P16: 805 | Q16: 742 | R16: 758 | S16: 495 | T16: 767 | U16: 607 | V16: 832 | W16: 742 | X16: 0 | Y16: 0 | Z16: 0 | AA16: 0 | AB16: 0 | AC16: 0 | AD16: 0 | AE16: 0 | AF16: 0 | AG16: =IFERROR(SUM(I16:AF16)/SUM(I17:AF17),0) -> 1
H17: ='PANEL DE CONTROL DISTRITAL'!H15 -> Total de Archivos de Transacción procesados | I17: 0 | J17: 533 | K17: 713 | L17: 691 | M17: 839 | N17: 777 | O17: 913 | P17: 805 | Q17: 742 | R17: 758 | S17: 495 | T17: 767 | U17: 607 | V17: 832 | W17: 742 | X17: 0 | Y17: 0 | Z17: 0 | AA17: 0 | AB17: 0 | AC17: 0 | AD17: 0 | AE17: 0 | AF17: 0
A19: ='PANEL DE CONTROL DISTRITAL'!A18 -> 4 | B19: ='PANEL DE CONTROL DISTRITAL'!B18 -> CONCILIACIÓN | C19: ='PANEL DE CONTROL DISTRITAL'!C18 -> Responsable de Módulo | D19: ='PANEL DE CONTROL DISTRITAL'!D18 -> Credenciales disponibles para entrega = | E19: ='PANEL DE CONTROL DISTRITAL'!E18 -> ((Credenciales recibidas - credenciales inconsistentes )/ Credenciales Recibidas) x 100 | F19: ='PANEL DE CONTROL DISTRITAL'!F18 -> Semanal (remesa) | G19: ='PANEL DE CONTROL DISTRITAL'!G18 -> 0.9 | H19: ='PANEL DE CONTROL DISTRITAL'!H19 -> Credenciales recibidas - credenciales inconsistentes | I19: 0 | J19: 113 | K19: 388 | L19: 270 | M19: 473 | N19: 442 | O19: 417 | P19: 358 | Q19: 404 | R19: 479 | S19: 260 | T19: 283 | U19: 422 | V19: 430 | W19: 304 | X19: 0 | Y19: 0 | Z19: 0 | AA19: 0 | AB19: 0 | AC19: 0 | AD19: 0 | AE19: 0 | AF19: 0 | AG19: =IFERROR(SUM(I16:AF16)/SUM(I17:AF17),0) -> 1
H20: ='PANEL DE CONTROL DISTRITAL'!H18 -> Credenciales Recibidas | I20: 0 | J20: 113 | K20: 388 | L20: 270 | M20: 473 | N20: 442 | O20: 417 | P20: 358 | Q20: 404 | R20: 479 | S20: 260 | T20: 283 | U20: 422 | V20: 430 | W20: 304 | X20: 0 | Y20: 0 | Z20: 0 | AA20: 0 | AB20: 0 | AC20: 0 | AD20: 0 | AE20: 0 | AF20: 0
A22: ='PANEL DE CONTROL DISTRITAL'!A21 -> 5 | B22: ='PANEL DE CONTROL DISTRITAL'!B21 -> ENTREGA | C22: ='PANEL DE CONTROL DISTRITAL'!C21 -> Operador de Equipo Tecnológico | D22: ='PANEL DE CONTROL DISTRITAL'!D21 -> Efectividad de entrega de CPV en MAC = | E22: ='PANEL DE CONTROL DISTRITAL'!E21 -> Total de credenciales entregadas – reimpresiones por error de captura en MAC)/Total de credenciales entregadas ) x 100 | F22: ='PANEL DE CONTROL DISTRITAL'!F21 -> Semanal (remesa) | G22: ='PANEL DE CONTROL DISTRITAL'!G21 -> 0.9 | H22: ='PANEL DE CONTROL DISTRITAL'!H22 -> Total de credenciales entregadas – reimpresiones por error de captura en MAC | I22: 0 | J22: 234 | K22: 307 | L22: 370 | M22: 397 | N22: 353 | O22: 510 | P22: 400 | Q22: 330 | R22: 426 | S22: 385 | T22: 344 | U22: 293 | V22: 419 | W22: 350 | X22: 0 | Y22: 0 | Z22: 0 | AA22: 0 | AB22: 0 | AC22: 0 | AD22: 0 | AE22: 0 | AF22: 0 | AG22: =IFERROR(SUM(I22:AF22)/SUM(I23:AF23),0) -> 1
H23: ='PANEL DE CONTROL DISTRITAL'!H21 -> Total de credenciales entregadas | I23: 0 | J23: 234 | K23: 307 | L23: 370 | M23: 397 | N23: 353 | O23: 510 | P23: 400 | Q23: 330 | R23: 426 | S23: 385 | T23: 344 | U23: 293 | V23: 419 | W23: 350 | X23: 0 | Y23: 0 | Z23: 0 | AA23: 0 | AB23: 0 | AC23: 0 | AD23: 0 | AE23: 0 | AF23: 0
B24: *Registre el valor nominal solicitado en la celda, el resultado proporcional esta automatizado.
I26: Semaforización
J27: Valor que requiere atención y justificación en el apartado de observaciones
J28: Valor suficiente
J29: Valor esperado
A31: ='PANEL DE CONTROL DISTRITAL'!A6 -> Número | B31: ='PANEL DE CONTROL DISTRITAL'!B6:H6 -> PROCESOS SUSTANTIVOS E INDICADORES | I31: ='210151'!I31:T32 -> CUADRO DE OBSERVACIONES
B32: ='PANEL DE CONTROL DISTRITAL'!B7:D7 -> DESCRIPCIÓN | E32: ='PANEL DE CONTROL DISTRITAL'!E7:H7 -> MEDICIÓN
B33: ='PANEL DE CONTROL DISTRITAL'!B8 -> Proceso | C33: ='PANEL DE CONTROL DISTRITAL'!C8 -> Dueño de Proceso | D33: ='PANEL DE CONTROL DISTRITAL'!D8 -> Indicador | E33: ='PANEL DE CONTROL DISTRITAL'!E8 -> Cálculo | F33: ='PANEL DE CONTROL DISTRITAL'!F8 -> Periodo | G33: ='PANEL DE CONTROL DISTRITAL'!G8 -> Estimado | H33: =AG6 -> % AVANCE REGISTRADO | I33: ='210151'!I33:N33 -> Descripción | O33: ='210151'!O33:T33 -> No conformidad
A34: ='PANEL DE CONTROL DISTRITAL'!A9 -> 1 | B34: ='PANEL DE CONTROL DISTRITAL'!B9 -> ENTREVISTA | C34: ='PANEL DE CONTROL DISTRITAL'!C9 -> Auxiliar de Atención Ciudadana | D34: ='PANEL DE CONTROL DISTRITAL'!D9 -> Efectividad de la entrevista = | E34: ='PANEL DE CONTROL DISTRITAL'!E9 -> (Número de fichas requisitadas- tramites no identificados por huella / Número de trámites aplicados) x 100 | F34: ='PANEL DE CONTROL DISTRITAL'!F9 -> Semanal (remesa) | G34: ='PANEL DE CONTROL DISTRITAL'!G9 -> 0.9 | H34: =AG10 -> 1.0011323
A37: ='PANEL DE CONTROL DISTRITAL'!A12 -> 2 | B37: ='PANEL DE CONTROL DISTRITAL'!B12 -> TRÁMITE | C37: ='PANEL DE CONTROL DISTRITAL'!C12 -> Operador de Equipo Tecnológico | D37: ='PANEL DE CONTROL DISTRITAL'!D12 -> Trámites exitosos efectivos= | E37: ='PANEL DE CONTROL DISTRITAL'!E12 -> (Número de trámites exitosos/ Número de trámites aplicados) x 100 | F37: ='PANEL DE CONTROL DISTRITAL'!F12 -> Semanal (remesa) | G37: ='PANEL DE CONTROL DISTRITAL'!G12 -> 0.9 | H37: =AG13 -> 0.99452727
A40: ='PANEL DE CONTROL DISTRITAL'!A15 -> 3 | B40: ='PANEL DE CONTROL DISTRITAL'!B15 -> TRANSFERENCIA | C40: ='PANEL DE CONTROL DISTRITAL'!C15 -> Responsable de Módulo | D40: ='PANEL DE CONTROL DISTRITAL'!D15 -> Transacciones exitosas = | E40: ='PANEL DE CONTROL DISTRITAL'!E15 -> (Número de Archivos de Transacción aceptados /Total de Archivos de Transacción procesados) x100 | F40: ='PANEL DE CONTROL DISTRITAL'!F15 -> Semanal (remesa) | G40: ='PANEL DE CONTROL DISTRITAL'!G15 -> 0.9 | H40: =AG16 -> 1
A43: ='PANEL DE CONTROL DISTRITAL'!A18 -> 4 | B43: ='PANEL DE CONTROL DISTRITAL'!B18 -> CONCILIACIÓN | C43: ='PANEL DE CONTROL DISTRITAL'!C18 -> Responsable de Módulo | D43: ='PANEL DE CONTROL DISTRITAL'!D18 -> Credenciales disponibles para entrega = | E43: ='PANEL DE CONTROL DISTRITAL'!E18 -> ((Credenciales recibidas - credenciales inconsistentes )/ Credenciales Recibidas) x 100 | F43: ='PANEL DE CONTROL DISTRITAL'!F18 -> Semanal (remesa) | G43: ='PANEL DE CONTROL DISTRITAL'!G18 -> 0.9 | H43: =AG19 -> 1
A46: ='PANEL DE CONTROL DISTRITAL'!A21 -> 5 | B46: ='PANEL DE CONTROL DISTRITAL'!B21 -> ENTREGA | C46: ='PANEL DE CONTROL DISTRITAL'!C21 -> Operador de Equipo Tecnológico | D46: ='PANEL DE CONTROL DISTRITAL'!D21 -> Efectividad de entrega de CPV en MAC = | E46: ='PANEL DE CONTROL DISTRITAL'!E21 -> Total de credenciales entregadas – reimpresiones por error de captura en MAC)/Total de credenciales entregadas ) x 100 | F46: ='PANEL DE CONTROL DISTRITAL'!F21 -> Semanal (remesa) | G46: ='PANEL DE CONTROL DISTRITAL'!G21 -> 0.9 | H46: =AG22 -> 1

Sheet 210153
A1: ='PANEL DE CONTROL DISTRITAL'!A1:Q1 -> INSTITUTO NACIONAL ELECTORAL SISTEMA DE GESTIÓN DE LA CALIDAD PUEBLA
D2: Distrito | E2: 1 | F2: Módulo | H2: 210153 | W2: ='PANEL DE CONTROL DISTRITAL'!M2 -> Fecha de corte 07 / 12 / 2020
A4: ='210151'!A4:AG4 -> TABLERO DE CONTROL DE PROCESOS SUSTANTIVOS DEL SISTEMA DE GESTIÓN DE LA CALIDAD
A6: ='PANEL DE CONTROL DISTRITAL'!A6:A8 -> Número | B6: ='PANEL DE CONTROL DISTRITAL'!B6:H6 -> PROCESOS SUSTANTIVOS E INDICADORES | I6: ='210151'!I6:AF6 -> SEMANA OPERATIVA | AG6: ='210151'!AG6:AG9 -> % AVANCE REGISTRADO
B7: ='PANEL DE CONTROL DISTRITAL'!B7:D7 -> DESCRIPCIÓN | E7: ='PANEL DE CONTROL DISTRITAL'!E7:H7 -> MEDICIÓN | I7: ='PANEL DE CONTROL DISTRITAL'!I5 -> CAMPAÑA ANUAL INTENSA 2020-2021
B9: ='PANEL DE CONTROL DISTRITAL'!B8 -> Proceso | C9: ='PANEL DE CONTROL DISTRITAL'!C8 -> Dueño de Proceso | D9: ='PANEL DE CONTROL DISTRITAL'!D8 -> Indicador | E9: ='PANEL DE CONTROL DISTRITAL'!E8 -> Cálculo | F9: ='PANEL DE CONTROL DISTRITAL'!F8 -> Periodo | G9: ='PANEL DE CONTROL DISTRITAL'!G8 -> Estimado | H9: ='PANEL DE CONTROL DISTRITAL'!H8 -> Nominativo | I9: ='210151'!I9 -> 2020-36 | J9: ='210151'!J9 -> 2020-37 | K9: ='210151'!K9 -> 2020-38 | L9: ='210151'!L9 -> 2020-39 | M9: ='210151'!M9 -> 2020-40 | N9: ='210151'!N9 -> 2020-41 | O9: ='210151'!O9 -> 2020-42 | P9: ='210151'!P9 -> 2020-43 | ... AF9: ='210151'!AF9 -> 2021-06
A10: ='PANEL DE CONTROL DISTRITAL'!A9 -> 1 | B10: ='PANEL DE CONTROL DISTRITAL'!B9 -> ENTREVISTA | C10: ='PANEL DE CONTROL DISTRITAL'!C9 -> Auxiliar de Atención Ciudadana | D10: ='PANEL DE CONTROL DISTRITAL'!D9 -> Efectividad de la entrevista = | E10: ='PANEL DE CONTROL DISTRITAL'!E9 -> (Número de fichas requisitadas- tramites no identificados por huella / Número de trámites aplicados) x 100 | F10: ='PANEL DE CONTROL DISTRITAL'!F9 -> Semanal (remesa) | G10: ='PANEL DE CONTROL DISTRITAL'!G9 -> 0.9 | H10: ='PANEL DE CONTROL DISTRITAL'!H10 -> Número de fichas requisitadas- tramites no identificados por huella | I10: 0 | J10: 0 | K10: 0 | L10: 0 | M10: 0 | N10: 0 | O10: 76 | P10: 178 | Q10: 86 | R10: 91 | S10: 69 | T10: 133 | U10: 97 | V10: 124 | W10: 124 | X10: 0 | Y10: 0 | Z10: 0 | AA10: 0 | AB10: 0 | AC10: 0 | AD10: 0 | AE10: 0 | AF10: 0 | AG10: =IFERROR(SUM(I10:AF10)/SUM(I11:AF11),0) -> 1
H11: ='PANEL DE CONTROL DISTRITAL'!H9 -> Número de trámites aplicados | I11: 0 | J11: 0 | K11: 0 | L11: 0 | M11: 0 | N11: 0 | O11: 76 | P11: 178 | Q11: 86 | R11: 91 | S11: 69 | T11: 133 | U11: 97 | V11: 124 | W11: 124 | X11: 0 | Y11: 0 | Z11: 0 | AA11: 0 | AB11: 0 | AC11: 0 | AD11: 0 | AE11: 0 | AF11: 0
A13: ='PANEL DE CONTROL DISTRITAL'!A12 -> 2 | B13: ='PANEL DE CONTROL DISTRITAL'!B12 -> TRÁMITE | C13: ='PANEL DE CONTROL DISTRITAL'!C12 -> Operador de Equipo Tecnológico | D13: ='PANEL DE CONTROL DISTRITAL'!D12 -> Trámites exitosos efectivos= | E13: ='PANEL DE CONTROL DISTRITAL'!E12 -> (Número de trámites exitosos/ Número de trámites aplicados) x 100 | F13: ='PANEL DE CONTROL DISTRITAL'!F12 -> Semanal (remesa) | G13: ='PANEL DE CONTROL DISTRITAL'!G12 -> 0.9 | H13: ='PANEL DE CONTROL DISTRITAL'!H13 -> Número de trámites exitosos | I13: 0 | J13: 0 | K13: 0 | L13: 0 | M13: 0 | N13: 0 | O13: 75 | P13: 177 | Q13: 84 | R13: 91 | S13: 69 | T13: 128 | U13: 96 | V13: 123 | W13: 123 | X13: 0 | Y13: 0 | Z13: 0 | AA13: 0 | AB13: 0 | AC13: 0 | AD13: 0 | AE13: 0 | AF13: 0 | AG13: =IFERROR(SUM(I13:AF13)/SUM(I14:AF14),0) -> 0.98773006
H14: ='PANEL DE CONTROL DISTRITAL'!H12 -> Número de trámites aplicados | I14: 0 | J14: 0 | K14: 0 | L14: 0 | M14: 0 | N14: 0 | O14: 76 | P14: 178 | Q14: 86 | R14: 91 | S14: 69 | T14: 133 | U14: 97 | V14: 124 | W14: 124 | X14: 0 | Y14: 0 | Z14: 0 | AA14: 0 | AB14: 0 | AC14: 0 | AD14: 0 | AE14: 0 | AF14: 0
A16: ='PANEL DE CONTROL DISTRITAL'!A15 -> 3 | B16: ='PANEL DE CONTROL DISTRITAL'!B15 -> TRANSFERENCIA | C16: ='PANEL DE CONTROL DISTRITAL'!C15 -> Responsable de Módulo | D16: ='PANEL DE CONTROL DISTRITAL'!D15 -> Transacciones exitosas = | E16: ='PANEL DE CONTROL DISTRITAL'!E15 -> (Número de Archivos de Transacción aceptados /Total de Archivos de Transacción procesados) x100 | F16: ='PANEL DE CONTROL DISTRITAL'!F15 -> Semanal (remesa) | G16: ='PANEL DE CONTROL DISTRITAL'!G15 -> 0.9 | H16: ='PANEL DE CONTROL DISTRITAL'!H16 -> Número de Archivos de Transacción aceptados | I16: 0 | J16: 10 | K16: 12 | L16: 34 | M16: 23 | N16: 22 | O16: 128 | P16: 221 | Q16: 229 | R16: 236 | S16: 205 | T16: 224 | U16: 199 | V16: 245 | W16: 261 | X16: 0 | Y16: 0 | Z16: 0 | AA16: 0 | AB16: 0 | AC16: 0 | AD16: 0 | AE16: 0 | AF16: 0 | AG16: =IFERROR(SUM(I16:AF16)/SUM(I17:AF17),0) -> 1
H17: ='PANEL DE CONTROL DISTRITAL'!H15 -> Total de Archivos de Transacción procesados | I17: 0 | J17: 10 | K17: 12 | L17: 34 | M17: 23 | N17: 22 | O17: 128 | P17: 221 | Q17: 229 | R17: 236 | S17: 205 | T17: 224 | U17: 199 | V17: 245 | W17: 261 | X17: 0 | Y17: 0 | Z17: 0 | AA17: 0 | AB17: 0 | AC17: 0 | AD17: 0 | AE17: 0 | AF17: 0
A19: ='PANEL DE CONTROL DISTRITAL'!A18 -> 4 | B19: ='PANEL DE CONTROL DISTRITAL'!B18 -> CONCILIACIÓN | C19: ='PANEL DE CONTROL DISTRITAL'!C18 -> Responsable de Módulo | D19: ='PANEL DE CONTROL DISTRITAL'!D18 -> Credenciales disponibles para entrega = | E19: ='PANEL DE CONTROL DISTRITAL'!E18 -> ((Credenciales recibidas - credenciales inconsistentes )/ Credenciales Recibidas) x 100 | F19: ='PANEL DE CONTROL DISTRITAL'!F18 -> Semanal (remesa) | G19: ='PANEL DE CONTROL DISTRITAL'!G18 -> 0.9 | H19: ='PANEL DE CONTROL DISTRITAL'!H19 -> Credenciales recibidas - credenciales inconsistentes | I19: 0 | J19: 0 | K19: 1 | L19: 0 | M19: 0 | N19: 0 | O19: 1 | P19: 108 | Q19: 119 | R19: 145 | S19: 65 | T19: 71 | U19: 109 | V19: 94 | W19: 141 | X19: 0 | Y19: 0 | Z19: 0 | AA19: 0 | AB19: 0 | AC19: 0 | AD19: 0 | AE19: 0 | AF19: 0 | AG19: =IFERROR(SUM(I16:AF16)/SUM(I17:AF17),0) -> 1
H20: ='PANEL DE CONTROL DISTRITAL'!H18 -> Credenciales Recibidas | I20: 0 | J20: 0 | K20: 1 | L20: 0 | M20: 0 | N20: 0 | O20: 1 | P20: 108 | Q20: 119 | R20: 145 | S20: 65 | T20: 71 | U20: 109 | V20: 94 | W20: 141 | X20: 0 | Y20: 0 | Z20: 0 | AA20: 0 | AB20: 0 | AC20: 0 | AD20: 0 | AE20: 0 | AF20: 0
A22: ='PANEL DE CONTROL DISTRITAL'!A21 -> 5 | B22: ='PANEL DE CONTROL DISTRITAL'!B21 -> ENTREGA | C22: ='PANEL DE CONTROL DISTRITAL'!C21 -> Operador de Equipo Tecnológico | D22: ='PANEL DE CONTROL DISTRITAL'!D21 -> Efectividad de entrega de CPV en MAC = | E22: ='PANEL DE CONTROL DISTRITAL'!E21 -> Total de credenciales entregadas – reimpresiones por error de captura en MAC)/Total de credenciales entregadas ) x 100 | F22: ='PANEL DE CONTROL DISTRITAL'!F21 -> Semanal (remesa) | G22: ='PANEL DE CONTROL DISTRITAL'!G21 -> 0.9 | H22: ='PANEL DE CONTROL DISTRITAL'!H22 -> Total de credenciales entregadas – reimpresiones por error de captura en MAC | I22: 0 | J22: 10 | K22: 12 | L22: 34 | M22: 23 | N22: 22 | O22: 52 | P22: 43 | Q22: 143 | R22: 145 | S22: 136 | T22: 91 | U22: 102 | V22: 121 | W22: 137 | X22: 0 | Y22: 0 | Z22: 0 | AA22: 0 | AB22: 0 | AC22: 0 | AD22: 0 | AE22: 0 | AF22: 0 | AG22: =IFERROR(SUM(I22:AF22)/SUM(I23:AF23),0) -> 1
H23: ='PANEL DE CONTROL DISTRITAL'!H21 -> Total de credenciales entregadas | I23: 0 | J23: 10 | K23: 12 | L23: 34 | M23: 23 | N23: 22 | O23: 52 | P23: 43 | Q23: 143 | R23: 145 | S23: 136 | T23: 91 | U23: 102 | V23: 121 | W23: 137 | X23: 0 | Y23: 0 | Z23: 0 | AA23: 0 | AB23: 0 | AC23: 0 | AD23: 0 | AE23: 0 | AF23: 0
B24: *Registre el valor nominal solicitado en la celda, el resultado proporcional esta automatizado.
I26: Semaforización
J27: Valor que requiere atención y justificación en el apartado de observaciones
J28: Valor suficiente
J29: Valor esperado
A31: ='PANEL DE CONTROL DISTRITAL'!A6 -> Número | B31: ='PANEL DE CONTROL DISTRITAL'!B6:H6 -> PROCESOS SUSTANTIVOS E INDICADORES | I31: ='210151'!I31:T32 -> CUADRO DE OBSERVACIONES
B32: ='PANEL DE CONTROL DISTRITAL'!B7:D7 -> DESCRIPCIÓN | E32: ='PANEL DE CONTROL DISTRITAL'!E7:H7 -> MEDICIÓN
B33: ='PANEL DE CONTROL DISTRITAL'!B8 -> Proceso | C33: ='PANEL DE CONTROL DISTRITAL'!C8 -> Dueño de Proceso | D33: ='PANEL DE CONTROL DISTRITAL'!D8 -> Indicador | E33: ='PANEL DE CONTROL DISTRITAL'!E8 -> Cálculo | F33: ='PANEL DE CONTROL DISTRITAL'!F8 -> Periodo | G33: ='PANEL DE CONTROL DISTRITAL'!G8 -> Estimado | H33: =AG6 -> % AVANCE REGISTRADO | I33: ='210151'!I33:N33 -> Descripción | O33: ='210151'!O33:T33 -> No conformidad
A34: ='PANEL DE CONTROL DISTRITAL'!A9 -> 1 | B34: ='PANEL DE CONTROL DISTRITAL'!B9 -> ENTREVISTA | C34: ='PANEL DE CONTROL DISTRITAL'!C9 -> Auxiliar de Atención Ciudadana | D34: ='PANEL DE CONTROL DISTRITAL'!D9 -> Efectividad de la entrevista = | E34: ='PANEL DE CONTROL DISTRITAL'!E9 -> (Número de fichas requisitadas- tramites no identificados por huella / Número de trámites aplicados) x 100 | F34: ='PANEL DE CONTROL DISTRITAL'!F9 -> Semanal (remesa) | G34: ='PANEL DE CONTROL DISTRITAL'!G9 -> 0.9 | H34: =AG10 -> 1
A37: ='PANEL DE CONTROL DISTRITAL'!A12 -> 2 | B37: ='PANEL DE CONTROL DISTRITAL'!B12 -> TRÁMITE | C37: ='PANEL DE CONTROL DISTRITAL'!C12 -> Operador de Equipo Tecnológico | D37: ='PANEL DE CONTROL DISTRITAL'!D12 -> Trámites exitosos efectivos= | E37: ='PANEL DE CONTROL DISTRITAL'!E12 -> (Número de trámites exitosos/ Número de trámites aplicados) x 100 | F37: ='PANEL DE CONTROL DISTRITAL'!F12 -> Semanal (remesa) | G37: ='PANEL DE CONTROL DISTRITAL'!G12 -> 0.9 | H37: =AG13 -> 0.98773006
A40: ='PANEL DE CONTROL DISTRITAL'!A15 -> 3 | B40: ='PANEL DE CONTROL DISTRITAL'!B15 -> TRANSFERENCIA | C40: ='PANEL DE CONTROL DISTRITAL'!C15 -> Responsable de Módulo | D40: ='PANEL DE CONTROL DISTRITAL'!D15 -> Transacciones exitosas = | E40: ='PANEL DE CONTROL DISTRITAL'!E15 -> (Número de Archivos de Transacción aceptados /Total de Archivos de Transacción procesados) x100 | F40: ='PANEL DE CONTROL DISTRITAL'!F15 -> Semanal (remesa) | G40: ='PANEL DE CONTROL DISTRITAL'!G15 -> 0.9 | H40: =AG16 -> 1
A43: ='PANEL DE CONTROL DISTRITAL'!A18 -> 4 | B43: ='PANEL DE CONTROL DISTRITAL'!B18 -> CONCILIACIÓN | C43: ='PANEL DE CONTROL DISTRITAL'!C18 -> Responsable de Módulo | D43: ='PANEL DE CONTROL DISTRITAL'!D18 -> Credenciales disponibles para entrega = | E43: ='PANEL DE CONTROL DISTRITAL'!E18 -> ((Credenciales recibidas - credenciales inconsistentes )/ Credenciales Recibidas) x 100 | F43: ='PANEL DE CONTROL DISTRITAL'!F18 -> Semanal (remesa) | G43: ='PANEL DE CONTROL DISTRITAL'!G18 -> 0.9 | H43: =AG19 -> 1
A46: ='PANEL DE CONTROL DISTRITAL'!A21 -> 5 | B46: ='PANEL DE CONTROL DISTRITAL'!B21 -> ENTREGA | C46: ='PANEL DE CONTROL DISTRITAL'!C21 -> Operador de Equipo Tecnológico | D46: ='PANEL DE CONTROL DISTRITAL'!D21 -> Efectividad de entrega de CPV en MAC = | E46: ='PANEL DE CONTROL DISTRITAL'!E21 -> Total de credenciales entregadas – reimpresiones por error de captura en MAC)/Total de credenciales entregadas ) x 100 | F46: ='PANEL DE CONTROL DISTRITAL'!F21 -> Semanal (remesa) | G46: ='PANEL DE CONTROL DISTRITAL'!G21 -> 0.9 | H46: =AG22 -> 1

Sheet 210154
A1: ='PANEL DE CONTROL DISTRITAL'!A1:Q1 -> INSTITUTO NACIONAL ELECTORAL SISTEMA DE GESTIÓN DE LA CALIDAD PUEBLA
D2: Distrito | E2: 1 | F2: Módulo | H2: 210154 | W2: ='PANEL DE CONTROL DISTRITAL'!M2 -> Fecha de corte 07 / 12 / 2020
A4: ='210151'!A4:AG4 -> TABLERO DE CONTROL DE PROCESOS SUSTANTIVOS DEL SISTEMA DE GESTIÓN DE LA CALIDAD
A6: ='PANEL DE CONTROL DISTRITAL'!A6:A8 -> Número | B6: ='PANEL DE CONTROL DISTRITAL'!B6:H6 -> PROCESOS SUSTANTIVOS E INDICADORES | I6: ='210151'!I6:AF6 -> SEMANA OPERATIVA | AG6: ='210151'!AG6:AG9 -> % AVANCE REGISTRADO
B7: ='PANEL DE CONTROL DISTRITAL'!B7:D7 -> DESCRIPCIÓN | E7: ='PANEL DE CONTROL DISTRITAL'!E7:H7 -> MEDICIÓN | I7: ='PANEL DE CONTROL DISTRITAL'!I5 -> CAMPAÑA ANUAL INTENSA 2020-2021
B9: ='PANEL DE CONTROL DISTRITAL'!B8 -> Proceso | C9: ='PANEL DE CONTROL DISTRITAL'!C8 -> Dueño de Proceso | D9: ='PANEL DE CONTROL DISTRITAL'!D8 -> Indicador | E9: ='PANEL DE CONTROL DISTRITAL'!E8 -> Cálculo | F9: ='PANEL DE CONTROL DISTRITAL'!F8 -> Periodo | G9: ='PANEL DE CONTROL DISTRITAL'!G8 -> Estimado | H9: ='PANEL DE CONTROL DISTRITAL'!H8 -> Nominativo | I9: ='210151'!I9 -> 2020-36 | J9: ='210151'!J9 -> 2020-37 | K9: ='210151'!K9 -> 2020-38 | L9: ='210151'!L9 -> 2020-39 | M9: ='210151'!M9 -> 2020-40 | N9: ='210151'!N9 -> 2020-41 | O9: ='210151'!O9 -> 2020-42 | P9: ='210151'!P9 -> 2020-43 | ... AF9: ='210151'!AF9 -> 2021-06
A10: ='PANEL DE CONTROL DISTRITAL'!A9 -> 1 | B10: ='PANEL DE CONTROL DISTRITAL'!B9 -> ENTREVISTA | C10: ='PANEL DE CONTROL DISTRITAL'!C9 -> Auxiliar de Atención Ciudadana | D10: ='PANEL DE CONTROL DISTRITAL'!D9 -> Efectividad de la entrevista = | E10: ='PANEL DE CONTROL DISTRITAL'!E9 -> (Número de fichas requisitadas- tramites no identificados por huella / Número de trámites aplicados) x 100 | F10: ='PANEL DE CONTROL DISTRITAL'!F9 -> Semanal (remesa) | G10: ='PANEL DE CONTROL DISTRITAL'!G9 -> 0.9 | H10: ='PANEL DE CONTROL DISTRITAL'!H10 -> Número de fichas requisitadas- tramites no identificados por huella | I10: 0 | J10: 0 | K10: 0 | L10: 0 | M10: 0 | N10: 0 | O10: 79 | P10: 149 | Q10: 129 | R10: 128 | S10: 107 | T10: 205 | U10: 167 | V10: 188 | W10: 146 | X10: 0 | Y10: 0 | Z10: 0 | AA10: 0 | AB10: 0 | AC10: 0 | AD10: 0 | AE10: 0 | AF10: 0 | AG10: =IFERROR(SUM(I10:AF10)/SUM(I11:AF11),0) -> 1
H11: ='PANEL DE CONTROL DISTRITAL'!H9 -> Número de trámites aplicados | I11: 0 | J11: 0 | K11: 0 | L11: 0 | M11: 0 | N11: 0 | O11: 79 | P11: 149 | Q11: 129 | R11: 128 | S11: 107 | T11: 205 | U11: 167 | V11: 188 | W11: 146 | X11: 0 | Y11: 0 | Z11: 0 | AA11: 0 | AB11: 0 | AC11: 0 | AD11: 0 | AE11: 0 | AF11: 0
A13: ='PANEL DE CONTROL DISTRITAL'!A12 -> 2 | B13: ='PANEL DE CONTROL DISTRITAL'!B12 -> TRÁMITE | C13: ='PANEL DE CONTROL DISTRITAL'!C12 -> Operador de Equipo Tecnológico | D13: ='PANEL DE CONTROL DISTRITAL'!D12 -> Trámites exitosos efectivos= | E13: ='PANEL DE CONTROL DISTRITAL'!E12 -> (Número de trámites exitosos/ Número de trámites aplicados) x 100 | F13: ='PANEL DE CONTROL DISTRITAL'!F12 -> Semanal (remesa) | G13: ='PANEL DE CONTROL DISTRITAL'!G12 -> 0.9 | H13: ='PANEL DE CONTROL DISTRITAL'!H13 -> Número de trámites exitosos | I13: 0 | J13: 0 | K13: 0 | L13: 0 | M13: 0 | N13: 0 | O13: 78 | P13: 149 | Q13: 128 | R13: 126 | S13: 105 | T13: 204 | U13: 164 | V13: 188 | W13: 145 | X13: 0 | Y13: 0 | Z13: 0 | AA13: 0 | AB13: 0 | AC13: 0 | AD13: 0 | AE13: 0 | AF13: 0 | AG13: =IFERROR(SUM(I13:AF13)/SUM(I14:AF14),0) -> 0.99152542
H14: ='PANEL DE CONTROL DISTRITAL'!H12 -> Número de trámites aplicados | I14: 0 | J14: 0 | K14: 0 | L14: 0 | M14: 0 | N14: 0 | O14: 79 | P14: 149 | Q14: 129 | R14: 128 | S14: 107 | T14: 205 | U14: 167 | V14: 188 | W14: 146 | X14: 0 | Y14: 0 | Z14: 0 | AA14: 0 | AB14: 0 | AC14: 0 | AD14: 0 | AE14: 0 | AF14: 0
A15: 0
A16: ='PANEL DE CONTROL DISTRITAL'!A15 -> 3 | B16: ='PANEL DE CONTROL DISTRITAL'!B15 -> TRANSFERENCIA | C16: ='PANEL DE CONTROL DISTRITAL'!C15 -> Responsable de Módulo | D16: ='PANEL DE CONTROL DISTRITAL'!D15 -> Transacciones exitosas = | E16: ='PANEL DE CONTROL DISTRITAL'!E15 -> (Número de Archivos de Transacción aceptados /Total de Archivos de Transacción procesados) x100 | F16: ='PANEL DE CONTROL DISTRITAL'!F15 -> Semanal (remesa) | G16: ='PANEL DE CONTROL DISTRITAL'!G15 -> 0.9 | H16: ='PANEL DE CONTROL DISTRITAL'!H16 -> Número de Archivos de Transacción aceptados | I16: 0 | J16: 16 | K16: 12 | L16: 15 | M16: 22 | N16: 14 | O16: 96 | P16: 184 | Q16: 208 | R16: 294 | S16: 266 | T16: 356 | U16: 343 | V16: 373 | W16: 310 | X16: 0 | Y16: 0 | Z16: 0 | AA16: 0 | AB16: 0 | AC16: 0 | AD16: 0 | AE16: 0 | AF16: 0 | AG16: =IFERROR(SUM(I16:AF16)/SUM(I17:AF17),0) -> 1
H17: ='PANEL DE CONTROL DISTRITAL'!H15 -> Total de Archivos de Transacción procesados | I17: 0 | J17: 16 | K17: 12 | L17: 15 | M17: 22 | N17: 14 | O17: 96 | P17: 184 | Q17: 208 | R17: 294 | S17: 266 | T17: 356 | U17: 343 | V17: 373 | W17: 310 | X17: 0 | Y17: 0 | Z17: 0 | AA17: 0 | AB17: 0 | AC17: 0 | AD17: 0 | AE17: 0 | AF17: 0
A19: ='PANEL DE CONTROL DISTRITAL'!A18 -> 4 | B19: ='PANEL DE CONTROL DISTRITAL'!B18 -> CONCILIACIÓN | C19: ='PANEL DE CONTROL DISTRITAL'!C18 -> Responsable de Módulo | D19: ='PANEL DE CONTROL DISTRITAL'!D18 -> Credenciales disponibles para entrega = | E19: ='PANEL DE CONTROL DISTRITAL'!E18 -> ((Credenciales recibidas - credenciales inconsistentes )/ Credenciales Recibidas) x 100 | F19: ='PANEL DE CONTROL DISTRITAL'!F18 -> Semanal (remesa) | G19: ='PANEL DE CONTROL DISTRITAL'!G18 -> 0.9 | H19: ='PANEL DE CONTROL DISTRITAL'!H19 -> Credenciales recibidas - credenciales inconsistentes | I19: 0 | J19: 0 | K19: 0 | L19: 0 | M19: 0 | N19: 0 | O19: 3 | P19: 75 | Q19: 153 | R19: 183 | S19: 83 | T19: 130 | U19: 161 | V19: 162 | W19: 207 | X19: 0 | Y19: 0 | Z19: 0 | AA19: 0 | AB19: 0 | AC19: 0 | AD19: 0 | AE19: 0 | AF19: 0 | AG19: =IFERROR(SUM(I16:AF16)/SUM(I17:AF17),0) -> 1
H20: ='PANEL DE CONTROL DISTRITAL'!H18 -> Credenciales Recibidas | I20: 0 | J20: 0 | K20: 0 | L20: 0 | M20: 0 | N20: 0 | O20: 3 | P20: 75 | Q20: 153 | R20: 183 | S20: 83 | T20: 130 | U20: 161 | V20: 162 | W20: 207 | X20: 0 | Y20: 0 | Z20: 0 | AA20: 0 | AB20: 0 | AC20: 0 | AD20: 0 | AE20: 0 | AF20: 0
A22: ='PANEL DE CONTROL DISTRITAL'!A21 -> 5 | B22: ='PANEL DE CONTROL DISTRITAL'!B21 -> ENTREGA | C22: ='PANEL DE CONTROL DISTRITAL'!C21 -> Operador de Equipo Tecnológico | D22: ='PANEL DE CONTROL DISTRITAL'!D21 -> Efectividad de entrega de CPV en MAC = | E22: ='PANEL DE CONTROL DISTRITAL'!E21 -> Total de credenciales entregadas – reimpresiones por error de captura en MAC)/Total de credenciales entregadas ) x 100 | F22: ='PANEL DE CONTROL DISTRITAL'!F21 -> Semanal (remesa) | G22: ='PANEL DE CONTROL DISTRITAL'!G21 -> 0.9 | H22: ='PANEL DE CONTROL DISTRITAL'!H22 -> Total de credenciales entregadas – reimpresiones por error de captura en MAC | I22: 0 | J22: 16 | K22: 12 | L22: 15 | M22: 22 | N22: 14 | O22: 17 | P22: 35 | Q22: 79 | R22: 166 | S22: 159 | T22: 151 | U22: 176 | V22: 185 | W22: 164 | X22: 0 | Y22: 0 | Z22: 0 | AA22: 0 | AB22: 0 | AC22: 0 | AD22: 0 | AE22: 0 | AF22: 0 | AG22: =IFERROR(SUM(I22:AF22)/SUM(I23:AF23),0) -> 1
H23: ='PANEL DE CONTROL DISTRITAL'!H21 -> Total de credenciales entregadas | I23: 0 | J23: 16 | K23: 12 | L23: 15 | M23: 22 | N23: 14 | O23: 17 | P23: 35 | Q23: 79 | R23: 166 | S23: 159 | T23: 151 | U23: 176 | V23: 185 | W23: 164 | X23: 0 | Y23: 0 | Z23: 0 | AA23: 0 | AB23: 0 | AC23: 0 | AD23: 0 | AE23: 0 | AF23: 0
B24: *Registre el valor nominal solicitado en la celda, el resultado proporcional esta automatizado.
I26: Semaforización
J27: Valor que requiere atención y justificación en el apartado de observaciones
J28: Valor suficiente
J29: Valor esperado
A31: ='PANEL DE CONTROL DISTRITAL'!A6 -> Número | B31: ='PANEL DE CONTROL DISTRITAL'!B6:H6 -> PROCESOS SUSTANTIVOS E INDICADORES | I31: ='210151'!I31:T32 -> CUADRO DE OBSERVACIONES
B32: ='PANEL DE CONTROL DISTRITAL'!B7:D7 -> DESCRIPCIÓN | E32: ='PANEL DE CONTROL DISTRITAL'!E7:H7 -> MEDICIÓN
B33: ='PANEL DE CONTROL DISTRITAL'!B8 -> Proceso | C33: ='PANEL DE CONTROL DISTRITAL'!C8 -> Dueño de Proceso | D33: ='PANEL DE CONTROL DISTRITAL'!D8 -> Indicador | E33: ='PANEL DE CONTROL DISTRITAL'!E8 -> Cálculo | F33: ='PANEL DE CONTROL DISTRITAL'!F8 -> Periodo | G33: ='PANEL DE CONTROL DISTRITAL'!G8 -> Estimado | H33: =AG6 -> % AVANCE REGISTRADO | I33: ='210151'!I33:N33 -> Descripción | O33: ='210151'!O33:T33 -> No conformidad
A34: ='PANEL DE CONTROL DISTRITAL'!A9 -> 1 | B34: ='PANEL DE CONTROL DISTRITAL'!B9 -> ENTREVISTA | C34: ='PANEL DE CONTROL DISTRITAL'!C9 -> Auxiliar de Atención Ciudadana | D34: ='PANEL DE CONTROL DISTRITAL'!D9 -> Efectividad de la entrevista = | E34: ='PANEL DE CONTROL DISTRITAL'!E9 -> (Número de fichas requisitadas- tramites no identificados por huella / Número de trámites aplicados) x 100 | F34: ='PANEL DE CONTROL DISTRITAL'!F9 -> Semanal (remesa) | G34: ='PANEL DE CONTROL DISTRITAL'!G9 -> 0.9 | H34: =AG10 -> 1
A37: ='PANEL DE CONTROL DISTRITAL'!A12 -> 2 | B37: ='PANEL DE CONTROL DISTRITAL'!B12 -> TRÁMITE | C37: ='PANEL DE CONTROL DISTRITAL'!C12 -> Operador de Equipo Tecnológico | D37: ='PANEL DE CONTROL DISTRITAL'!D12 -> Trámites exitosos efectivos= | E37: ='PANEL DE CONTROL DISTRITAL'!E12 -> (Número de trámites exitosos/ Número de trámites aplicados) x 100 | F37: ='PANEL DE CONTROL DISTRITAL'!F12 -> Semanal (remesa) | G37: ='PANEL DE CONTROL DISTRITAL'!G12 -> 0.9 | H37: =AG13 -> 0.99152542
A40: ='PANEL DE CONTROL DISTRITAL'!A15 -> 3 | B40: ='PANEL DE CONTROL DISTRITAL'!B15 -> TRANSFERENCIA | C40: ='PANEL DE CONTROL DISTRITAL'!C15 -> Responsable de Módulo | D40: ='PANEL DE CONTROL DISTRITAL'!D15 -> Transacciones exitosas = | E40: ='PANEL DE CONTROL DISTRITAL'!E15 -> (Número de Archivos de Transacción aceptados /Total de Archivos de Transacción procesados) x100 | F40: ='PANEL DE CONTROL DISTRITAL'!F15 -> Semanal (remesa) | G40: ='PANEL DE CONTROL DISTRITAL'!G15 -> 0.9 | H40: =AG16 -> 1
A43: ='PANEL DE CONTROL DISTRITAL'!A18 -> 4 | B43: ='PANEL DE CONTROL DISTRITAL'!B18 -> CONCILIACIÓN | C43: ='PANEL DE CONTROL DISTRITAL'!C18 -> Responsable de Módulo | D43: ='PANEL DE CONTROL DISTRITAL'!D18 -> Credenciales disponibles para entrega = | E43: ='PANEL DE CONTROL DISTRITAL'!E18 -> ((Credenciales recibidas - credenciales inconsistentes )/ Credenciales Recibidas) x 100 | F43: ='PANEL DE CONTROL DISTRITAL'!F18 -> Semanal (remesa) | G43: ='PANEL DE CONTROL DISTRITAL'!G18 -> 0.9 | H43: =AG19 -> 1
A46: ='PANEL DE CONTROL DISTRITAL'!A21 -> 5 | B46: ='PANEL DE CONTROL DISTRITAL'!B21 -> ENTREGA | C46: ='PANEL DE CONTROL DISTRITAL'!C21 -> Operador de Equipo Tecnológico | D46: ='PANEL DE CONTROL DISTRITAL'!D21 -> Efectividad de entrega de CPV en MAC = | E46: ='PANEL DE CONTROL DISTRITAL'!E21 -> Total de credenciales entregadas – reimpresiones por error de captura en MAC)/Total de credenciales entregadas ) x 100 | F46: ='PANEL DE CONTROL DISTRITAL'!F21 -> Semanal (remesa) | G46: ='PANEL DE CONTROL DISTRITAL'!G21 -> 0.9 | H46: =AG22 -> 1

Sheet 210155
A1: ='PANEL DE CONTROL DISTRITAL'!A1:Q1 -> INSTITUTO NACIONAL ELECTORAL SISTEMA DE GESTIÓN DE LA CALIDAD PUEBLA
D2: Distrito | E2: 1 | F2: Módulo | H2: 210155 | W2: ='PANEL DE CONTROL DISTRITAL'!M2 -> Fecha de corte 07 / 12 / 2020
A4: ='210151'!A4:AG4 -> TABLERO DE CONTROL DE PROCESOS SUSTANTIVOS DEL SISTEMA DE GESTIÓN DE LA CALIDAD
A6: ='PANEL DE CONTROL DISTRITAL'!A6:A8 -> Número | B6: ='PANEL DE CONTROL DISTRITAL'!B6:H6 -> PROCESOS SUSTANTIVOS E INDICADORES | I6: ='210151'!I6:AF6 -> SEMANA OPERATIVA | AG6: ='210151'!AG6:AG9 -> % AVANCE REGISTRADO
B7: ='PANEL DE CONTROL DISTRITAL'!B7:D7 -> DESCRIPCIÓN | E7: ='PANEL DE CONTROL DISTRITAL'!E7:H7 -> MEDICIÓN | I7: ='PANEL DE CONTROL DISTRITAL'!I5 -> CAMPAÑA ANUAL INTENSA 2020-2021
B9: ='PANEL DE CONTROL DISTRITAL'!B8 -> Proceso | C9: ='PANEL DE CONTROL DISTRITAL'!C8 -> Dueño de Proceso | D9: ='PANEL DE CONTROL DISTRITAL'!D8 -> Indicador | E9: ='PANEL DE CONTROL DISTRITAL'!E8 -> Cálculo | F9: ='PANEL DE CONTROL DISTRITAL'!F8 -> Periodo | G9: ='PANEL DE CONTROL DISTRITAL'!G8 -> Estimado | H9: ='PANEL DE CONTROL DISTRITAL'!H8 -> Nominativo | I9: ='210151'!I9 -> 2020-36 | J9: ='210151'!J9 -> 2020-37 | K9: ='210151'!K9 -> 2020-38 | L9: ='210151'!L9 -> 2020-39 | M9: ='210151'!M9 -> 2020-40 | N9: ='210151'!N9 -> 2020-41 | O9: ='210151'!O9 -> 2020-42 | P9: ='210151'!P9 -> 2020-43 | ... AF9: ='210151'!AF9 -> 2021-06
A10: ='PANEL DE CONTROL DISTRITAL'!A9 -> 1 | B10: ='PANEL DE CONTROL DISTRITAL'!B9 -> ENTREVISTA | C10: ='PANEL DE CONTROL DISTRITAL'!C9 -> Auxiliar de Atención Ciudadana | D10: ='PANEL DE CONTROL DISTRITAL'!D9 -> Efectividad de la entrevista = | E10: ='PANEL DE CONTROL DISTRITAL'!E9 -> (Número de fichas requisitadas- tramites no identificados por huella / Número de trámites aplicados) x 100 | F10: ='PANEL DE CONTROL DISTRITAL'!F9 -> Semanal (remesa) | G10: ='PANEL DE CONTROL DISTRITAL'!G9 -> 0.9 | H10: ='PANEL DE CONTROL DISTRITAL'!H10 -> Número de fichas requisitadas- tramites no identificados por huella | I10: 0 | J10: 0 | K10: 0 | L10: 0 | M10: 0 | N10: 0 | O10: 0 | P10: 0 | Q10: 0 | R10: 0 | S10: 0 | T10: 0 | U10: 0 | V10: 0 | W10: 0 | X10: 0 | Y10: 0 | Z10: 0 | AA10: 0 | AB10: 0 | AC10: 0 | AD10: 0 | AE10: 0 | AF10: 0 | AG10: =IFERROR(SUM(I10:AF10)/SUM(I11:AF11),0) -> 0
H11: ='PANEL DE CONTROL DISTRITAL'!H9 -> Número de trámites aplicados | I11: 0 | J11: 0 | K11: 0 | L11: 0 | M11: 0 | N11: 0 | O11: 0 | P11: 0 | Q11: 0 | R11: 0 | S11: 0 | T11: 0 | U11: 0 | V11: 0 | W11: 0 | X11: 0 | Y11: 0 | Z11: 0 | AA11: 0 | AB11: 0 | AC11: 0 | AD11: 0 | AE11: 0 | AF11: 0
A13: ='PANEL DE CONTROL DISTRITAL'!A12 -> 2 | B13: ='PANEL DE CONTROL DISTRITAL'!B12 -> TRÁMITE | C13: ='PANEL DE CONTROL DISTRITAL'!C12 -> Operador de Equipo Tecnológico | D13: ='PANEL DE CONTROL DISTRITAL'!D12 -> Trámites exitosos efectivos= | E13: ='PANEL DE CONTROL DISTRITAL'!E12 -> (Número de trámites exitosos/ Número de trámites aplicados) x 100 | F13: ='PANEL DE CONTROL DISTRITAL'!F12 -> Semanal (remesa) | G13: ='PANEL DE CONTROL DISTRITAL'!G12 -> 0.9 | H13: ='PANEL DE CONTROL DISTRITAL'!H13 -> Número de trámites exitosos | I13: 0 | J13: 0 | K13: 0 | L13: 0 | M13: 0 | N13: 0 | O13: 0 | P13: 0 | Q13: 0 | R13: 0 | S13: 0 | T13: 0 | U13: 0 | V13: 0 | W13: 0 | X13: 0 | Y13: 0 | Z13: 0 | AA13: 0 | AB13: 0 | AC13: 0 | AD13: 0 | AE13: 0 | AF13: 0 | AG13: =IFERROR(SUM(I13:AF13)/SUM(I14:AF14),0) -> 0
H14: ='PANEL DE CONTROL DISTRITAL'!H12 -> Número de trámites aplicados | I14: 0 | J14: 0 | K14: 0 | L14: 0 | M14: 0 | N14: 0 | O14: 0 | P14: 0 | Q14: 0 | R14: 0 | S14: 0 | T14: 0 | U14: 0 | V14: 0 | W14: 0 | X14: 0 | Y14: 0 | Z14: 0 | AA14: 0 | AB14: 0 | AC14: 0 | AD14: 0 | AE14: 0 | AF14: 0
A16: ='PANEL DE CONTROL DISTRITAL'!A15 -> 3 | B16: ='PANEL DE CONTROL DISTRITAL'!B15 -> TRANSFERENCIA | C16: ='PANEL DE CONTROL DISTRITAL'!C15 -> Responsable de Módulo | D16: ='PANEL DE CONTROL DISTRITAL'!D15 -> Transacciones exitosas = | E16: ='PANEL DE CONTROL DISTRITAL'!E15 -> (Número de Archivos de Transacción aceptados /Total de Archivos de Transacción procesados) x100 | F16: ='PANEL DE CONTROL DISTRITAL'!F15 -> Semanal (remesa) | G16: ='PANEL DE CONTROL DISTRITAL'!G15 -> 0.9 | H16: ='PANEL DE CONTROL DISTRITAL'!H16 -> Número de Archivos de Transacción aceptados | I16: 0 | J16: 6 | K16: 16 | L16: 12 | M16: 4 | N16: 4 | O16: 10 | P16: 9 | Q16: 4 | R16: 15 | S16: 15 | T16: 14 | U16: 10 | V16: 8 | W16: 6 | X16: 0 | Y16: 0 | Z16: 0 | AA16: 0 | AB16: 0 | AC16: 0 | AD16: 0 | AE16: 0 | AF16: 0 | AG16: =IFERROR(SUM(I16:AF16)/SUM(I17:AF17),0) -> 1
H17: ='PANEL DE CONTROL DISTRITAL'!H15 -> Total de Archivos de Transacción procesados | I17: 0 | J17: 6 | K17: 16 | L17: 12 | M17: 4 | N17: 4 | O17: 10 | P17: 9 | Q17: 4 | R17: 15 | S17: 15 | T17: 14 | U17: 10 | V17: 8 | W17: 6 | X17: 0 | Y17: 0 | Z17: 0 | AA17: 0 | AB17: 0 | AC17: 0 | AD17: 0 | AE17: 0 | AF17: 0
A19: ='PANEL DE CONTROL DISTRITAL'!A18 -> 4 | B19: ='PANEL DE CONTROL DISTRITAL'!B18 -> CONCILIACIÓN | C19: ='PANEL DE CONTROL DISTRITAL'!C18 -> Responsable de Módulo | D19: ='PANEL DE CONTROL DISTRITAL'!D18 -> Credenciales disponibles para entrega = | E19: ='PANEL DE CONTROL DISTRITAL'!E18 -> ((Credenciales recibidas - credenciales inconsistentes )/ Credenciales Recibidas) x 100 | F19: ='PANEL DE CONTROL DISTRITAL'!F18 -> Semanal (remesa) | G19: ='PANEL DE CONTROL DISTRITAL'!G18 -> 0.9 | H19: ='PANEL DE CONTROL DISTRITAL'!H19 -> Credenciales recibidas - credenciales inconsistentes | I19: 0 | J19: 0 | K19: 0 | L19: 0 | M19: 0 | N19: 0 | O19: 3 | P19: 0 | Q19: 0 | R19: 0 | S19: 0 | T19: 0 | U19: 0 | V19: 0 | W19: 0 | X19: 0 | Y19: 0 | Z19: 0 | AA19: 0 | AB19: 0 | AC19: 0 | AD19: 0 | AE19: 0 | AF19: 0 | AG19: =IFERROR(SUM(I16:AF16)/SUM(I17:AF17),0) -> 1
H20: ='PANEL DE CONTROL DISTRITAL'!H18 -> Credenciales Recibidas | I20: 0 | J20: 0 | K20: 0 | L20: 0 | M20: 0 | N20: 0 | O20: 3 | P20: 0 | Q20: 0 | R20: 0 | S20: 0 | T20: 0 | U20: 0 | V20: 0 | W20: 0 | X20: 0 | Y20: 0 | Z20: 0 | AA20: 0 | AB20: 0 | AC20: 0 | AD20: 0 | AE20: 0 | AF20: 0
