Workbook
Name AMENAZARAS: [1]CÁLCULOS!$B$29:$B$30
Name Entorno: Ponderación!$A$2:$B$11
Name Impacto: [2]Ponderación!$G$2:$H$4
Name Impacto: Ponderación!$G$2:$H$5
Name INTENSIDAD: [1]CÁLCULOS!$B$22:$B$26
Name Menor: "Severidad"
Name Naturaleza: [2]Ponderación!$A$2:$B$8
Name Naturaleza: Ponderación!$A$2:$B$11
Name Probabilidad: [2]Ponderación!$D$2:$E$4
Name Probabilidad: Ponderación!$D$2:$E$4

Sheet Matriz Riesgo y Op
D2: INSTITUTO NACIONAL ELECTORAL JLE PUEBLA SISTEMA DE GESTIÓN DE LA CALIDAD | L2: Versión: 0
D3: ANALISÍS DE RIESGOS/OPORTUNIDADES PROCESO DE SUMINISTRO DE BIENES Y SERVICIOS | L3: Fecha de emisión: 06/03/2020
A5: ATENCIÓN A RIESGOS
A6: IDENTIFICACIÓN | I6: EVALUACIÓN | L6: SEGUIMIENTO
A7: CLASIFICACIÓN RIESGO / OPORTUNIDAD | B7: ACTIVIDAD DEL PROCESO | C7: ¿CUAL ES EL RIESGO DE QUE NO SE REALICE LA ACTIVIDAD? | D7: PROBABILIDAD DE QUE PASE | E7: ¿QUÉ LO ORIGINO? | F7: CONSECUENCIAS | G7: IMPACTO AL PROCESO | H7: ENTORNO DEL RIESGO | I7: NIVEL DE RIESGO / OPORTUNIDAD | J7: CLASIFICACIÓN | K7: DICTAMEN | L7: CONCLUSIONES | M7: ACCIONES DE RESPUESTA | N7: RESPONSABLE
A8: Riesgo | B8: Especificaciones técnicas del bien o servicio solicitado (si aplica) | C8: Proveer un bien o servicio no adecuado | D8: Baja | E8: * Por omitir o sean insuficientes las especificaciones del bien en la solicitud o requerimiento. | F8: * Que el bien solicitado no cumpla con las especificaciones requeridas. * Entregar el bien o servicio a destiempo. | G8: Leve | H8: Operativo | I8: =IFERROR(VLOOKUP(H8,Naturaleza,2,FALSE)*VLOOKUP('Matriz Riesgo y Op'!D8,Probabilidad,2,FALSE)*VLOOKUP('Matriz Riesgo y Op'!G8,Impacto,2,FALSE),"") -> 10 | J8: =IF(A8="Riesgo",IF(I8="","",IF(AND(I8>0,I8<200),"Trivial",IF(OR(I8=200,AND(I8>200,I8<400)),"Tolerable",IF(OR(I8=400,AND(I8>400,I8<600)),"Moderado",IF(OR(I8=600,AND(I8>600,I8<800)),"Importante",IF(OR(I8=800,I8>800,I8<1000,I8=1000),"Intolerable","")))))),IF(A8="Oportunidad",IF(I8="","",IF(AND(I8>0,I8<250),"Limitada",IF(OR(I8=250,AND(I8>250,I8<500)),"Media",IF(OR(I8=500,AND(I8>500,I8<750)),"Potencial",IF(OR(I8=750,AND(I8>750,I8<=1000)),"Sobresaliente",""))))),"")) -> Trivial | K8: =IFERROR(VLOOKUP(J8,'Parámetros de riesgo'!$B$27:$C$31,2,FALSE),IFERROR(VLOOKUP(J8,'Parámetros de riesgo'!$H$27:$I$30,2,FALSE),"")) -> VIGILARLO | L8: Control rutinario que de no realizar4se no se lograrán los estándares solicitados | M8: Garantizar que la información indicada en la "Requisición del bien y servicio" este completa y correcta. | N8: Vocales Secretarios Distritales/ Enlaces Administrativos
A13: Riesgo | B13: Revisión de la requisición o solicitud del área requirente | C13: Que el bien solicitado no sea el adecuado | D13: Baja | E13: * Que no se haga una revisión correcta a la "Requisición del bien y servicio". | F13: * Proveer el bien o servicio de forma extemporánea o que no cumpla con las especificaciones requeridas. | G13: Leve | H13: Operativo | I13: =IFERROR(VLOOKUP(H13,Naturaleza,2,FALSE)*VLOOKUP('Matriz Riesgo y Op'!D13,Probabilidad,2,FALSE)*VLOOKUP('Matriz Riesgo y Op'!G13,Impacto,2,FALSE),"") -> 10 | J13: =IF(A13="Riesgo",IF(I13="","",IF(AND(I13>0,I13<200),"Trivial",IF(OR(I13=200,AND(I13>200,I13<400)),"Tolerable",IF(OR(I13=400,AND(I13>400,I13<600)),"Moderado",IF(OR(I13=600,AND(I13>600,I13<800)),"Importante",IF(OR(I13=800,I13>800,I13<1000,I13=1000),"Intolerable","")))))),IF(A13="Oportunidad",IF(I13="","",IF(AND(I13>0,I13<250),"Limitada",IF(OR(I13=250,AND(I13>250,I13<500)),"Media",IF(OR(I13=500,AND(I13>500,I13<750)),"Potencial",IF(OR(I13=750,AND(I13>750,I13<=1000)),"Sobresaliente",""))))),"")) -> Trivial | K13: =IFERROR(VLOOKUP(J13,'Parámetros de riesgo'!$B$27:$C$31,2,FALSE),IFERROR(VLOOKUP(J13,'Parámetros de riesgo'!$H$27:$I$30,2,FALSE),"")) -> VIGILARLO | L13: =IFERROR(VLOOKUP(K13,'Parámetros de riesgo'!$C$27:$D$31,2,FALSE),IFERROR(VLOOKUP(K13,'Parámetros de riesgo'!$I$27:$J$30,2,FALSE),"")) -> Control rutinario, no afecta la secuencia e integridad del proceso y/o Partes Interesadas. Documentar las acciones de respuesta en la Evaluación de Efectividad de riesgos y oportunidades. | M13: Garantizar que la información indicada en la "Requisición del bien y servicio" este completa y correcta. | N13: Vocales Secretarios Distritales/ Enlaces Administrativos
A18: Riesgo | B18: Identificación de partida y presupuesto autorizado | C18: No contar con suficiencia presupuestal en las partidas o que el presupuesto del bien o servicio se encuentre en otra partida | D18: Baja | E18: * Presupuesto limitado o retraso de la ministración en las estructuras programáticas de proyectos. | F18: * Que no sea posible en tiempo y forma la adquisición del bien o servicio. | G18: Leve | H18: Operativo | I18: =IFERROR(VLOOKUP(H18,Naturaleza,2,FALSE)*VLOOKUP('Matriz Riesgo y Op'!D18,Probabilidad,2,FALSE)*VLOOKUP('Matriz Riesgo y Op'!G18,Impacto,2,FALSE),"") -> 10 | J18: =IF(A18="Riesgo",IF(I18="","",IF(AND(I18>0,I18<200),"Trivial",IF(OR(I18=200,AND(I18>200,I18<400)),"Tolerable",IF(OR(I18=400,AND(I18>400,I18<600)),"Moderado",IF(OR(I18=600,AND(I18>600,I18<800)),"Importante",IF(OR(I18=800,I18>800,I18<1000,I18=1000),"Intolerable","")))))),IF(A18="Oportunidad",IF(I18="","",IF(AND(I18>0,I18<250),"Limitada",IF(OR(I18=250,AND(I18>250,I18<500)),"Media",IF(OR(I18=500,AND(I18>500,I18<750)),"Potencial",IF(OR(I18=750,AND(I18>750,I18<=1000)),"Sobresaliente",""))))),"")) -> Trivial | K18: =IFERROR(VLOOKUP(J18,'Parámetros de riesgo'!$B$27:$C$31,2,FALSE),IFERROR(VLOOKUP(J18,'Parámetros de riesgo'!$H$27:$I$30,2,FALSE),"")) -> VIGILARLO | L18: =IFERROR(VLOOKUP(K18,'Parámetros de riesgo'!$C$27:$D$31,2,FALSE),IFERROR(VLOOKUP(K18,'Parámetros de riesgo'!$I$27:$J$30,2,FALSE),"")) -> Control rutinario, no afecta la secuencia e integridad del proceso y/o Partes Interesadas. Documentar las acciones de respuesta en la Evaluación de Efectividad de riesgos y oportunidades. | M18: Monitorear la ministración de recursos cada vez que llega una "Requisición del bien y servicio". | N18: Vocales Secretarios Distritales/ Enlaces Administrativos
A23: Riesgo | B23: Investigación de Mercado (cuadro comparativo) | C23: Que no se cuente con los presupuestos respecto a las especificaciones solicitadas del bien o servicio | D23: Baja | E23: * No contar con una lista de proveedores amplia y actualizada que limite el margen de estudio. | F23: * Que el cuadro comparativo de costos no sea correcto, lo que implica no tomar la decisión de compra del bien o servicio. | G23: Leve | H23: Operativo | I23: =IFERROR(VLOOKUP(H23,Naturaleza,2,FALSE)*VLOOKUP('Matriz Riesgo y Op'!D23,Probabilidad,2,FALSE)*VLOOKUP('Matriz Riesgo y Op'!G23,Impacto,2,FALSE),"") -> 10 | J23: =IF(A23="Riesgo",IF(I23="","",IF(AND(I23>0,I23<200),"Trivial",IF(OR(I23=200,AND(I23>200,I23<400)),"Tolerable",IF(OR(I23=400,AND(I23>400,I23<600)),"Moderado",IF(OR(I23=600,AND(I23>600,I23<800)),"Importante",IF(OR(I23=800,I23>800,I23<1000,I23=1000),"Intolerable","")))))),IF(A23="Oportunidad",IF(I23="","",IF(AND(I23>0,I23<250),"Limitada",IF(OR(I23=250,AND(I23>250,I23<500)),"Media",IF(OR(I23=500,AND(I23>500,I23<750)),"Potencial",IF(OR(I23=750,AND(I23>750,I23<=1000)),"Sobresaliente",""))))),"")) -> Trivial | K23: =IFERROR(VLOOKUP(J23,'Parámetros de riesgo'!$B$27:$C$31,2,FALSE),IFERROR(VLOOKUP(J23,'Parámetros de riesgo'!$H$27:$I$30,2,FALSE),"")) -> VIGILARLO | L23: =IFERROR(VLOOKUP(K23,'Parámetros de riesgo'!$C$27:$D$31,2,FALSE),IFERROR(VLOOKUP(K23,'Parámetros de riesgo'!$I$27:$J$30,2,FALSE),"")) -> Control rutinario, no afecta la secuencia e integridad del proceso y/o Partes Interesadas. Documentar las acciones de respuesta en la Evaluación de Efectividad de riesgos y oportunidades. | M23: Ampliar el Catálogo de Proveedores para facilitar el estudio de Mercado. | N23: Vocales Secretarios Distritales/ Enlaces Administrativos
A28: Riesgo | B28: Cotizaciones (cuadro comparativo) | C28: No contar con un documento en el que se concentren las mejores propuestas de proveedores para el Instituto | D28: Baja | E28: * Actuar apresuradamente por adquirir el bien en tiempo y forma. | F28: * Adquirir bienes que no cumplan las especificaciones técnicas, ni mejor precio para el Instituto. | G28: Moderado | H28: Operativo | I28: =IFERROR(VLOOKUP(H28,Naturaleza,2,FALSE)*VLOOKUP('Matriz Riesgo y Op'!D28,Probabilidad,2,FALSE)*VLOOKUP('Matriz Riesgo y Op'!G28,Impacto,2,FALSE),"") -> 70 | J28: =IF(A28="Riesgo",IF(I28="","",IF(AND(I28>0,I28<200),"Trivial",IF(OR(I28=200,AND(I28>200,I28<400)),"Tolerable",IF(OR(I28=400,AND(I28>400,I28<600)),"Moderado",IF(OR(I28=600,AND(I28>600,I28<800)),"Importante",IF(OR(I28=800,I28>800,I28<1000,I28=1000),"Intolerable","")))))),IF(A28="Oportunidad",IF(I28="","",IF(AND(I28>0,I28<250),"Limitada",IF(OR(I28=250,AND(I28>250,I28<500)),"Media",IF(OR(I28=500,AND(I28>500,I28<750)),"Potencial",IF(OR(I28=750,AND(I28>750,I28<=1000)),"Sobresaliente",""))))),"")) -> Trivial | K28: =IFERROR(VLOOKUP(J28,'Parámetros de riesgo'!$B$27:$C$31,2,FALSE),IFERROR(VLOOKUP(J28,'Parámetros de riesgo'!$H$27:$I$30,2,FALSE),"")) -> VIGILARLO | L28: =IFERROR(VLOOKUP(K28,'Parámetros de riesgo'!$C$27:$D$31,2,FALSE),IFERROR(VLOOKUP(K28,'Parámetros de riesgo'!$I$27:$J$30,2,FALSE),"")) -> Control rutinario, no afecta la secuencia e integridad del proceso y/o Partes Interesadas. Documentar las acciones de respuesta en la Evaluación de Efectividad de riesgos y oportunidades. | M28: Garantizar la elaboración del cuadro comparativo. | N28: Vocales Secretarios Distritales/ Enlaces Administrativos
A33: Riesgo | B33: Definición del tipo de adquisición – contrato / Pedido-Contrato | C33: Definir el tipo de contrato incorrectamente | D33: Baja | E33: * Por desconocimiento de la norma administrativa u omisión de procedimientos. | F33: * Que no sea posible la oportuna adquisición del bien o servicio. | G33: Leve | H33: Operativo | I33: =IFERROR(VLOOKUP(H33,Naturaleza,2,FALSE)*VLOOKUP('Matriz Riesgo y Op'!D33,Probabilidad,2,FALSE)*VLOOKUP('Matriz Riesgo y Op'!G33,Impacto,2,FALSE),"") -> 10 | J33: =IF(A33="Riesgo",IF(I33="","",IF(AND(I33>0,I33<200),"Trivial",IF(OR(I33=200,AND(I33>200,I33<400)),"Tolerable",IF(OR(I33=400,AND(I33>400,I33<600)),"Moderado",IF(OR(I33=600,AND(I33>600,I33<800)),"Importante",IF(OR(I33=800,I33>800,I33<1000,I33=1000),"Intolerable","")))))),IF(A33="Oportunidad",IF(I33="","",IF(AND(I33>0,I33<250),"Limitada",IF(OR(I33=250,AND(I33>250,I33<500)),"Media",IF(OR(I33=500,AND(I33>500,I33<750)),"Potencial",IF(OR(I33=750,AND(I33>750,I33<=1000)),"Sobresaliente",""))))),"")) -> Trivial | K33: =IFERROR(VLOOKUP(J33,'Parámetros de riesgo'!$B$27:$C$31,2,FALSE),IFERROR(VLOOKUP(J33,'Parámetros de riesgo'!$H$27:$I$30,2,FALSE),"")) -> VIGILARLO | L33: =IFERROR(VLOOKUP(K33,'Parámetros de riesgo'!$C$27:$D$31,2,FALSE),IFERROR(VLOOKUP(K33,'Parámetros de riesgo'!$I$27:$J$30,2,FALSE),"")) -> Control rutinario, no afecta la secuencia e integridad del proceso y/o Partes Interesadas. Documentar las acciones de respuesta en la Evaluación de Efectividad de riesgos y oportunidades. | M33: Asegurar que se este aplicando la normatividad vigente para la determinación del tipo de adquisición. | N33: Vocales Secretarios Distritales/ Enlaces Administrativos
A38: Riesgo | B38: Autorización del Subcomité de Adquisiciones, Arrendamientos y Servicios | C38: Que no se lleve a cabo la adquisición del bien o servicio en tiempo y forma para atender la solicitud | D38: Baja | E38: * Que el área requirente no haya realizado la solicitud en los tiempos establecidos. | F38: * Que no sea posible en oportunidad la adquisición del bien o servicio. | G38: Leve | H38: Operativo | I38: =IFERROR(VLOOKUP(H38,Naturaleza,2,FALSE)*VLOOKUP('Matriz Riesgo y Op'!D38,Probabilidad,2,FALSE)*VLOOKUP('Matriz Riesgo y Op'!G38,Impacto,2,FALSE),"") -> 10 | J38: =IF(A38="Riesgo",IF(I38="","",IF(AND(I38>0,I38<200),"Trivial",IF(OR(I38=200,AND(I38>200,I38<400)),"Tolerable",IF(OR(I38=400,AND(I38>400,I38<600)),"Moderado",IF(OR(I38=600,AND(I38>600,I38<800)),"Importante",IF(OR(I38=800,I38>800,I38<1000,I38=1000),"Intolerable","")))))),IF(A38="Oportunidad",IF(I38="","",IF(AND(I38>0,I38<250),"Limitada",IF(OR(I38=250,AND(I38>250,I38<500)),"Media",IF(OR(I38=500,AND(I38>500,I38<750)),"Potencial",IF(OR(I38=750,AND(I38>750,I38<=1000)),"Sobresaliente",""))))),"")) -> Trivial | K38: =IFERROR(VLOOKUP(J38,'Parámetros de riesgo'!$B$27:$C$31,2,FALSE),IFERROR(VLOOKUP(J38,'Parámetros de riesgo'!$H$27:$I$30,2,FALSE),"")) -> VIGILARLO | L38: =IFERROR(VLOOKUP(K38,'Parámetros de riesgo'!$C$27:$D$31,2,FALSE),IFERROR(VLOOKUP(K38,'Parámetros de riesgo'!$I$27:$J$30,2,FALSE),"")) -> Control rutinario, no afecta la secuencia e integridad del proceso y/o Partes Interesadas. Documentar las acciones de respuesta en la Evaluación de Efectividad de riesgos y oportunidades. | M38: Concentrar la información indicada en la "Requisición del bien y servicio", para el análisis previo a la autorización. | N38: Vocales Secretarios Distritales/ Enlaces Administrativos
A43: Riesgo | B43: Se adjudica al Proveedor la Adquisición del bien o servicio | C43: No se cumpla con la entrega del bien o servicio por la falta de confirmación al Proveedor de que se le adjudica la adquisición | D43: Baja | E43: * No enviar el Pedido - Contrato al Proveedor que se le adjudica la adquisición. | F43: * Que no se cuente con el bien o servicio en tiempo y forma. | G43: Leve | H43: Operativo | I43: =IFERROR(VLOOKUP(H43,Naturaleza,2,FALSE)*VLOOKUP('Matriz Riesgo y Op'!D43,Probabilidad,2,FALSE)*VLOOKUP('Matriz Riesgo y Op'!G43,Impacto,2,FALSE),"") -> 10 | J43: =IF(A43="Riesgo",IF(I43="","",IF(AND(I43>0,I43<200),"Trivial",IF(OR(I43=200,AND(I43>200,I43<400)),"Tolerable",IF(OR(I43=400,AND(I43>400,I43<600)),"Moderado",IF(OR(I43=600,AND(I43>600,I43<800)),"Importante",IF(OR(I43=800,I43>800,I43<1000,I43=1000),"Intolerable","")))))),IF(A43="Oportunidad",IF(I43="","",IF(AND(I43>0,I43<250),"Limitada",IF(OR(I43=250,AND(I43>250,I43<500)),"Media",IF(OR(I43=500,AND(I43>500,I43<750)),"Potencial",IF(OR(I43=750,AND(I43>750,I43<=1000)),"Sobresaliente",""))))),"")) -> Trivial | K43: =IFERROR(VLOOKUP(J43,'Parámetros de riesgo'!$B$27:$C$31,2,FALSE),IFERROR(VLOOKUP(J43,'Parámetros de riesgo'!$H$27:$I$30,2,FALSE),"")) -> VIGILARLO | L43: =IFERROR(VLOOKUP(K43,'Parámetros de riesgo'!$C$27:$D$31,2,FALSE),IFERROR(VLOOKUP(K43,'Parámetros de riesgo'!$I$27:$J$30,2,FALSE),"")) -> Control rutinario, no afecta la secuencia e integridad del proceso y/o Partes Interesadas. Documentar las acciones de respuesta en la Evaluación de Efectividad de riesgos y oportunidades. | M43: Asegurar que se envíe la confirmación del Pedido- Contrato al proveedor. | N43: Vocales Secretarios Distritales/ Enlaces Administrativos
M44: Garantizar que se atienda el Pedido - contrato por parte del Proveedor (confirmación a través del correo electrónico o vía telefónica). | N44: Vocales Secretarios Distritales/ Enlaces Administrativos
A48: Riesgo | B48: Recepción y Salida de Almacén | C48: Que el registro y la clasificación de los bienes no sea el adecuado | D48: Baja | E48: * Premura en la solicitud del bien por parte del área requirente. | F48: * No contar con un reporte de existencias almacenarías confiable. * Perder el control de la distribución de los bienes adquiridos. | G48: Moderado | H48: Operativo | I48: =IFERROR(VLOOKUP(H48,Naturaleza,2,FALSE)*VLOOKUP('Matriz Riesgo y Op'!D48,Probabilidad,2,FALSE)*VLOOKUP('Matriz Riesgo y Op'!G48,Impacto,2,FALSE),"") -> 70 | J48: =IF(A48="Riesgo",IF(I48="","",IF(AND(I48>0,I48<200),"Trivial",IF(OR(I48=200,AND(I48>200,I48<400)),"Tolerable",IF(OR(I48=400,AND(I48>400,I48<600)),"Moderado",IF(OR(I48=600,AND(I48>600,I48<800)),"Importante",IF(OR(I48=800,I48>800,I48<1000,I48=1000),"Intolerable","")))))),IF(A48="Oportunidad",IF(I48="","",IF(AND(I48>0,I48<250),"Limitada",IF(OR(I48=250,AND(I48>250,I48<500)),"Media",IF(OR(I48=500,AND(I48>500,I48<750)),"Potencial",IF(OR(I48=750,AND(I48>750,I48<=1000)),"Sobresaliente",""))))),"")) -> Trivial | K48: =IFERROR(VLOOKUP(J48,'Parámetros de riesgo'!$B$27:$C$31,2,FALSE),IFERROR(VLOOKUP(J48,'Parámetros de riesgo'!$H$27:$I$30,2,FALSE),"")) -> VIGILARLO | L48: =IFERROR(VLOOKUP(K48,'Parámetros de riesgo'!$C$27:$D$31,2,FALSE),IFERROR(VLOOKUP(K48,'Parámetros de riesgo'!$I$27:$J$30,2,FALSE),"")) -> Control rutinario, no afecta la secuencia e integridad del proceso y/o Partes Interesadas. Documentar las acciones de respuesta en la Evaluación de Efectividad de riesgos y oportunidades. | M48: Confirmar que se lleve a cabo el control sobre las salidas de bienes del almacén del Sistema Integral para la Gestión Administrativa (SIGA). | N48: Vocales Secretarios Distritales/ Enlaces Administrativos
A54: ATENCIÓN A OPORTUNIDADES
A55: IDENTIFICACIÓN | I55: EVALUACIÓN | L55: SEGUMIENTO
A56: CLASIFICACIÓN RIESGO / OPORTUNIDAD | B56: ACTIVIDAD DEL PROCESO | C56: ¿CUÁL ES LA OPORTUNIDAD Y/O MEJORA EN LA ACTIVIDAD? | D56: PROBABILIDAD DE MEJORA | E56: ¿QUÉ ORIGINARÍA LA OPORTUNIDAD? | F56: BENEFICIOS | G56: IMPACTO DE LA MEJORA | H56: ENTORNO DE LA MEJORA | I56: NIVEL DE RIESGO / OPORTUNIDAD | J56: CLASIFICACIÓN | K56: DICTAMEN | L56: CONCLUSIONES | M56: ACCIONES DE RESPUESTA | N56: RESPONSABLE
A57: Oportunidad | B57: Especificaciones técnicas del bien o servicio solicitado (si aplica) | C57: Detallar de manera más precisa las características técnicas del bien, con la mayor parte de datos e incluso presentar una muestra tangible por un proveedor específico | D57: Alta | E57: * Evitar la entrega de un bien que no cumpla con las características técnicas solicitadas. | F57: * Facilitar la adquisición del bien o servicio. * La distribución efectiva del bien o servicio sin consecuencias de devolución. | G57: Moderado | H57: Operativo | I57: =IFERROR(VLOOKUP(H57,Naturaleza,2,FALSE)*VLOOKUP('Matriz Riesgo y Op'!D57,Probabilidad,2,FALSE)*VLOOKUP('Matriz Riesgo y Op'!G57,Impacto,2,FALSE),"") -> 700 | J57: =IF(A57="Riesgo",IF(I57="","",IF(AND(I57>0,I57<200),"Trivial",IF(OR(I57=200,AND(I57>200,I57<400)),"Tolerable",IF(OR(I57=400,AND(I57>400,I57<600)),"Moderado",IF(OR(I57=600,AND(I57>600,I57<800)),"Importante",IF(OR(I57=800,I57>800,I57<1000,I57=1000),"Intolerable","")))))),IF(A57="Oportunidad",IF(I57="","",IF(AND(I57>0,I57<250),"Limitada",IF(OR(I57=250,AND(I57>250,I57<500)),"Media",IF(OR(I57=500,AND(I57>500,I57<750)),"Potencial",IF(OR(I57=750,AND(I57>750,I57<=1000)),"Sobresaliente",""))))),"")) -> Potencial | K57: =IFERROR(VLOOKUP(J57,'Parámetros de riesgo'!$B$27:$C$31,2,FALSE),IFERROR(VLOOKUP(J57,'Parámetros de riesgo'!$H$27:$I$30,2,FALSE),"")) -> APROPIARSE | L57: =IFERROR(VLOOKUP(K57,'Parámetros de riesgo'!$C$27:$D$31,2,FALSE),IFERROR(VLOOKUP(K57,'Parámetros de riesgo'!$I$27:$J$30,2,FALSE),"")) -> Oportunidad con beneficios claros y específicos en el proceso de una o varias áreas y/o Partes Interesadas, de la cual se espera un resultado a corto y mediano plazo. Documentar las acciones de respuesta en la Evaluación de Efectividad de riesgos y oportunidades. | M57: Asegurar que el requerimiento sea solicitado a través del formato de "Requisición del bien y servicio". | N57: Vocales Secretarios Distritales/ Enlaces Administrativos
M58: Asegurar que el área requirente conozca el beneficio de tener una muestra del bien, en los casos que sea posible (por los tiempos y posibilidades del Proveedor), en el momento que entrega la "Requisición del bien y servicio". | N58: Vocales Secretarios Distritales/ Enlaces Administrativos
A62: Oportunidad | B62: Revisión de la requisición o solicitud del área requirente | C62: Asegurar que la información requisitada sea correcta | D62: Alta | E62: * Correcta descripción de las características del bien o servicio. | F62: * Contar con "Requisiciones del bien y servicio", con información adecuada y suficiente para la realizar la compra del bien o servicio en tiempo y forma. | G62: Moderado | H62: Operativo | I62: =IFERROR(VLOOKUP(H62,Naturaleza,2,FALSE)*VLOOKUP('Matriz Riesgo y Op'!D62,Probabilidad,2,FALSE)*VLOOKUP('Matriz Riesgo y Op'!G62,Impacto,2,FALSE),"") -> 700 | J62: =IF(A62="Riesgo",IF(I62="","",IF(AND(I62>0,I62<200),"Trivial",IF(OR(I62=200,AND(I62>200,I62<400)),"Tolerable",IF(OR(I62=400,AND(I62>400,I62<600)),"Moderado",IF(OR(I62=600,AND(I62>600,I62<800)),"Importante",IF(OR(I62=800,I62>800,I62<1000,I62=1000),"Intolerable","")))))),IF(A62="Oportunidad",IF(I62="","",IF(AND(I62>0,I62<250),"Limitada",IF(OR(I62=250,AND(I62>250,I62<500)),"Media",IF(OR(I62=500,AND(I62>500,I62<750)),"Potencial",IF(OR(I62=750,AND(I62>750,I62<=1000)),"Sobresaliente",""))))),"")) -> Potencial | K62: =IFERROR(VLOOKUP(J62,'Parámetros de riesgo'!$B$27:$C$31,2,FALSE),IFERROR(VLOOKUP(J62,'Parámetros de riesgo'!$H$27:$I$30,2,FALSE),"")) -> APROPIARSE | L62: =IFERROR(VLOOKUP(K62,'Parámetros de riesgo'!$C$27:$D$31,2,FALSE),IFERROR(VLOOKUP(K62,'Parámetros de riesgo'!$I$27:$J$30,2,FALSE),"")) -> Oportunidad con beneficios claros y específicos en el proceso de una o varias áreas y/o Partes Interesadas, de la cual se espera un resultado a corto y mediano plazo. Documentar las acciones de respuesta en la Evaluación de Efectividad de riesgos y oportunidades. | M62: Asegurar que la "Requisición del bien y servicio" sea entregada en los tiempos establecidos por la Coordinación Administrativa. | N62: Vocales Secretarios Distritales/ Enlaces Administrativos
M63: Asegurar que el requerimiento sea solicitado a través del formato de "Requisición del bien y servicio". | N63: Vocales Secretarios Distritales/ Enlaces Administrativos
A67: Oportunidad | B67: Identificación de partida y presupuesto autorizado | C67: Monitorear y comparar con carpeta financiera la ministración de recursos en bancos, para de manera inmediata realizar el proceso de compra | D67: Baja | E67: * Asegurarse de contar con los recursos disponibles en las estructuras programáticas etiquetadas para la compra del bien. | F67: * Permitir ir gestionando de manera anticipada la compra con el proveedor, solicitando el envío de información financiera para la gestión del pago en tiempo y forma. | G67: Leve | H67: Operativo | I67: =IFERROR(VLOOKUP(H67,Naturaleza,2,FALSE)*VLOOKUP('Matriz Riesgo y Op'!D67,Probabilidad,2,FALSE)*VLOOKUP('Matriz Riesgo y Op'!G67,Impacto,2,FALSE),"") -> 10 | J67: =IF(A67="Riesgo",IF(I67="","",IF(AND(I67>0,I67<200),"Trivial",IF(OR(I67=200,AND(I67>200,I67<400)),"Tolerable",IF(OR(I67=400,AND(I67>400,I67<600)),"Moderado",IF(OR(I67=600,AND(I67>600,I67<800)),"Importante",IF(OR(I67=800,I67>800,I67<1000,I67=1000),"Intolerable","")))))),IF(A67="Oportunidad",IF(I67="","",IF(AND(I67>0,I67<250),"Limitada",IF(OR(I67=250,AND(I67>250,I67<500)),"Media",IF(OR(I67=500,AND(I67>500,I67<750)),"Potencial",IF(OR(I67=750,AND(I67>750,I67<=1000)),"Sobresaliente",""))))),"")) -> Limitada | K67: =IFERROR(VLOOKUP(J67,'Parámetros de riesgo'!$B$27:$C$31,2,FALSE),IFERROR(VLOOKUP(J67,'Parámetros de riesgo'!$H$27:$I$30,2,FALSE),"")) -> A CONSIDERAR | L67: =IFERROR(VLOOKUP(K67,'Parámetros de riesgo'!$C$27:$D$31,2,FALSE),IFERROR(VLOOKUP(K67,'Parámetros de riesgo'!$I$27:$J$30,2,FALSE),"")) -> Oportunidad que genera un beneficio mínimo en el proceso y/o Partes Interesadas de la cual se espera un resultado inmediato. Documentar las acciones de respuesta en la Evaluación de Efectividad de riesgos y oportunidades. | M67: Seguimiento a la disposición de recursos de la carpeta financiera con el fin de asegurar que se realiza la compra en los tiempos establecidos. | N67: Vocales Secretarios Distritales/ Enlaces Administrativos
A72: Oportunidad | B72: Investigación de Mercado (cuadro comparativo) | C72: Privilegiar el acudir en sitio con el proveedor a solicitar las cotizaciones correspondientes del bien a adquirir | D72: Media | E72: * Presentar de manera tangible con el proveedor, en su caso, las características del bien. | F72: * Precisar y aclarar dudas con el proveedor, para que el bien a adquirir cumpla con las características solicitadas y de esa manera ampliar la cartera de proveedores que pueden satisfacer las necesidades institucionales. | G72: Moderado | H72: Operativo | I72: =IFERROR(VLOOKUP(H72,Naturaleza,2,FALSE)*VLOOKUP('Matriz Riesgo y Op'!D72,Probabilidad,2,FALSE)*VLOOKUP('Matriz Riesgo y Op'!G72,Impacto,2,FALSE),"") -> 490 | J72: =IF(A72="Riesgo",IF(I72="","",IF(AND(I72>0,I72<200),"Trivial",IF(OR(I72=200,AND(I72>200,I72<400)),"Tolerable",IF(OR(I72=400,AND(I72>400,I72<600)),"Moderado",IF(OR(I72=600,AND(I72>600,I72<800)),"Importante",IF(OR(I72=800,I72>800,I72<1000,I72=1000),"Intolerable","")))))),IF(A72="Oportunidad",IF(I72="","",IF(AND(I72>0,I72<250),"Limitada",IF(OR(I72=250,AND(I72>250,I72<500)),"Media",IF(OR(I72=500,AND(I72>500,I72<750)),"Potencial",IF(OR(I72=750,AND(I72>750,I72<=1000)),"Sobresaliente",""))))),"")) -> Media | K72: =IFERROR(VLOOKUP(J72,'Parámetros de riesgo'!$B$27:$C$31,2,FALSE),IFERROR(VLOOKUP(J72,'Parámetros de riesgo'!$H$27:$I$30,2,FALSE),"")) -> ABORDAR | L72: =IFERROR(VLOOKUP(K72,'Parámetros de riesgo'!$C$27:$D$31,2,FALSE),IFERROR(VLOOKUP(K72,'Parámetros de riesgo'!$I$27:$J$30,2,FALSE),"")) -> Oportunidad con buena posibilidad de abordarse siempre y cuando se profundice en los beneficios esperados en el proceso de una o varias áreas y/o Partes Interesadas de la cual se espera un resultado a corto plazo. Documentar las acciones de respuesta en la Evaluación de Efectividad de riesgos y oportunidades. | M72: Entregar al comprador las cotizaciones que cumplen con lo requerido. | N72: Vocales Secretarios Distritales/ Enlaces Administrativos
A77: Oportunidad | B77: Cotizaciones (cuadro comparativo) | C77: Contar con un catalogo de proveedores diferenciado por bien o servicio para la adquisición de manera eficaz | D77: Media | E77: * Mejores condiciones técnicas y económicas para una mejor decisión ante el Subcomité de Adquisiciones. | F77: * Lograr las mejores condiciones de compra para el Instituto. | G77: Importante | H77: Operativo | I77: =IFERROR(VLOOKUP(H77,Naturaleza,2,FALSE)*VLOOKUP('Matriz Riesgo y Op'!D77,Probabilidad,2,FALSE)*VLOOKUP('Matriz Riesgo y Op'!G77,Impacto,2,FALSE),"") -> 700 | J77: =IF(A77="Riesgo",IF(I77="","",IF(AND(I77>0,I77<200),"Trivial",IF(OR(I77=200,AND(I77>200,I77<400)),"Tolerable",IF(OR(I77=400,AND(I77>400,I77<600)),"Moderado",IF(OR(I77=600,AND(I77>600,I77<800)),"Importante",IF(OR(I77=800,I77>800,I77<1000,I77=1000),"Intolerable","")))))),IF(A77="Oportunidad",IF(I77="","",IF(AND(I77>0,I77<250),"Limitada",IF(OR(I77=250,AND(I77>250,I77<500)),"Media",IF(OR(I77=500,AND(I77>500,I77<750)),"Potencial",IF(OR(I77=750,AND(I77>750,I77<=1000)),"Sobresaliente",""))))),"")) -> Potencial | K77: =IFERROR(VLOOKUP(J77,'Parámetros de riesgo'!$B$27:$C$31,2,FALSE),IFERROR(VLOOKUP(J77,'Parámetros de riesgo'!$H$27:$I$30,2,FALSE),"")) -> APROPIARSE | L77: =IFERROR(VLOOKUP(K77,'Parámetros de riesgo'!$C$27:$D$31,2,FALSE),IFERROR(VLOOKUP(K77,'Parámetros de riesgo'!$I$27:$J$30,2,FALSE),"")) -> Oportunidad con beneficios claros y específicos en el proceso de una o varias áreas y/o Partes Interesadas, de la cual se espera un resultado a corto y mediano plazo. Documentar las acciones de respuesta en la Evaluación de Efectividad de riesgos y oportunidades. | M77: Garantizar el llenado del cuadro comparativo, a fin de concentrar toda la información necesaria para facilitar su autorización. | N77: Vocales Secretarios Distritales/ Enlaces Administrativos
M78: Elaborar el Catálogo de proveedores. | N78: Vocales Secretarios Distritales/ Enlaces Administrativos
A82: Oportunidad | B82: Definición del tipo de adquisición – contrato / Pedido-Contrato | C82: Generar el expediente del bien a adquirir conforme a los montos de autorizados, detallando la normatividad aplicable que permita clasificar las compras | D82: Media | E82: * No se omita ningún documento y la normativa que ampare la compra. | F82: * La correcta definición del tipo de adquisición. | G82: Moderado | H82: Operativo | I82: =IFERROR(VLOOKUP(H82,Naturaleza,2,FALSE)*VLOOKUP('Matriz Riesgo y Op'!D82,Probabilidad,2,FALSE)*VLOOKUP('Matriz Riesgo y Op'!G82,Impacto,2,FALSE),"") -> 490 | J82: =IF(A82="Riesgo",IF(I82="","",IF(AND(I82>0,I82<200),"Trivial",IF(OR(I82=200,AND(I82>200,I82<400)),"Tolerable",IF(OR(I82=400,AND(I82>400,I82<600)),"Moderado",IF(OR(I82=600,AND(I82>600,I82<800)),"Importante",IF(OR(I82=800,I82>800,I82<1000,I82=1000),"Intolerable","")))))),IF(A82="Oportunidad",IF(I82="","",IF(AND(I82>0,I82<250),"Limitada",IF(OR(I82=250,AND(I82>250,I82<500)),"Media",IF(OR(I82=500,AND(I82>500,I82<750)),"Potencial",IF(OR(I82=750,AND(I82>750,I82<=1000)),"Sobresaliente",""))))),"")) -> Media | K82: =IFERROR(VLOOKUP(J82,'Parámetros de riesgo'!$B$27:$C$31,2,FALSE),IFERROR(VLOOKUP(J82,'Parámetros de riesgo'!$H$27:$I$30,2,FALSE),"")) -> ABORDAR | L82: =IFERROR(VLOOKUP(K82,'Parámetros de riesgo'!$C$27:$D$31,2,FALSE),IFERROR(VLOOKUP(K82,'Parámetros de riesgo'!$I$27:$J$30,2,FALSE),"")) -> Oportunidad con buena posibilidad de abordarse siempre y cuando se profundice en los beneficios esperados en el proceso de una o varias áreas y/o Partes Interesadas de la cual se espera un resultado a corto plazo. Documentar las acciones de respuesta en la Evaluación de Efectividad de riesgos y oportunidades. | M82: Asegurar que el tipo de adjudicación es la correcta a través de una revisión documental. | N82: Vocales Secretarios Distritales/ Enlaces Administrativos
A87: Oportunidad | B87: Autorización del Subcomité de Adquisiciones, Arrendamientos y Servicios | C87: Presentar la solicitud del bien o servicio con toda la documentación necesaria para su autorización | D87: Media | E87: * Tener un panorama más amplio de las propuestas mas viables y claras de las compras, para su aprobación sin observaciones por el Subcomité de Adquisiciones. | F87: * Aprobación de la compra sin observaciones y limitaciones del bien por parte del Subcomité de Adquisiciones. | G87: Moderado | H87: Operativo | I87: =IFERROR(VLOOKUP(H87,Naturaleza,2,FALSE)*VLOOKUP('Matriz Riesgo y Op'!D87,Probabilidad,2,FALSE)*VLOOKUP('Matriz Riesgo y Op'!G87,Impacto,2,FALSE),"") -> 490 | J87: =IF(A87="Riesgo",IF(I87="","",IF(AND(I87>0,I87<200),"Trivial",IF(OR(I87=200,AND(I87>200,I87<400)),"Tolerable",IF(OR(I87=400,AND(I87>400,I87<600)),"Moderado",IF(OR(I87=600,AND(I87>600,I87<800)),"Importante",IF(OR(I87=800,I87>800,I87<1000,I87=1000),"Intolerable","")))))),IF(A87="Oportunidad",IF(I87="","",IF(AND(I87>0,I87<250),"Limitada",IF(OR(I87=250,AND(I87>250,I87<500)),"Media",IF(OR(I87=500,AND(I87>500,I87<750)),"Potencial",IF(OR(I87=750,AND(I87>750,I87<=1000)),"Sobresaliente",""))))),"")) -> Media | K87: =IFERROR(VLOOKUP(J87,'Parámetros de riesgo'!$B$27:$C$31,2,FALSE),IFERROR(VLOOKUP(J87,'Parámetros de riesgo'!$H$27:$I$30,2,FALSE),"")) -> ABORDAR | L87: =IFERROR(VLOOKUP(K87,'Parámetros de riesgo'!$C$27:$D$31,2,FALSE),IFERROR(VLOOKUP(K87,'Parámetros de riesgo'!$I$27:$J$30,2,FALSE),"")) -> Oportunidad con buena posibilidad de abordarse siempre y cuando se profundice en los beneficios esperados en el proceso de una o varias áreas y/o Partes Interesadas de la cual se espera un resultado a corto plazo. Documentar las acciones de respuesta en la Evaluación de Efectividad de riesgos y oportunidades. | M87: Garantizar que la "Requisición del bien y servicio", se presenta con toda la información adicional establecida para su autorización. | N87: Vocales Secretarios Distritales/ Enlaces Administrativos
A92: Oportunidad | B92: Se adjudica al Proveedor la Adquisición del bien o servicio | C92: Contactar al Proveedor para reconfirmar la adjudicación | D92: Media | E92: * Confirmar que el bien o servicio sea entregado. | F92: * Agilizar la entrega del bien o servicio. * Cumplir con la satisfacción del usuario en el uso del bien o servicio. | G92: Moderado | H92: Operativo | I92: =IFERROR(VLOOKUP(H92,Naturaleza,2,FALSE)*VLOOKUP('Matriz Riesgo y Op'!D92,Probabilidad,2,FALSE)*VLOOKUP('Matriz Riesgo y Op'!G92,Impacto,2,FALSE),"") -> 490 | J92: =IF(A92="Riesgo",IF(I92="","",IF(AND(I92>0,I92<200),"Trivial",IF(OR(I92=200,AND(I92>200,I92<400)),"Tolerable",IF(OR(I92=400,AND(I92>400,I92<600)),"Moderado",IF(OR(I92=600,AND(I92>600,I92<800)),"Importante",IF(OR(I92=800,I92>800,I92<1000,I92=1000),"Intolerable","")))))),IF(A92="Oportunidad",IF(I92="","",IF(AND(I92>0,I92<250),"Limitada",IF(OR(I92=250,AND(I92>250,I92<500)),"Media",IF(OR(I92=500,AND(I92>500,I92<750)),"Potencial",IF(OR(I92=750,AND(I92>750,I92<=1000)),"Sobresaliente",""))))),"")) -> Media | K92: =IFERROR(VLOOKUP(J92,'Parámetros de riesgo'!$B$27:$C$31,2,FALSE),IFERROR(VLOOKUP(J92,'Parámetros de riesgo'!$H$27:$I$30,2,FALSE),"")) -> ABORDAR | L92: =IFERROR(VLOOKUP(K92,'Parámetros de riesgo'!$C$27:$D$31,2,FALSE),IFERROR(VLOOKUP(K92,'Parámetros de riesgo'!$I$27:$J$30,2,FALSE),"")) -> Oportunidad con buena posibilidad de abordarse siempre y cuando se profundice en los beneficios esperados en el proceso de una o varias áreas y/o Partes Interesadas de la cual se espera un resultado a corto plazo. Documentar las acciones de respuesta en la Evaluación de Efectividad de riesgos y oportunidades. | M92: Asegurar contactar (vía telefónica o visita en sus instalaciones) para reconfirmar al Proveedor fue adjudicado. | N92: Vocales Secretarios Distritales/ Enlaces Administrativos
A97: Oportunidad | B97: Recepción y Salida de Almacén | C97: Optimizar el control de entradas y salidas dentro del almacén Institucional | D97: Alta | E97: * Contar con un registro eficaz y comprobación del ejercicio del presupuesto. | F97: * Optimizar el control del almacén y por ende el ejercicio adecuado de los recursos. | G97: Importante | H97: Operativo | I97: =IFERROR(VLOOKUP(H97,Naturaleza,2,FALSE)*VLOOKUP('Matriz Riesgo y Op'!D97,Probabilidad,2,FALSE)*VLOOKUP('Matriz Riesgo y Op'!G97,Impacto,2,FALSE),"") -> 1000 | J97: =IF(A97="Riesgo",IF(I97="","",IF(AND(I97>0,I97<200),"Trivial",IF(OR(I97=200,AND(I97>200,I97<400)),"Tolerable",IF(OR(I97=400,AND(I97>400,I97<600)),"Moderado",IF(OR(I97=600,AND(I97>600,I97<800)),"Importante",IF(OR(I97=800,I97>800,I97<1000,I97=1000),"Intolerable","")))))),IF(A97="Oportunidad",IF(I97="","",IF(AND(I97>0,I97<250),"Limitada",IF(OR(I97=250,AND(I97>250,I97<500)),"Media",IF(OR(I97=500,AND(I97>500,I97<750)),"Potencial",IF(OR(I97=750,AND(I97>750,I97<=1000)),"Sobresaliente",""))))),"")) -> Sobresaliente | K97: =IFERROR(VLOOKUP(J97,'Parámetros de riesgo'!$B$27:$C$31,2,FALSE),IFERROR(VLOOKUP(J97,'Parámetros de riesgo'!$H$27:$I$30,2,FALSE),"")) -> EXPLOTARLA | L97: =IFERROR(VLOOKUP(K97,'Parámetros de riesgo'!$C$27:$D$31,2,FALSE),IFERROR(VLOOKUP(K97,'Parámetros de riesgo'!$I$27:$J$30,2,FALSE),"")) -> Oportunidad con beneficios claros, generales y específicos en el proceso de varias o todas las áreas y/o Partes Interesadas de la cual se obtiene un resultado a corto, mediano y/o largo plazo. Documentar las acciones de respuesta en la Evaluación de Efectividad de riesgos y oportunidades. | M97: Asegurar la correcta salida del almacén del bien solicitado en el Sistema Integral para la Gestión Administrativa (SIGA). | N97: Vocales Secretarios Distritales/ Enlaces Administrativos

Sheet Parámetros de riesgo
D1: INSTITUTO NACIONAL ELECTORAL JLE PUEBLA SISTEMA DE GESTIÓN DE LA CALIDAD | K1: Versión: 0
D2: PARÁMETROS DE RIESGOS | K2: Fecha de emisión: 06/03/2020
A4: RIESGOS | G4: OPORTUNIDADES
A5: NATURALEZA | B5: DEFINICIONES | G5: NATURALEZA | H5: DEFINICIONES
A6: Operativa | B6: Riesgo cuyos efectos están relacionados con la nula o mala prestación del servicio y/o entrega de la credencial para votar durante la operación y a la entrega a la Ciudadanía. Puede incluir maquinaria, equipo, infraestructura, Recurso Humano, Insumos, servicios de apoyo (agua potable, electricidad, redes, internet, Sistema SIIRFE-MAC) y Partes Interesadas. | G6: Operativa | H6: Oportunidad cuyos efectos están relacionados con la prestación del servicio y/o entrega de la credencial para votar durante la operación y a la entrega a la Ciudadanía de forma eficiente. Puede incluir maquinaria, equipo, infraestructura, Recurso Humano, Insumos, servicios de apoyo (agua potable, electricidad, redes, internet, Sistema SIIRFE-MAC, etc.) y Partes Interesadas.
A7: Ambiental | B7: Cualquier riesgo cuyo efecto negativo está relacionado con la salud física, medio ambiente y seguridad laboral de cualquier Parte Interesada (interna o externa), así como el ambiente laboral de los funcionarios dentro de los MAC´s. | G7: Ambiental | H7: Oportunidad cuyo efecto está relacionado con mantener e incrementar los beneficios en la salud física, medio ambiente y seguridad laboral de cualquier Parte Interesada (interna y externa), así como el ambiente laboral de los Funcionarios dentro de los MAC´s.
A8: Legal y Reglamentario | B8: Riesgo cuyos efectos están relacionados con los cambios de las normatividades legales y reglamentarias aplicables al instituto en el ámbito federal, local y del ramo que no permitan acceder, mantener o mejorar las relaciones con las Partes Interesadas y esto afecte a la operación y a la entrega de la credencial para votar y/o trámite a la Ciudadanía. | G8: Legal y Reglamentario | H8: Oportunidad cuyos efectos están relacionados con el aprovechamiento de los cambios en las normatividades legales y reglamentarias aplicables en el Instituto en el ámbito federal, local y del ramo que permitan mantener y mejorar las relaciones con las Partes Interesadas durante la operación y a la entrega de la credencial para votar y/o trámite a la Ciudadanía.
A9: Política | B9: Riesgo cuyos efectos están relacionados con la probabilidad de que las fuerzas políticas generen cambios negativos en el entorno Institucional y obstaculicen o minimicen relaciones con Partes Interesadas. | G9: Política | H9: Oportunidad cuyos efectos están relacionados con la probabilidad de que las fuerzas políticas generen cambios positivos en el entorno Institucional y apoyen a mejorar las relaciones con las Partes Interesadas.
A10: Industrial | B10: Riesgo cuyos efectos están relacionados con Partes Interesadas que generan una desventaja frente a la competencia en el mismo ramo, zona geográfica, Ciudad, Estado y/o País en la prestación del producto / servicio brindado a la Ciudadanía. | G10: Industrial | H10: Oportunidad cuyos efectos están relacionados con Partes Interesadas que generan una ventaja competitiva en el mismo ramo, zona geográfica, Ciudad, Estado y/o País en la prestación del producto / servicio brindado a la Ciudadanía.
A11: Institucional | B11: Riesgo cuyos efectos están relacionados con cambios en la planeación y ejecución estratégica del INE, DOS, DERFE, que provocan limitantes tangibles e intangibles en los resultados de los MAC´s. | G11: Institucional | H11: Oportunidad cuyos efectos están relacionados con cambios en la planeación y ejecución estratégica del INE, DERFE, DOS, que provocan beneficios tangibles e intangibles en los resultados de los MAC´s.
A12: Social/Cultural | B12: Riesgo en los integrantes del mercado y su influencia en el entorno. Variables como la evolución demográfica, Movilidad social, Cambios en el estilo de vida, Actitud consumista, Nivel educativo, Patrones culturales y la Religión. | G12: Social/Cultural | H12: Oportunidad que los integrantes del mercado y su influencia en el entorno sean de beneficio con la evolución demográfica, Movilidad social, Cambios en el estilo de vida, Actitud consumista, Nivel educativo, Patrones culturales y la Religión.
A13: Tecnológicos | B13: Riesgo del desarrollo tecnológico y sus aportes en la actividad Institucional. Depende de su estado la cifra en gasto público en investigación, Preocupación gubernamental y de industria por la tecnología, Grado de obsolescencia, Madurez de las tecnologías convencionales, Desarrollo de nuevos productos, Velocidad de transmisión de la tecnología | G13: Tecnológicos | H13: Oportunidad en el desarrollo tecnológico y sus aportes en la actividad de los MAC´s, Madurez de las tecnologías convencionales, Desarrollo de nuevos productos, Velocidad de transmisión de la tecnología.
A14: Económico / Financiero | B14: Riesgo cuyos efectos están relacionados con limitar o detener la sostenibilidad financiera de los MAC´s las cuales pueden ser generadas en conjunto por una o varias de las Partes Interesadas. | G14: Económico / Financiero | H14: Oportunidad cuyos efectos están relacionados con mantener e incrementar la sostenibilidad financiera del Instituto, las cuales pueden ser generadas en conjunto por una o unas de las Partes Interesadas.
A16: PROBABILIDAD | B16: DEFINICIONES | G16: PROBABILIDAD | H16: DEFINICIONES
A17: Baja | B17: Remotamente posible. El daño ocurre muy rara vez. | G17: Baja | H17: Remotamente posible. La oportunidad ocurre muy rara vez.
... A24: Grave | B24: Riesgo negativo que afecta gravemente la integridad para otorgar la prestación del servicio determinado por el proceso. Pocas veces puede revertirse en un mediano o largo tiempo y genera costos de no calidad altos y con daños visiblemente permanentes. | G24: Importante | H24: Impacto positivo garantizado que potencializa la integridad para otorgar la prestación del servicio determinado por el proceso. Puede implementarse en un mediano o largo tiempo y genera costos de calidad considerables y posiblemente permanentes.
A26: RANGOS | B26: CLASIFICACIÓN | C26: DICTAMEN | D26: ACCIONES | G26: RANGOS | H26: CLASIFICACIÓN | I26: DICTAMEN | J26: ACCIONES
A27: 0 - 199 | B27: TRIVIAL | C27: VIGILARLO | D27: Control rutinario, no afecta la secuencia e integridad del proceso y/o Partes Interesadas. Documentar las acciones de respuesta en la Evaluación de Efectividad de riesgos y oportunidades. | G27: 0 - 250 | H27: LIMITADA | I27: A CONSIDERAR | J27: Oportunidad que genera un beneficio mínimo en el proceso y/o Partes Interesadas de la cual se espera un resultado inmediato. Documentar las acciones de respuesta en la Evaluación de Efectividad de riesgos y oportunidades.
A28: 200 - 399 | B28: TOLERABLE | C28: ASUMIRLO | D28: Monitorear el riesgo, afecta mínimamente la secuencia y la integridad del proceso. Documentar las acciones de respuesta en la Evaluación de Efectividad de riesgos y oportunidades. | G28: 251 - 500 | H28: MEDIA | I28: ABORDAR | J28: Oportunidad con buena posibilidad de abordarse siempre y cuando se profundice en los beneficios esperados en el proceso de una o varias áreas y/o Partes Interesadas de la cual se espera un resultado a corto plazo. Documentar las acciones de respuesta en la Evaluación de Efectividad de riesgos y oportunidades.
A29: 400 - 599 | B29: MODERADO | C29: CONTROLARLO | D29: Documentar las acciones de respuesta en la Evaluación de Efectividad de riesgos y oportunidades e incluir controles permanentes ya que existe un riesgo moderado en la secuencia y la integridad del proceso y/o Partes Interesadas. | G29: 501 - 750 | H29: POTENCIAL | I29: APROPIARSE | J29: Oportunidad con beneficios claros y específicos en el proceso de una o varias áreas y/o Partes Interesadas, de la cual se espera un resultado a corto y mediano plazo. Documentar las acciones de respuesta en la Evaluación de Efectividad de riesgos y oportunidades.
A30: 600 - 799 | B30: IMPORTANTE | C30: MINIMIZARLO | D30: Acción de contención inmediata, es importante generar una Cédula de no Conformidad eficaz y eficiente donde se realice un control específico y permanente ya que el riesgo es alto en la secuencia y la integridad del proceso y/o Partes interesadas. | G30: 751 - 1000 | H30: SOBRESALIENTE | I30: EXPLOTARLA | J30: Oportunidad con beneficios claros, generales y específicos en el proceso de varias o todas las áreas y/o Partes Interesadas de la cual se obtiene un resultado a corto, mediano y/o largo plazo. Documentar las acciones de respuesta en la Evaluación de Efectividad de riesgos y oportunidades.
A31: 800 - 1000 | B31: INTOLERABLE | C31: ATENCIÓN INMEDIATA | D31: Acción de contención inmediata, es urgente generar una Cédula de no Conformidad y revisión del proceso (aplicar reingeniería si es necesario) eficaz y eficiente donde se realice un control específico y permanente ya que el riesgo es grave en la secuencia y la integridad del proceso y/o Partes interesadas.

Sheet Ponderación
A1: Entorno | D1: Probabilidad | G1: Impacto
A2: Político | B2: 5 | D2: Baja | E2: 1 | G2: Leve | H2: 1
A3: Industrial | B3: 5 | D3: Media | E3: 7 | G3: Moderado | H3: 7
A4: Operativo | B4: 10 | D4: Alta | E4: 10 | G4: Grave | H4: 10
A5: Institucional | B5: 8 | G5: Importante | H5: 10
A6: Financiera | B6: 7
A7: Ambiental | B7: 8
A8: Legal y Reglamentario | B8: 9
A9: Salud | B9: 10
A10: Social/Cultural | B10: 6
A11: Tecnológicos | B11: 6

Sheet E de efectividad Ri
C1: INSTITUTO NACIONAL ELECTORAL JLE PUEBLA SISTEMA DE GESTIÓN DE LA CALIDAD | G1: Versión: 0
C2: EVALUACIÓN DE LA EFECTIVIDAD DE LOS RIESGOS | G2: Fecha de emisión: 06/03/2020
A4: Fecha: | C4: Proceso: | F4: Responsable:
A5: Referencia documental:
A7: Acciones de Respuesta | B7: Riesgo | C7: Criterio de evaluación | G7: Evidencia de soporte | H7: Observaciones
C8: 1 | D8: 2 | E8: 3 | F8: 4
A9: ='Matriz Riesgo y Op'!M8 -> Garantizar que la información indicada en la "Requisición del bien y servicio" este completa y correcta. | B9: ='Matriz Riesgo y Op'!C8 -> Proveer un bien o servicio no adecuado
A10: ='Matriz Riesgo y Op'!M9 -> 0
A11: ='Matriz Riesgo y Op'!M10 -> 0
A12: ='Matriz Riesgo y Op'!M11 -> 0
A13: ='Matriz Riesgo y Op'!M12 -> 0
A14: ='Matriz Riesgo y Op'!M13 -> Garantizar que la información indicada en la "Requisición del bien y servicio" este completa y correcta. | B14: ='Matriz Riesgo y Op'!C13 -> Que el bien solicitado no sea el adecuado
A15: ='Matriz Riesgo y Op'!M14 -> 0
A16: ='Matriz Riesgo y Op'!M15 -> 0
A17: ='Matriz Riesgo y Op'!M16 -> 0
A18: ='Matriz Riesgo y Op'!M17 -> 0
A19: ='Matriz Riesgo y Op'!M18 -> Monitorear la ministración de recursos cada vez que llega una "Requisición del bien y servicio". | B19: ='Matriz Riesgo y Op'!C18 -> No contar con suficiencia presupuestal en las partidas o que el presupuesto del bien o servicio se encuentre en otra partida
A20: ='Matriz Riesgo y Op'!M19 -> 0
A21: ='Matriz Riesgo y Op'!M20 -> 0
A22: ='Matriz Riesgo y Op'!M21 -> 0
A23: ='Matriz Riesgo y Op'!M22 -> 0
A24: ='Matriz Riesgo y Op'!M23 -> Ampliar el Catálogo de Proveedores para facilitar el estudio de Mercado. | B24: ='Matriz Riesgo y Op'!C23 -> Que no se cuente con los presupuestos respecto a las especificaciones solicitadas del bien o servicio
A25: ='Matriz Riesgo y Op'!M24 -> 0
A26: ='Matriz Riesgo y Op'!M25 -> 0
A27: ='Matriz Riesgo y Op'!M26 -> 0
A28: ='Matriz Riesgo y Op'!M27 -> 0
A29: ='Matriz Riesgo y Op'!M28 -> Garantizar la elaboración del cuadro comparativo. | B29: ='Matriz Riesgo y Op'!C28 -> No contar con un documento en el que se concentren las mejores propuestas de proveedores para el Instituto
A30: ='Matriz Riesgo y Op'!M29 -> 0
A31: ='Matriz Riesgo y Op'!M30 -> 0
A32: ='Matriz Riesgo y Op'!M31 -> 0
A33: ='Matriz Riesgo y Op'!M32 -> 0
A34: ='Matriz Riesgo y Op'!M33 -> Asegurar que se este aplicando la normatividad vigente para la determinación del tipo de adquisición. | B34: ='Matriz Riesgo y Op'!C33 -> Definir el tipo de contrato incorrectamente
A35: ='Matriz Riesgo y Op'!M34 -> 0
A36: ='Matriz Riesgo y Op'!M35 -> 0
A37: ='Matriz Riesgo y Op'!M36 -> 0
A38: ='Matriz Riesgo y Op'!M37 -> 0
A39: ='Matriz Riesgo y Op'!M38 -> Concentrar la información indicada en la "Requisición del bien y servicio", para el análisis previo a la autorización. | B39: ='Matriz Riesgo y Op'!C38 -> Que no se lleve a cabo la adquisición del bien o servicio en tiempo y forma para atender la solicitud
A40: ='Matriz Riesgo y Op'!M39 -> 0
A41: ='Matriz Riesgo y Op'!M40 -> 0
A42: ='Matriz Riesgo y Op'!M41 -> 0
...

Sheet E de efectividad Op
C1: INSTITUTO NACIONAL ELECTORAL JLE PUEBLA SISTEMA DE GESTIÓN DE LA CALIDAD | G1: Versión: 0
C2: EVALUACIÓN DE LA EFECTIVIDAD DE LOS OPORTUNIDADES | G2: Fecha de emisión: 06/03/2020
A4: Fecha: | C4: Proceso: | F4: Responsable:
A5: Referencia documental:
A7: Acciones de Respuesta | B7: Oportunidad | C7: Criterio de evaluación | G7: Evidencia de soporte | H7: Observaciones
C8: 1 | D8: 2 | E8: 3 | F8: 4
A9: ='Matriz Riesgo y Op'!M57 -> Asegurar que el requerimiento sea solicitado a través del formato de "Requisición del bien y servicio". | B9: ='Matriz Riesgo y Op'!C57 -> Detallar de manera más precisa las características técnicas del bien, con la mayor parte de datos e incluso presentar una muestra tangible por un proveedor específico
A10: ='Matriz Riesgo y Op'!M58 -> Asegurar que el área requirente conozca el beneficio de tener una muestra del bien, en los casos que sea posible (por los tiempos y posibilidades del Proveedor), en el momento que entrega la "Requisición del bien y servicio".
A11: ='Matriz Riesgo y Op'!M59 -> 0
A12: ='Matriz Riesgo y Op'!M60 -> 0
A13: ='Matriz Riesgo y Op'!M61 -> 0
A14: ='Matriz Riesgo y Op'!M62 -> Asegurar que la "Requisición del bien y servicio" sea entregada en los tiempos establecidos por la Coordinación Administrativa. | B14: ='Matriz Riesgo y Op'!C62 -> Asegurar que la información requisitada sea correcta
A15: ='Matriz Riesgo y Op'!M63 -> Asegurar que el requerimiento sea solicitado a través del formato de "Requisición del bien y servicio".
A16: ='Matriz Riesgo y Op'!M64 -> 0
A17: ='Matriz Riesgo y Op'!M65 -> 0
A18: ='Matriz Riesgo y Op'!M66 -> 0
A19: ='Matriz Riesgo y Op'!M67 -> Seguimiento a la disposición de recursos de la carpeta financiera con el fin de asegurar que se realiza la compra en los tiempos establecidos. | B19: ='Matriz Riesgo y Op'!C67 -> Monitorear y comparar con carpeta financiera la ministración de recursos en bancos, para de manera inmediata realizar el proceso de compra
A20: ='Matriz Riesgo y Op'!M68 -> 0
A21: ='Matriz Riesgo y Op'!M69 -> 0
A22: ='Matriz Riesgo y Op'!M70 -> 0
A23: ='Matriz Riesgo y Op'!M71 -> 0
A24: ='Matriz Riesgo y Op'!M72 -> Entregar al comprador las cotizaciones que cumplen con lo requerido. | B24: ='Matriz Riesgo y Op'!C72 -> Privilegiar el acudir en sitio con el proveedor a solicitar las cotizaciones correspondientes del bien a adquirir
A25: ='Matriz Riesgo y Op'!M73 -> 0
A26: ='Matriz Riesgo y Op'!M74 -> 0
A27: ='Matriz Riesgo y Op'!M75 -> 0
A28: ='Matriz Riesgo y Op'!M76 -> 0
A29: ='Matriz Riesgo y Op'!M77 -> Garantizar el llenado del cuadro comparativo, a fin de concentrar toda la información necesaria para facilitar su autorización. | B29: ='Matriz Riesgo y Op'!C77 -> Contar con un catalogo de proveedores diferenciado por bien o servicio para la adquisición de manera eficaz
A30: ='Matriz Riesgo y Op'!M78 -> Elaborar el Catálogo de proveedores.
A31: ='Matriz Riesgo y Op'!M79 -> 0
A32: ='Matriz Riesgo y Op'!M80 -> 0
A33: ='Matriz Riesgo y Op'!M81 -> 0
A34: ='Matriz Riesgo y Op'!M82 -> Asegurar que el tipo de adjudicación es la correcta a través de una revisión documental. | B34: ='Matriz Riesgo y Op'!C82 -> Generar el expediente del bien a adquirir conforme a los montos de autorizados, detallando la normatividad aplicable que permita clasificar las compras
A35: ='Matriz Riesgo y Op'!M83 -> 0
A36: ='Matriz Riesgo y Op'!M84 -> 0
A37: ='Matriz Riesgo y Op'!M85 -> 0
A38: ='Matriz Riesgo y Op'!M86 -> 0
A39: ='Matriz Riesgo y Op'!M87 -> Garantizar que la "Requisición del bien y servicio", se presenta con toda la información adicional establecida para su autorización. | B39: ='Matriz Riesgo y Op'!C87 -> Presentar la solicitud del bien o servicio con toda la documentación necesaria para su autorización
A40: ='Matriz Riesgo y Op'!M88 -> 0
A41: ='Matriz Riesgo y Op'!M89 -> 0
A42: ='Matriz Riesgo y Op'!M90 -> 0
...
