Workbook
Name AMENAZARAS: [1]CÁLCULOS!$B$29:$B$30
Name AMENAZARAS: [1]CÁLCULOS!$B$29:$B$30
Name arriba3d: #REF!
Name arriba3d: #REF!
Name ARRIBA4A: #REF!
Name ARRIBA4A: #REF!
Name ARRIBADOSA: #REF!
Name ARRIBADOSA: #REF!
Name ARRIBADOSABE: #REF!
Name ARRIBADOSABE: #REF!
Name ARRIBADUOSAAA: '[2]1a. Misión, Visión'!#REF!
Name ARRIBADUOSAAA: '[2]1a. Misión, Visión'!#REF!
Name ARRIBAFACTCLAU: #REF!
Name ARRIBAFACTCLAU: #REF!
Name ARRIBAIMPRIMIR: #REF!
Name ARRIBAIMPRIMIR: #REF!
Name BUSCARMES: #REF!
Name BUSCARMES: #REF!
Name DEBILIDAD: #REF!
Name DEBILIDAD: #REF!
Name ESTRATEGIA: #REF!
Name ESTRATEGIA: #REF!
Name EXTERNAS: #REF!
Name EXTERNAS: #REF!
Name FLUJODECAJA: #REF!
Name FLUJODECAJA: #REF!
Name FORTALEZAS: #REF!
Name FORTALEZAS: #REF!
Name GRAFIK2a6: #REF!
Name GRAFIK2a6: #REF!
Name INDICE: [2]INDICE!#REF!
Name INDICE: [2]INDICE!#REF!
Name INFO2a6: #REF!
Name INFO2a6: #REF!
Name INFO2E: #REF!
Name INFO2E: #REF!
Name INFO2F: #REF!
Name INFO2F: #REF!
Name INFO2G: #REF!
Name INFO2G: #REF!
Name INFO3A: #REF!
Name INFO3A: #REF!
Name INFO3B: #REF!
Name INFO3B: #REF!
Name info3ce: #REF!
Name info3ce: #REF!
Name INFO4A: #REF!
Name INFO4A: #REF!
Name INFOADL: #REF!
Name INFOADL: #REF!
Name infoBCG: #REF!
Name infoBCG: #REF!
Name INFODOSA: #REF!
Name INFODOSA: #REF!
Name INFODOSABE: #REF!
Name INFODOSABE: #REF!
Name INFODOSBE: #REF!
Name INFODOSBE: #REF!
Name INFODUOSAAA: '[2]1a. Misión, Visión'!#REF!
Name INFODUOSAAA: '[2]1a. Misión, Visión'!#REF!

Sheet INDICE
C2: INSTITUTO NACIONAL ELECTORAL JLE PUEBLA | K2: Versión: 1
C3: SISTEMA DE GESTIÓN DE LA CALIDAD | K3: Fecha de emisión:
C4: PLAN ESTRATÉGICO | K4: 44279
A9: 1º CONCEPTOS | D9: 2ª ENTORNO | G9: 3ª ANÁLISIS GLOBAL | J9: 4ª ANÁLISIS CONTEXTO
A10: 1a. Misión, Visión y Valores | D10: 2a. Análisis FODA | G10: 3a. Matriz Partes Interesadas | J10: 3b. Matriz-Contexto
A11: 1b. Política de la Calidad y Objetivos de la Calidad | D11: 2b. Matriz Posicionamiento Estratégico
A12: 1c. Alcance del Sistema de Gestión de la Calidad
A16: Denominación (abreviada) | D16: JLE PUEBLA
A18: Período de vigencia del plan | E18: 2021-2022
A20: Segundo ejercicio | E20: 44396
A23: RESPONSABLE | C23: ROL | F23: NOMBRE | I23: FIRMA
A24: Elaboración: | C24: Coordinadores de Calidad | F24: L.A.P. Claudia Cardona Ramírez Ing. Julio César Fernández Hernández C. Jorge Alfonso Olvera Águila
A25: Revisión: | C25: Alta Dirección | F25: Mtro. Carlos Alberto Montero Catalán
A26: Aprobación: | C26: Alta Dirección | F26: Dr. Marcos Rodríguez del Castillo Lic. Marcelo Pineda Pineda C. Lilia Andrea Morales Benavides

Sheet INTRO
D1: INSTITUTO NACIONAL ELECTORAL JLE PUEBLA | L1: Versión: 1
D2: SISTEMA DE GESTIÓN DE LA CALIDAD | L2: Fecha de emisión:
D3: PLAN ESTRATÉGICO | L3: 44279
B5: ¿QUÉ ENTENDEMOS COMO PLAN ESTRATÉGICO?
B6: Entendemos por "Plan Estratégico" aquel que, partiendo de lo que la Institución es hoy o de lo que se quiere ser (si aún no existe), analiza la situación dónde nos encontramos y define dónde, cómo y cuándo llegaremos. Por tanto, siempre es un plan a medio/largo plazo que contiene elementos "filosóficos”, elementos analíticos y elementos operativos sostenidos y confirmados por las consiguientes previsiones económico - financieras.
B10: ESTRUCTURA DE UN "PLAN ESTRATÉGICO"
C12: CONCEPTOS - FILOSOFÍA ← | H12: Misión, Visión, Valores
C13: Elementos conceptuales: Quiénes somos, a dónde queremos llegar.
C15: ANÁLISIS ESTRATÉGICO ← | H15: Entorno y coyuntura
C16: Análisis: Dónde estamos y cuál es el entorno. Situación y factores internos y externos. Posición competitiva. Qué opciones estratégicas tenemos. | H16: Situación interna y externa
H17: Posición competitiva
H18: Modelo de negocio
C19: CONCLUSIONES, OBJETIVOS Y ESTRATEGIA ← | H19: Conclusiones y objetivos
C20: Definición: Qué objetivos, cómo y cuándo los alcanzaremos. Que estrategias aplicaremos. | H20: Objetivos, metas y estrategias

Sheet 1a. Misión, Visión
B1: INSTITUTO NACIONAL ELECTORAL JLE PUEBLA | J1: Versión: 1
B2: SISTEMA DE GESTIÓN DE LA CALIDAD | J2: Fecha de emisión:
B3: PLAN ESTRATÉGICO | J3: 44279
B6: =INDICE!D16 -> JLE PUEBLA | D6: MISIÓN | H6: =INDICE!E18 -> 2021-2022
B8: Organizar procesos electorales libres, equitativos y confiables, para garantizar el ejercicio de los derechos político-electorales de la ciudadanía y contribuir al desarrollo de la vida democrática de México.
B11: =INDICE!D16 -> JLE PUEBLA | D11: VISIÓN | H11: =INDICE!E18 -> 2021-2022
B13: Ser el organismo electoral nacional autónomo que contribuya a la consolidación de la cultura y convivencia democrática en México, distinguiéndose por ser una institución, moderna, transparente y eficiente, en la que la sociedad confíe plenamente para la organización de elecciones equitativas e imparciales.
B16: =INDICE!D16 -> JLE PUEBLA | D16: VALORES ORGANIZACIONALES | H16: =INDICE!E18 -> 2021-2022
B18: Confianza, Tolerancia, Compromiso, Transparencia y Rendición de Cuentas.
B19: =INDICE!D16 -> JLE PUEBLA | D19: PRINCIPIOS RECTORES | H19: =INDICE!E18 -> 2021-2022
B21: Certeza, Legalidad, Independencia, Imparcialidad, Objetividad y Máxima Publicidad.

Sheet 1b. Política y Objetivos
C1: INSTITUTO NACIONAL ELECTORAL JLE PUEBLA | N1: Versión: 1
C2: SISTEMA DE GESTIÓN DE LA CALIDAD | N2: Fecha de emisión:
C4: PLAN ESTRATÉGICO | N4: 44279
B6: POLÍTICA DE LA CALIDAD
B7: En el Instituto Nacional Electoral INE, estamos comprometidos en proporcionar a la ciudadanía un servicio eficiente y de calidad en el trámite de expedición de su credencial para votar, desde la entrevista hasta la entrega de la credencial para votar, para contribuir al derecho a la identidad ciudadana, con base en el marco normativo, reglamentario y en un entorno de mejora continua con apego a los requisitos de la norma ISO 9001:2015.
B10: OBJETIVOS DE LA CALIDAD
B11: 1. Actualizar el Padrón Electoral en la entidad mediante la captación de solicitudes de credencial requeridas por la ciudadanía en los Módulos de Atención Ciudadana instalados. 2. Elevar el porcentaje de utilización de la capacidad en los Módulos de Atención Ciudadana de la Entidad. 3. Brindar el servicio en todos los Módulos de Atención Ciudadana autorizados en el estado, conforme al calendario de operación de Módulos de Atención Ciudadana de la campaña de actualización en turno. 4. Promover la inscripción de jóvenes al Padrón Electoral. 5. Mantener el servicio de atención a domicilio, acorde a lo que establece el artículo 141 de la Ley General de Instituciones y Procedimientos Electorales (LGIPE). 6. Conocer la opinión ciudadana sobre el servicio de los Módulos de Atención Ciudadana.

Sheet 1c. Alcance del SGC
C1: INSTITUTO NACIONAL ELECTORAL JLE PUEBLA | N1: Versión: 1
C2: SISTEMA DE GESTIÓN DE LA CALIDAD | N2: Fecha de emisión:
C4: PLAN ESTRATÉGICO | N4: 44279
B6: Alcance del Sistema de Gestión de la Calidad
B7: El alcance determinado por la JLE de la entidad es dar un servicio de atención a la ciudadanía durante el trámite de expedición de su CPV, desde la primera entrevista hasta su entrega en los Módulos de Atención Ciudadana de la entidad.
B11: Requisitos no Aplicables al Sistema de Gestión de la Calidad
B12: 7.1.5 Recursos de seguimiento y medición. La JLE de la entidad no considera como un requisito esencial los recursos de seguimiento y medición para proporcionar confianza en la validez de los resultados, ya que, no se requiere un equipo de medición para el desarrollo del servicio que se le proporciona a la ciudadanía. El servicio del trámite para la expedición de la CPV no requiere la trazabilidad de las mediciones para proporcionar la evidencia de la conformidad del servicio. Así mismo, los recursos de seguimiento y medición, dada la naturaleza del servicio del trámite de la CPV que se brinda en la entidad, se verifica por medio de los indicadores de desempeño de cada Proceso Sustantivo o de Apoyo y de los Objetivos de la Calidad.
B16: 8.3 Diseño y desarrollo de los productos y servicios, no es aplicable para la entidad ya que no fabrica la CPV, puesto que depende de una empresa externa para la elaboración de ésta, de acuerdo con los requerimientos solicitados por el Instituto Nacional Electoral (INE) para su entrega. Así mismo, el servicio está establecido por la normatividad vigente en el INE y que aplica para el trámite de la CPV, por lo tanto, el SGC de la entidad, no puede realizar modificaciones en la normatividad vigente.
B21: El servicio aplicable, a través, de los siguientes centros de trabajo
B22: Sitio | E22: Dirección | K22: Procesos que se desarrollan
B23: Junta Local Ejecutiva | E23: Avenida 35 Oriente número 5, Colonia Huexotitla, C.P. 72534, Puebla, Puebla. | K23: Proceso Estratégico y Procesos de Apoyo identificados en el Anexo 1 del Manual del Sistema de Gestión de la Calidad.
B24: Módulo 210151 | E24: Calle Morelos número 3, Colonia Centro, C.P. 73170, Huauchinango, Puebla. | K24: Procesos Sustantivos identificados en el Anexo 1 del Manual del Sistema de Gestión de la Calidad
B25: Módulo 210152 | E25: Avenida Juárez Sur número 252, Colonia La Rivera, C.P. 73080, Xicotepec, Puebla.
B26: Módulo 210251 | E26: Calle Ignacio Allende número 9-A, Colonia Centro, C.P. 73310, Zacatlán, Puebla.
B27: Módulo 210351 | E27: Prolongación de Mina número 214, Colonia Barrio de Francia, C.P. 73880, Teziutlán, Puebla.
B28: Módulo 210352 | E28: Calle Carlos Betancourt Molina número 54, Colonia Centro, C.P. 73680, Zacapoaxtla, Puebla.
B29: Módulo 210451 | E29: Avenida 2 Poniente número 616, Colonia Centro, C.P. 75910, Ajalpan, Puebla.
B30: Módulo 210551 | E30: Calle Zaragoza Norte número 303, Colonia Centro, C.P. 74000, San Martín Texmelucan, Puebla.
B31: Módulo 210552 | E31: Calle Pablo L. Sidar número 221, Colonia Barrio Segundo, C.P. 74160, Huejotzingo, Puebla.
B32: Módulo 210651 | E32: Calzada Ignacio Zaragoza 266, Colonia Los Pinos, C.P. 72240, Puebla, Puebla.
B33: Módulo 210751 | E33: Calle 9 Poniente número 301, Colonia Barrio El Santuario, C.P. 75200, Tepeaca, Puebla.
B34: Módulo 210752 | E34: Calle 14 Sur número 515, Colonia Barrio Sagrada Familia, C.P. 72980, Amozoc, Puebla.
B35: Módulo 210851 | E35: Boulevard José María Morelos y Pavón número 604, Colonia Centro, C.P. 75520, Chalchicomula de Sesma, Puebla.
B36: Módulo 210951 | E36: Calle Eufemio Zapata número 1, Colonia Santa María La Rivera, C.P. 72010, Puebla, Puebla.
... B47: Módulos Semifijos: 210252, 210452, 210753, 210852, 211453 | E47: Conforme al Directorio de Módulos de Atención Ciudadana de las Campañas de Actualización.
B48: Módulos móviles: 210153, 210154, 210155, 210253, 210254, 210255, 210353, 210354, 210453, 210454, 210553, 210853, 210854, 210855, 211052, 211353, 211454, 211455, 211456, 211552

Sheet 2a. Análisis Foda
C1: INSTITUTO NACIONAL ELECTORAL JLE PUEBLA | X1: Versión: 1
C3: SISTEMA DE GESTIÓN DE LA CALIDAD | X3: Fecha de emisión:
C5: FODA | X5: 44279
B7: FORTALEZAS (F) | F7: DESACUERDO | G7: NI DE ACUERDO NI EN DESACUERDO | H7: DE ACUERDO | I7: VALOR | L7: DEBILIDADES (D) | P7: DESACUERDO | Q7: NI DE ACUERDO NI EN DESACUERDO | R7: DE ACUERDO | S7: VALOR
F8: 1 | G8: 2 | H8: 3 | P8: 1 | Q8: 2 | R8: 3
B9: Experiencia acumulada del personal. | H9: x | I9: =SUMIF(F9:H9, "X",$F$8:$H$8) -> 3 | L9: Falta de información en los MAC´s, del estatus del trámite de la Credencial para Votar, lo cual impide dar una orientación y respuesta oportuna a la ciudadanía. | Q9: x | S9: =SUMIF(P9:R9,"X",P$8:R$8) -> 2
B10: Capacitación constante al personal de MAC´s relativa a los procedimientos operativos. | H10: x | I10: =SUMIF(F10:H10, "X",$F$8:$H$8) -> 3 | L10: Falta de sustitución oportuna de periféricos en Módulos de Atención Ciudadana. | R10: x | S10: =SUMIF(P10:R10,"X",P$8:R$8) -> 3
B11: Procedimientos estandarizados para la operación de los MAC´s a través del Sistema Integral de Información del Registro Federal de Electores (SIIRFE), las Instrucciones de Trabajo y del Sistema de Gestión de la Calidad. | H11: x | I11: =SUMIF(F11:H11, "X",$F$8:$H$8) -> 3 | L11: Impacto negativo por las fallas en la actualización de las versiones de SIIRFE. | Q11: x | S11: =SUMIF(P11:R11,"X",P$8:R$8) -> 2
B12: Infraestructura tecnológica y de movilidad suficiente para la operación de MAC´s. | G12: x | I12: =SUMIF(F12:H12, "X",$F$8:$H$8) -> 2 | L12: Insuficiencia en los montos de gasto de campo y radicación oportuna. | R12: x | S12: =SUMIF(P12:R12,"X",P$8:R$8) -> 3
B13: Aplicación de programas de Depuración al Padrón Electoral con la exclusión de las y los ciudadanos fallecidos, suspendidos en sus Derechos Político-Electorales, duplicados, con datos presuntamente irregulares, pérdida de vigencia de la credencial y aplicación del artículo 155 de la LGIPE. | H13: x | I13: =SUMIF(F13:H13, "X",$F$8:$H$8) -> 3 | L13: Falta de diseño y elaboración de mensajes y materiales para la difusión de los medios de identificación para el trámite de la Credencial para Votar. | R13: x | S13: =SUMIF(P13:R13,"X",P$8:R$8) -> 3
B14: El posicionamiento de la Credencial para Votar como el principal medio de identificación aceptado. | H14: x | I14: =SUMIF(F14:H14, "X",$F$8:$H$8) -> 3 | L14: Deficiencia en las campañas de difusión del Registro Federal de Electores en medios de comunicación. | R14: x | S14: =SUMIF(P14:R14,"X",P$8:R$8) -> 3
B15: Aplicación de protocolos para el regreso a la "nueva normalidad" derivada de la pandemia por COVID-19, para la atención de grupos vulnerables y atención de la ciudadanía en un marco de no discriminación por género u orientación sexual, grupos indígenas, situación religiosa, repatriados, víctimas de violencia, etc. | H15: x | I15: =SUMIF(F15:H15, "X",$F$8:$H$8) -> 3 | L15: Falta de parque vehicular equipado para módulos itinerantes y el mantenimiento oportuno por parte de la empresa arrendadora. | R15: x | S15: =SUMIF(P15:R15,"X",P$8:R$8) -> 3
B16: Proceso de selección objetiva para la contratación del personal de los MAC´s. | H16: x | I16: =SUMIF(F16:H16, "X",$F$8:$H$8) -> 3 | L16: Involucramiento doloso del personal de Módulos de Atención Ciudadana en trámites irregulares y usurpación de identidad. | R16: x | S16: =SUMIF(P16:R16,"X",P$8:R$8) -> 3
B17: Confianza ciudadana hacia el INE. | H17: x | I17: =SUMIF(F17:H17, "X",$F$8:$H$8) -> 3 | L17: Falta de incentivos económicos para las y los funcionarios de los MAC´s. | R17: x | S17: =SUMIF(P17:R17,"X",P$8:R$8) -> 3
B18: Aplicación de procedimientos en el marco de los principios rectores de certeza, legalidad y máxima publicidad, relativos al tratamiento de sus datos personales, así como las causas de improcedencia del trámite, en su caso. | H18: x | I18: =SUMIF(F18:H18, "X",$F$8:$H$8) -> 3 | L18: No se cuenta con infraestructura suficiente para atender a ciudadanos por aplicación del Artículo 141 de la LGIPE. | R18: x | S18: =SUMIF(P18:R18,"X",P$8:R$8) -> 3
B19: TOTAL | I19: =SUM(I9:I18) -> 29 | J19: =I19 -> 29 | L19: TOTAL | S19: =SUM(S9:S18)*-1 -> -28 | T19: =S19*-1 -> 28 | U19: =(S19*$K$38)/$M$38 -> -96.551724 | W19: =(I19*$K$39)/$M$39 -> 10
B21: AMENAZAS (A) | F21: NO | G21: PUEDE SER | H21: SI | I21: VALOR | L21: OPORTUNIDADES (O) | P21: NO | Q21: PUEDE SER | R21: SI | S21: VALOR
B22: Crecimiento poblacional desordenado, que dificulta la correcta referenciación de la ciudadanía. | H22: x | I22: =SUMIF(F22:H22, "X",$F$8:$H$8) -> 3 | L22: Realizar convenios de capacitación relacionados con protección civil. | R22: x | S22: =SUMIF(P22:R22,"X",$P$8:$R$8) -> 3
B23: Recorte presupuestal de la Cámara de Diputados: que se traduce en limitaciones internas para la ejecución de programas. | H23: x | I23: =SUMIF(F23:H23, "X",$F$8:$H$8) -> 3 | L23: Aprovechar las redes sociales existentes para la información relativa a requisitos, directorio de MAC´s, cierre de MAC´s, horarios, entre otros. | R23: x | S23: =SUMIF(P23:R23,"X",$P$8:$R$8) -> 3
B24: Campaña de desacreditación de algunos medios de comunicación y actores políticos hacia la institución. | H24: x | I24: =SUMIF(F24:H24, "X",$F$8:$H$8) -> 3 | L24: Gestionar con autoridades municipales la difusión de requisitos, directorios y concertación de espacios para instalación de los MAC´s itinerantes. | R24: x | S24: =SUMIF(P24:R24,"X",$P$8:$R$8) -> 3
B25: Disminución de la participación ciudadana con el Instituto. | G25: x | I25: =SUMIF(F25:H25, "X",$F$8:$H$8) -> 2 | L25: Aprovechar los espacios en radio y televisión relativas a difusión de la información de las campañas de credencialización. | R25: x | S25: =SUMIF(P25:R25,"X",$P$8:$R$8) -> 3
B26: Actas de nacimiento con deficiencias y problemas para la generación correcta de la CURP. | G26: x | I26: =SUMIF(F26:H26, "X",$F$8:$H$8) -> 2 | L26: Mantener la Certificación de Calidad en Normas ISO. | R26: x | S26: =SUMIF(P26:R26,"X",$P$8:$R$8) -> 3
B27: Comprobantes de domicilio con discrepancias respecto a la cartografía electoral. | G27: x | I27: =SUMIF(F27:H27, "X",$F$8:$H$8) -> 2 | L27: Reforzar el conocimiento sobre el funcionamiento, directorio, horarios y requisitos de los MAC´s, en todo el personal de las Juntas. | Q27: x | S27: =SUMIF(P27:R27,"X",$P$8:$R$8) -> 2
B28: Problemáticas generadas por la pandemia por COVID-19 y por la inseguridad pública. | H28: x | I28: =SUMIF(F28:H28, "X",$F$8:$H$8) -> 3 | L28: Mejorar condiciones laborales del personal de los MAC´s, incorporándolos a plaza presupuestal. | R28: x | S28: =SUMIF(P28:R28,"X",$P$8:$R$8) -> 3
B29: Cédula de identidad ciudadana a cargo de la SEGOB. | G29: x | I29: =SUMIF(F29:H29, "X",$F$8:$H$8) -> 2 | L29: Mejorar los mecanismos de entrega y comprobación de recursos. | R29: x | S29: =SUMIF(P29:R29,"X",$P$8:$R$8) -> 3
B30: Intentos de intromisión de poderes del Estado mexicano que atentan contra la autonomía del Instituto. | H30: x | I30: =SUMIF(F30:H30, "X",$F$8:$H$8) -> 3 | L30: Mejorar las condiciones de imagen institucional en los MAC´s. | R30: x | S30: =SUMIF(P30:R30,"X",$P$8:$R$8) -> 3
B31: Trámites realizados con mala fe de la ciudadanía. | H31: x | I31: =SUMIF(F31:H31, "X",$F$8:$H$8) -> 3 | L31: Contar con una cartera amplia de proveedores para la adquisición de bienes y servicios. | R31: x | S31: =SUMIF(P31:R31,"X",$P$8:$R$8) -> 3
B32: TOTAL | I32: =SUM(I22:I31)*-1 -> -26 | J32: =I32*-1 -> 26 | L32: TOTAL | S32: =SUM(S22:S31) -> 29 | T32: =S32 -> 29 | U32: =(S32*$K$38)/$M$38 -> 100 | W32: =(I32*$K$39)/$M$39 -> -8.9655172
B35: Parámetros de análisis situacional de la Organización: | L35: COORDENADAS (EJES)
B36: 1. Fortalezas y Debilidades: | D36: 2. Amenazas y Oportunidades | L36: X | M36: Valor proporcional D + O | N36: =O36 -> 3.4482759 | O36: =U32+U19 -> 3.4482759
B37: a) Dar 1 punto por cada X en desacuerdo | D37: a) Dar 1 punto por cada X bajo No | L37: Y | M37: Valor proporcional F + A | N37: =O37 -> 1.0344828 | O37: =W19+W32 -> 1.0344828
B38: b) Dar 2 puntos por cada X bajo ni acuerdo o en desacuerdo | D38: b) Dar 2 puntos por cada X bajo puede ser | K38: 100 | L38: X | M38: =MAX(T9:T32) -> 29
B39: c) Dar 3 puntos por cada X bajo acuerdo | D39: c) Dar 3 puntos por cada X bajo Sí | K39: 10 | L39: Y | M39: =MAX(J9:J32) -> 29

Sheet 2b. Matriz Posicionamiento
J1: INSTITUTO NACIONAL ELECTORAL JLE PUEBLA | BL1: Versión: 1
J3: SISTEMA DE GESTIÓN DE LA CALIDAD | BL3: Fecha de emisión:
J5: FODA | BL5: 44279
AB9: PERFIL: | AC9: =IF(AND(AND(AU34>=0,AU35>=0),AND(AU34<=3,AU35<=6)),"A",IF(AND(AND(AU34>=0,AU35>6),AND(AU34<=3,AU35<=12)),"D",IF(AND(AND(AU34>3,AU35>=0),AND(AU34<=6,AU35<=6)),"B",IF(AND(AND(AU34>3,AU35>6),AND(AU34<=6,AU35<=12)),"C",IF(AND(AND(AU34>=0,AU35<0),AND(AU34<=3,AU35>=-6)),"A",IF(AND(AND(AU34>=0,AU35<-6),AND(AU34<=3,AU35>=-12)),"D",IF(AND(AND(AU34>3,AU35<0),AND(AU34<=6,AU35>=-6)),"B",IF(AND(AND(AU34>3,AU35<-6),AND(AU34<=6,AU35>=-12)),"C",IF(AND(AND(AU34<0,AU35>0),AND(AU34>=-3,AU35<=6)),"A",IF(AND(AND(AU34<-3,AU35>0),AND(AU34>=-6,AU35<=6)),"B",IF(AND(AND(AU34<-3,AU35>6),AND(AU34>=-6,AU35<=12)),"C",IF(AND(AND(AU34<0,AU35>6),AND(AU34>=-3,AU35<=12)),"D",IF(AND(AND(AU34<0,AU35<0),AND(AU34>=-3,AU35>=-6)),"A",IF(AND(AND(AU34<-3,AU35<0),AND(AU34>=-6,AU35>=-6)),"B",IF(AND(AND(AU34<-3,AU35<-6),AND(AU34>=-6,AU35>=-12)),"C",IF(AND(AND(AU34<0,AU35<-6),AND(AU34>=-3,AU35>=-12)),"D","error")))))))))))))))) -> B | AU9: =IF(AND(AND(AU34>=0,AU35>=0),AND(AU34<=6,AU35<=12)),"Perfil Agresivo",IF(AND(AND(AU34<0,AU35>=0),AND(AU34>=-6,AU35<=12)),"Perfil Re Orientación",IF(AND(AND(AU34<0,AU35<0),AND(AU34>=-6,AU35>=-12)),"Perfil Defensivo",IF(AND(AND(AU34>=0,AU35<0),AND(AU34<=6,AU35>=-12)),"Perfil Supervivencia","Error")))) -> Perfil Agresivo
AB10: DEFINICIÓN DEL PERFIL
E11: Perfil Re Orientación | N11: Y | R11: Perfil Agresivo
AB12: Premisa del Perfil | AU12: Definición
AB13: =VLOOKUP(BR15,Perfiles!C3:D18,2,FALSE) -> PERFIL B): Alta competencia en una Institución sólida. | AU13: =VLOOKUP(AB13,Perfiles!D3:E18,2,FALSE) -> Institución financieramente fuerte que ha obtenido ventajas competitivas importantes en una Institución sólida. Institución sólida en penetración del mercado y desarrollo del servicio. Institución que cumple con altos estándares y procesos definidos por conveniencia propia más que por la Institución. Institución que demuestra comunicación sólida interna y externamente. Institución de estructura sólida y alta capacidad de reorganizar actividades frente a un riesgo. Institución con personal competente y comprometido con una estructura sólida en todas sus áreas. Institución con un ambiente laboral óptimo. Institución en cuyos niveles de satisfacción al Cliente interno son óptimos y al Cliente externo son buenos. Institución con alto nivel de liderazgo y empoderamiento en las diferentes jerarquías de la misma. Institución con soportes internos y/o externos (perteneciente a un Grupo), que beneficia a la línea de productos y/o servicios a todas las partes interesadas.
N14: 16
N15: 14 | BR15: =IF(AND(AND(AU34>=0,AU35>=0),AND(AU34<=3,AU35<=6)),"a",IF(AND(AND(AU34>=0,AU35>6),AND(AU34<=3,AU35<=12)),"d",IF(AND(AND(AU34>3,AU35>=0),AND(AU34<=6,AU35<=6)),"b",IF(AND(AND(AU34>3,AU35>6),AND(AU34<=6,AU35<=12)),"c",IF(AND(AND(AU34>=0,AU35<0),AND(AU34<=3,AU35>=-6)),"e",IF(AND(AND(AU34>=0,AU35<-6),AND(AU34<=3,AU35>=-12)),"h",IF(AND(AND(AU34>3,AU35<0),AND(AU34<=6,AU35>=-6)),"f",IF(AND(AND(AU34>3,AU35<-6),AND(AU34<=6,AU35>=-12)),"g",IF(AND(AND(AU34<0,AU35>0),AND(AU34>=-3,AU35<=6)),"i",IF(AND(AND(AU34<-3,AU35>0),AND(AU34>=-6,AU35<=6)),"j",IF(AND(AND(AU34<-3,AU35>6),AND(AU34>=-6,AU35<=12)),"k",IF(AND(AND(AU34<0,AU35>6),AND(AU34>=-3,AU35<=12)),"l",IF(AND(AND(AU34<0,AU35<0),AND(AU34>=-3,AU35>=-6)),"m",IF(AND(AND(AU34<-3,AU35<0),AND(AU34>=-6,AU35>=-6)),"h",IF(AND(AND(AU34<-3,AU35<-6),AND(AU34>=-6,AU35>=-12)),"o",IF(AND(AND(AU34<0,AU35<-6),AND(AU34>=-3,AU35>=-12)),"p","error")))))))))))))))) -> b
N16: 12
N17: 10
N18: 8
N19: 6
N20: 4
N21: 2
C22: X | N22: 0
F23: -18 | G23: -14 | H23: -12 | I23: -10 | J23: -8 | K23: -6 | L23: -4 | M23: -2 | N23: 0 | O23: 0 | P23: 2 | Q23: 4 | R23: 6 | S23: 8 | T23: 10 | U23: 12 | V23: 14 | W23: 16
N24: -2
N25: -4
N26: -6
N27: -8
N28: -10
N29: -12
N30: -14
N31: -16 | AB31: Coordenadas
AB32: EJE
E33: Perfil Defensivo | R33: Perfil Supervivencia | AB33: COORDENADAS (EJES) | AU33: RESULTADOS
AB34: X | AU34: ='2a. Análisis Foda'!N36 -> 3.4482759 | BN34: =AU34*-1 -> -3.4482759
AB35: Y | AU35: ='2a. Análisis Foda'!N37 -> 1.0344828 | BN35: =AU35*-1 -> -1.0344828

Sheet 3a.Matríz de Partes Interesadas
C1: INSTITUTO NACIONAL ELECTORAL JLE PUEBLA | E1: Versión: 1
C3: SISTEMA DE GESTIÓN DE LA CALIDAD | E3: Fecha de emisión:
C5: PLAN ESTRATÉGICO | E5: 44279
A9: Partes Interesadas | B9: Tipo | C9: Necesidades | D9: Seguimiento | E9: Revisión | F9: Expectativas
C10: Requisitos pertinentes | F10: Requisitos deseables a considerar
A11: Personal de la Delegación INE Puebla | B11: Interna | C11: • Remuneración económica. • Buen clima laboral. • Información Institucional. • Capacitación. • Conocimiento de las funciones de los puestos. | D11: DEA, DOS y Junta Local Ejecutiva. | E11: Evaluaciones de competencias. | F11: •Contar con los recursos necesarios para realizar el trabajo. •Motivación Institucional. •Buen trato de los jefes inmediatos. •Ambiente incluyente. •Remuneración justa. •Estabilidad laboral.
A12: Dirección de Operación y Seguimiento (DOS) | B12: Interna | C12: • Cumplir con las funciones, actividades y procedimientos para la operación del MAC. • Personal de MAC debidamente capacitado. • Aplicación correcta de las supervisiones a los MAC´s. • Cumplir con los procedimientos para el retiro, resguardo y destrucción de formatos de credencial de los MAC´s. • Coordinar la liberación de la plantilla para la operación de los MAC´s. • Mantener el parque vehicular en buen estado para garantizar la operación del MAC. • Mantener el equipo tecnológico necesario y en buen estado para la operación del MAC. | D12: Juntas Local y Distritales Ejecutivas. | E12: • Programa de Capacitación. • Indicadores de desempeño. • Manuales de Operación actualizados. • Cédula de supervisión. • Inventario de infraestructura. | F12: • Las funciones, actividades y procedimientos que se establecen para la operación del Módulo de Atención Ciudadana son comprendidas y aplicadas en su totalidad. • La efectividad de la Capacitación del personal es reflejada en la operación del MAC. • Los procedimientos de seguimiento y evaluación de la operación arrojen los resultados positivos. • Correcta aplicación de las Instrucciones de Trabajo para la Operación del Módulo de Atención Ciudadana. • Equipo tecnológico, infraestructura, mobiliario y parque vehicular suficientes que se mantengan en buen estado.
A13: Dirección de Depuración y Verificación en Campo (DDVC) | B13: Interna | C13: • Inclusión o exclusión de la Ciudadanía al Padrón Electoral. • Realizar la validación para la presunta usurpación de identidad y datos apócrifos de la ciudadanía. • Investigar los casos de datos presuntamente irregulares de la ciudadanía. • Informar a la ciudadanía la suspensión de sus derechos políticos. • Informar a la ciudadanía la cancelación de su trámite por datos irregulares. • Informar a la ciudadanía sobre posibles domicilios irregulares. | D13: Junta Local Ejecutiva/Depuración al Padrón. | E13: • Base de datos del Padrón Electoral actualizado. • Análisis registral. | F13: • Padrón Electoral actualizado. • Identificación de la ciudadanía que pretende realizar robo de identidad. • Identificación de la ciudadanía con datos usurpados. • Tener actualizada la reincorporación de la ciudadanía con retiro de sus derechos políticos. • Base de datos actualizada hasta la fecha.
A14: Dirección de Cartografía Electoral (DCE) | B14: Interna | C14: • Referenciar correctamente el domicilio de la ciudadanía. • Actualizar la cartografía electoral para el uso de los MAC´s. | D14: Junta Local Ejecutiva/ Cartografía Estatal. | E14: • Formato CIF-05 lleno para verificar las claves geoelectorales. | F14: • La verificación en campo pueda ser localizada fácilmente por el técnico cartográfico y las georreferencias proporcionadas den información veraz de la ubicación de la ciudadanía. • La actualización cartográfica electoral se mantenga actualizada en el menor tiempo posible. • El crecimiento demográfico no sea de forma acelerada.
A15: Dirección de Atención Ciudadana INETEL y Centro de Atención Ciudadana (DAC) | B15: Interna | C15: • Brindar información a la ciudadanía de la documentación requerida para el trámite de credencial. • Informar al ciudadano del estatus de su trámite de la CPV. • Recibir, canalizar y dar seguimiento a las quejas ciudadanas. • Generar cita para el trámite de la CPV. • Recibir denuncias por robo y/o extravío de la CPV. • Recibir, canalizar y dar seguimiento a quejas y/o denuncias en contra del personal de MAC. | D15: Junta Local Ejecutiva/ CECEOC. | E15: • Base de datos del Padrón Electoral. • Internet para generar las citas programadas. • Sistema Remedy para registrar las atenciones. ciudadanas por teléfono y presenciales. • SIIRFE Monitoreo Trámites y Credenciales Robadas y Extraviadas. | F15: • Brindar la información más oportuna y adecuada para el trámite de la credencial. • Atender un gran porcentaje de citas programadas. • Brindar a la ciudadanía los requisitos adecuadamente en los medios de comunicación de la DAC para no recibir quejas. • Dar inmediata respuesta a las quejas presentadas.
A16: Dirección de Ejecutiva Administrativa (DEA) | B16: Interna | C16: • Administrar correctamente los recursos humanos, financieros y materiales para el cumplimiento de las funciones operativas de las vocalías del Registro Federal de Electores. • Llevar acabo la planeación y programación de los recursos financieros, para garantizar la operación y desarrollo de los programas y proyectos de las vocalías del Registro Federal de Electores. | D16: Juntas Local y Distritales Ejecutivas. | E16: • Documentos normativos-administrativos, con la finalidad de contribuir al cumplimiento de los programas y proyectos. | F16: • Aplicación de los recursos, financieros y materiales para la operación de los MAC ´s. • Buena Integración de los documentos presupuestales de control de la evaluación.
A17: Centro de Consulta y Resguardo Documental (CECyRD) | B17: Interna | C17: • Que el flujo de la información de inscripción y actualización sea constante y sin interrupciones. • Validar la información generada en el MAC. • Que se integre la Solicitud individual de inscripción o actualización del ciudadano. • Enviar la información para la credencial para votar. | D17: Juntas Local y Distritales Ejecutivas/MAC 's. | E17: • Actualización de las versiones del SIIRFE-MAC, permitiendo realizar el levantamiento de tramites en forma correcta. | F17: • Base de datos capturadas correctamente. • Que no existan afectaciones o errores en la base de datos del INE. • Digitalización correcta de la documentación de la ciudadanía. • Que la operación no sea interrumpida por falta de insumos. • Todas las validaciones, solicitudes, inscripciones, envío y recibo de información adecuadas.
A18: Instituciones Privadas | B18: Externa | C18: • Contar con un instrumento confiable de identificación ciudadana que le permita ser fuente confiable para otorgar servicios a sus clientes. | D18: Consejo General/ Junta General Ejecutiva | E18: •Convenios de apoyo y colaboración. | F18: •Que los ciudadanos cuenten con una identificación vigente. •Prevención de falsificaciones de la CPV. • Que la Información sea fidedigna de la identificación otorgada por el Instituto de acuerdo con los requisitos establecidos.
A19: Instituciones Publicas (Federales y Estatales) | B19: Externa | C19: • Que se aplique lo estipulado en la Constitución Política Mexicana y leyes reglamentarias, así como convenios que se establezcan con el Instituto. | D19: Juntas Local y Distritales Ejecutivas/MAC 's. | E19: •Convenios de apoyo y colaboración. | F19: •Información oportuna y certera, contenida en los instrumentos electorales a cargo del Instituto.
A20: Proveedores | B20: Externa | C20: • Pago oportuno. • Negocio permanente. | D20: Jefe de Recursos Materiales./Junta Local Ejecutiva. | E20: •Evaluaciones de proveedores. | F20: • Política de entregas. •Créditos.
A21: Ciudadanía | B21: Externa | C21: • Obtener un documento oficial que permite la identidad de la ciudadanía. • Recibir información clara y precisa para el trámite de la credencial. • Obtener orientación de los requisitos que deben cumplir sus documentos para el trámite. • No tener errores en la impresión de la Credencial para Votar • Ser atendidos con cordialidad y respeto sin discriminación por parte del personal. | D21: Juntas Local y Distritales Ejecutivas/MAC´s. | E21: • Credencial para Votar. | F21: • Que se realice el trámite conforme a la normatividad. • Atención y seguimiento a quejas. • Entrega de Credencial para votar a la ciudadanía.
A22: Medios de Comunicación | B22: Externa | C22: • La información proporcionada por la institución se realice de manera oportuna y verídica conforme a los trámites que se realizan en los MAC 's. | D22: Juntas Local y Distritales Ejecutivas. | E22: • Que los anuncios del INE sean trasmitidos a la ciudadanía en radio, televisión y redes sociales. | F22: • Que la información sea compartida de forma inmediata y directa con los medios de comunicación.
... A24: Partidos Políticos | B24: Externa | C24: • Que la ciudadanía pueda obtener su CPV para ejercer su derecho al voto. | D24: Juntas Local y Distritales Ejecutivas/Órganos de Vigilancia. | E24: • Con los informes de los Órganos de Vigilancia, a través de las sesiones que se desarrollan en los mismo. | F24: • Contar con un Padrón y Lista Nominal de Electores confiable, en los que no existan duplicidades y este depurado. • Que el nivel de cobertura permita asegurar el derecho del voto de la ciudadanía.

Sheet 4a. Parámetros de riesgo
D1: INSTITUTO NACIONAL ELECTORAL JLE PUEBLA | K1: Versión: 1
D3: SISTEMA DE GESTIÓN DE LA CALIDAD | K3: Fecha de emisión:
D5: PLAN ESTRATÉGICO | K5: 44279
A8: RIESGOS | G8: OPORTUNIDADES
A9: NATURALEZA | B9: DEFINICIONES | G9: NATURALEZA | H9: DEFINICIONES
A10: Operativa | B10: Riesgo cuyos efectos están relacionados con la nula o mala prestación del servicio y/o entrega de la credencial para votar durante la operación y a la entrega a la Ciudadanía. Puede incluir maquinaria, equipo, infraestructura, recurso humano, insumos, servicios de apoyo (agua potable, electricidad, redes, internet, Sistema SIIRFE-MAC) y Partes Interesadas. | G10: Operativa | H10: Oportunidad cuyos efectos están relacionados con la prestación del servicio y/o entrega de la credencial para votar durante la operación y a la entrega a la Ciudadanía de forma eficiente. Puede incluir maquinaria, equipo, infraestructura, Recurso Humano, Insumos, servicios de apoyo (agua potable, electricidad, redes, internet, Sistema SIIRFE-MAC, etc.) y Partes Interesadas.
A11: Ambiental | B11: Cualquier riesgo cuyo efecto negativo está relacionado con la salud física, medio ambiente y seguridad laboral de cualquier Parte Interesada (interna o externa) así como el ambiente laboral de los funcionarios dentro de la Delegación INE Puebla. | G11: Ambiental | H11: Oportunidad cuyo efecto está relacionado con mantener e incrementar los beneficios en la salud física, medio ambiente y seguridad laboral de cualquier Parte Interesada (interna y externa) así como el ambiente laboral de los Funcionarios dentro de la Delegación INE Puebla.
A12: Legal y Reglamentario | B12: Riesgo cuyos efectos están relacionados con los cambios de las normatividades legales y reglamentarias aplicables a la Delegación INE Puebla en el ámbito federal, local y del ramo que no permitan acceder, mantener o mejorar las relaciones con las Partes Interesadas y esto afecte a la Delegación INE Puebla durante la operación, entrega de la credencial para votar y/o trámite a la Ciudadanía. | G12: Legal y Reglamentario | H12: Oportunidad cuyos efectos están relacionados con el aprovechamiento de los cambios en las normatividades legales y reglamentarias aplicables a la Delegación INE Puebla en el ámbito federal, local y del ramo que permitan mantener y mejorar las relaciones con las Partes Interesadas durante la operación y a la entrega de la credencial para votar y/o trámite a la Ciudadanía.
A13: Política | B13: Riesgo cuyos efectos están relacionados con la probabilidad de que las fuerzas políticas generen cambios negativos en el entorno de la Delegación INE Puebla y obstaculicen o minimicen relaciones con Partes Interesadas. | G13: Política | H13: Oportunidad cuyos efectos están relacionados con la probabilidad de que las fuerzas políticas generen cambios positivos en el entorno de la Delegación INE Puebla y apoyen a mejorar las relaciones con las Partes Interesadas.
A14: Industrial | B14: Riesgo cuyos efectos están relacionados con Partes Interesadas que generan una desventaja frente a la competencia en el mismo ramo, zona geográfica, Ciudad, Estado y/o País en la prestación del producto / servicio brindado a la Ciudadanía. | G14: Industrial | H14: Oportunidad cuyos efectos están relacionados con Partes Interesadas que generan una ventaja competitiva en el mismo ramo, zona geográfica, Ciudad, Estado y/o País en la prestación del producto / servicio brindado a la Ciudadanía.
A15: Institucional | B15: Riesgo cuyos efectos están relacionados con cambios en la planeación y ejecución estratégica del INE, DOS, DERFE que provocan limitantes tangibles e intangibles en los resultados de la Delegación INE Puebla. | G15: Institucional | H15: Oportunidad cuyos efectos están relacionados con cambios en la planeación y ejecución estratégica del INE, DERFE.DOS que provocan beneficios tangibles e intangibles en los resultados de la Delegación INE Puebla.
A16: Social/Cultural | B16: Riesgo en los integrantes del mercado y su influencia en el entorno. Variables como la evolución demográfica, Movilidad social, Cambios en el estilo de vida, Actitud consumista, Nivel educativo, Patrones culturales y la Religión. | G16: Social/Cultural | H16: Oportunidad que los integrantes del mercado y su influencia en el entorno sean de beneficio con la evolución demográfica, Movilidad social, Cambios en el estilo de vida, Actitud consumista, Nivel educativo, Patrones culturales y la Religión.
A17: Tecnológicos | B17: Riesgo del desarrollo tecnológico y sus aportes en la actividad Institucional. Depende de su estado la cifra en gasto público en investigación, Preocupación gubernamental y de industria por la tecnología, Grado de obsolescencia, Madurez de las tecnologías convencionales, Desarrollo de nuevos productos, Velocidad de transmisión de la tecnología | G17: Tecnológicos | H17: Oportunidad en el desarrollo tecnológico y sus aportes en la actividad de la Delegación INE Puebla, Madurez de las tecnologías convencionales, Desarrollo de nuevos productos, Velocidad de transmisión de la tecnología
A18: Económico / Financiero | B18: Riesgo cuyos efectos están relacionados con limitar o detener la sostenibilidad financiera de la Delegación INE Puebla las cuales pueden ser generadas en conjunto por una o unas de las Partes Interesadas. | G18: Económico / Financiero | H18: Oportunidad cuyos efectos están relacionados con mantener e incrementar la sostenibilidad financiera de la Delegación INE Puebla las cuales pueden ser generadas en conjunto por una o unas de las Partes Interesadas.
A20: OCURRENCIA | B20: DEFINICIONES | H20: DEFINICIONES
A21: Baja | B21: Remotamente posible. El daño ocurre muy rara vez. | G21: Baja | H21: Remotamente posible. La oportunidad ocurre muy rara vez.
A22: Media | B22: Bastante posible. El daño ocurre en algunas ocasiones y no es extraño que sucediera. | G22: Media | H22: Bastante posible. La oportunidad ocurre en algunas ocasiones y no es extraño que sucediera.
A23: Alta | B23: Completamente posible. El daño ocurre siempre o casi siempre y ya ha ocurrido en ocasiones anteriores. | G23: Alta | H23: Completamente posible. La oportunidad ocurre casi siempre o siempre y ya ha ocurrido en ocasiones anteriores.
A25: SEVERIDAD | B25: DEFINICIONES | G25: SEVERIDAD | H25: DEFINICIONES
A26: Leve | B26: Riesgo mínimo negativo que limita la integridad para otorgar la prestación del producto / servicio determinado por la Delegación INE Puebla. Puede revertirse de forma rápida o inmediata y genera costos de no calidad mínimos sin daños permanentes. | G26: Leve | H26: Impacto mínimo positivo que mantiene la integridad para otorgar la prestación del producto / servicio determinado por la Delegación INE Puebla. Puede implementarse de forma rápida y genera costos de calidad mínimos.
A27: Moderado | B27: Riesgo negativo considerable que afecta la integridad para otorgar la prestación del producto / servicio determinado por la Delegación INE Puebla. Puede revertirse en un corto tiempo y genera costos de no calidad considerables y con daños mínimos permanentes. | G27: Moderado | H27: Impacto positivo considerable que mejora la integridad para otorgar la prestación del producto / servicio determinado por la Delegación INE Puebla. Puede implementarse de un corto tiempo y genera costos de calidad considerables.
A28: Grave | B28: Riesgo negativo que afecta gravemente la integridad para otorgar la prestación del producto / servicio determinado por la Delegación INE Puebla. Pocas veces puede revertirse en un mediano o largo tiempo y genera costos de no calidad altos y con daños visiblemente permanentes. | G28: Importante | H28: Impacto positivo garantizado que potencializa la integridad para otorgar la prestación del producto / servicio determinado por la Delegación INE Puebla. Puede implementarse en un mediano o largo tiempo y genera costos de calidad considerables y posiblemente permanentes.
A30: RANGOS | B30: CLASIFICACIÓN | C30: DICTAMEN | D30: ACCIONES | G30: RANGOS | H30: CLASIFICACIÓN | I30: DICTAMEN | J30: ACCIONES
A31: 0 - 199 | B31: TRIVIAL | C31: VIGILARLO | D31: Control rutinario, no afecta la secuencia e integridad de los procesos de una o varias áreas de la Delegación INE Puebla, el SGC y/o Partes Interesadas. | G31: 0 - 250 | H31: LIMITADA | I31: A CONSIDERAR | J31: Oportunidad que genera un beneficio mínimo en los procesos de una o varias áreas de la Institución, el SGC y/o Partes Interesadas de la cual se espera un resultado inmediato.
A32: 200 - 399 | B32: TOLERABLE | C32: ASUMIRLO | D32: Monitorear el riesgo, afecta mínimamente la secuencia y la integridad de los procesos de una o varias áreas de la Delegación INE Puebla, el SGC y/o Partes Interesadas. | G32: 251 - 500 | H32: MEDIA | I32: ABORDAR | J32: Oportunidad con buena posibilidad de abordarse siempre y cuando se profundice en los beneficios esperados en los procesos de una o varias áreas de la Delegación INE Puebla, el SGC y/o Partes Interesadas de la cual se espera un resultado a corto plazo.
A33: 400 - 599 | B33: MODERADO | C33: CONTROLARLO | D33: Plan de acción eficaz donde se realice un control permanente ya que existe un riesgo moderado en la secuencia y la integridad de los procesos de una o varias áreas de la Delegación INE Puebla, al SGC y/o Partes Interesadas. | G33: 501 - 750 | H33: POTENCIAL | I33: APROPIARSE | J33: Oportunidad con beneficios claros y específicos en los procesos de una o varias áreas de la Delegación INE Puebla, el SGC y/o Partes Interesadas, de la cual se espera un resultado a corto y mediano plazo.
A34: 600 - 799 | B34: IMPORTANTE | C34: MINIMIZARLO | D34: Acción de contención inmediata, es importante generar un plan de acción eficaz y eficiente donde se realice un control específico y permanente ya que el riesgo es alto en la secuencia y la integridad de los procesos de varias áreas de la Delegación INE Puebla, el SGC y/o Partes interesadas. | G34: 751 - 1000 | H34: SOBRESALIENTE | I34: EXPLOTARLA | J34: Oportunidad con beneficios claros, generales y específicos en los procesos de varias o todas las áreas de la Delegación INE Puebla, el SGC y/o Partes Interesadas de la cual se obtiene un resultado a corto, mediano y/o largo plazo.
A35: 800 - 1000 | B35: INTOLERABLE | C35: ATENCIÓN INMEDIATA | D35: Acción de contención inmediata, es urgente generar un plan de acción y revisión del proceso (aplicar reingeniería si es necesario) eficaz y eficiente donde se realice un control específico y permanente ya que el riesgo es grave en la secuencia y la integridad de los procesos de varias o todas las áreas de la Delegación INE Puebla, el SGC y/o Partes interesadas.

Sheet 4b. Matriz - Contexto
B2: INSTITUTO NACIONAL ELECTORAL JLE PUEBLA | G2: Versión: 1
B4: SISTEMA DE GESTIÓN DE LA CALIDAD | G4: Fecha de emisión:
B6: PLAN ESTRATÉGICO | G6: 44279
A9: CLASIFICACIÓN DEL FODA | B9: DESCRIPCIÓN DEL RIESGO / OPORTUNIDAD GENERAL | C9: TIPO DE EFECTO | D9: PROCESOS AFECTADOS / BENEFICIADOS | O9: NATURALEZA | P9: OCURRENCIA | Q9: SEVERIDAD | R9: NIVEL DE RIESGO / OPORTUNIDAD | S9: CLASIFICACIÓN | T9: DICTAMEN | U9: CONCLUSIONES
D10: Entrevista | E10: Trámite | F10: Transferencia | G10: Conciliación | H10: Entrega de Credencial | I10: Reclutamiento y Selección | J10: Capacitación | K10: Desempeño de Personal | L10: Soporte Técnico | M10: Bienes y Servicios | N10: Alta Dirección
A11: Fortaleza | B11: ='2a. Análisis Foda'!B9:E9 -> Experiencia acumulada del personal. | C11: Positivo | D11: X | E11: X | F11: X | G11: X | H11: X | O11: Operativo | P11: Media | Q11: Importante | R11: =IFERROR(VLOOKUP(O11,Naturaleza,2,FALSE)*VLOOKUP('4b. Matriz - Contexto'!P11,Probabilidad,2,FALSE)*VLOOKUP('4b. Matriz - Contexto'!Q11,Severidad,2,FALSE),"") -> 700 | S11: =IF(A11="Debilidad",IF(R11="","",IF(AND(R11>0,R11<200),"Trivial",IF(OR(R11=200,AND(R11>200,R11<400)),"Tolerable",IF(OR(R11=400,AND(R11>400,R11<600)),"Moderado",IF(OR(R11=600,AND(R11>600,R11<800)),"Importante",IF(OR(R11=800,R11>800,R11<1000,R11=1000),"Intolerable","")))))),IF(A11="Amenaza",IF(R11="","",IF(AND(R11>0,R11<200),"Trivial",IF(OR(R11=200,AND(R11>200,R11<400)),"Tolerable",IF(OR(R11=400,AND(R11>400,R11<600)),"Moderado",IF(OR(R11=600,AND(R11>600,R11<800)),"Importante",IF(OR(R11=800,R11>800,R11<1000,R11=1000),"Intolerable","")))))),IF(A11="Fortaleza",IF(R11="","",IF(AND(R11>0,R11<250),"Limitada",IF(OR(R11=250,AND(R11>250,R11<500)),"Media",IF(OR(R11=500,AND(R11>500,R11<750)),"Potencial",IF(OR(R11=750,AND(R11>750,R11<=1000)),"Sobresaliente", ""))))), IF(A11="Oportunidad",IF(R11="","",IF(AND(R11>0,R11<250),"Limitada",IF(OR(R11=250,AND(R11>250,R11<500)),"Media",IF(OR(R11=500,AND(R11>500,R11<750)),"Potencial",IF(OR(R11=750,AND(R11>750,R11<=1000)),"Sobresaliente",""))))),"")))) -> Potencial | T11: =IFERROR(VLOOKUP(S11,'4a. Parámetros de riesgo'!$B$31:$C$35,2,FALSE),IFERROR(VLOOKUP(S11,'4a. Parámetros de riesgo'!$H$31:$I$35,2,FALSE),"")) -> APROPIARSE | U11: =IFERROR(VLOOKUP(T11,'4a. Parámetros de riesgo'!$C$31:$D$35,2,FALSE),IFERROR(VLOOKUP(T11,'4a. Parámetros de riesgo'!$I$31:$J$35,2,FALSE),"")) -> Oportunidad con beneficios claros y específicos en los procesos de una o varias áreas de la Delegación INE Puebla, el SGC y/o Partes Interesadas, de la cual se espera un resultado a corto y mediano plazo.
A12: Fortaleza | B12: ='2a. Análisis Foda'!B10:E10 -> Capacitación constante al personal de MAC´s relativa a los procedimientos operativos. | C12: Positivo | J12: X | O12: Operativo | P12: Media | Q12: Importante | R12: =IFERROR(VLOOKUP(O12,Naturaleza,2,FALSE)*VLOOKUP('4b. Matriz - Contexto'!P12,Probabilidad,2,FALSE)*VLOOKUP('4b. Matriz - Contexto'!Q12,Severidad,2,FALSE),"") -> 700 | S12: =IF(A12="Debilidad",IF(R12="","",IF(AND(R12>0,R12<200),"Trivial",IF(OR(R12=200,AND(R12>200,R12<400)),"Tolerable",IF(OR(R12=400,AND(R12>400,R12<600)),"Moderado",IF(OR(R12=600,AND(R12>600,R12<800)),"Importante",IF(OR(R12=800,R12>800,R12<1000,R12=1000),"Intolerable","")))))),IF(A12="Amenaza",IF(R12="","",IF(AND(R12>0,R12<200),"Trivial",IF(OR(R12=200,AND(R12>200,R12<400)),"Tolerable",IF(OR(R12=400,AND(R12>400,R12<600)),"Moderado",IF(OR(R12=600,AND(R12>600,R12<800)),"Importante",IF(OR(R12=800,R12>800,R12<1000,R12=1000),"Intolerable","")))))),IF(A12="Fortaleza",IF(R12="","",IF(AND(R12>0,R12<250),"Limitada",IF(OR(R12=250,AND(R12>250,R12<500)),"Media",IF(OR(R12=500,AND(R12>500,R12<750)),"Potencial",IF(OR(R12=750,AND(R12>750,R12<=1000)),"Sobresaliente", ""))))), IF(A12="Oportunidad",IF(R12="","",IF(AND(R12>0,R12<250),"Limitada",IF(OR(R12=250,AND(R12>250,R12<500)),"Media",IF(OR(R12=500,AND(R12>500,R12<750)),"Potencial",IF(OR(R12=750,AND(R12>750,R12<=1000)),"Sobresaliente",""))))),"")))) -> Potencial | T12: =IFERROR(VLOOKUP(S12,'4a. Parámetros de riesgo'!$B$31:$C$35,2,FALSE),IFERROR(VLOOKUP(S12,'4a. Parámetros de riesgo'!$H$31:$I$35,2,FALSE),"")) -> APROPIARSE | U12: =IFERROR(VLOOKUP(T12,'4a. Parámetros de riesgo'!$C$31:$D$35,2,FALSE),IFERROR(VLOOKUP(T12,'4a. Parámetros de riesgo'!$I$31:$J$35,2,FALSE),"")) -> Oportunidad con beneficios claros y específicos en los procesos de una o varias áreas de la Delegación INE Puebla, el SGC y/o Partes Interesadas, de la cual se espera un resultado a corto y mediano plazo.
A13: Fortaleza | B13: ='2a. Análisis Foda'!B11:E11 -> Procedimientos estandarizados para la operación de los MAC´s a través del Sistema Integral de Información del Registro Federal de Electores (SIIRFE), las Instrucciones de Trabajo y del Sistema de Gestión de la Calidad. | C13: Positivo | D13: X | E13: X | F13: X | G13: X | H13: X | O13: Operativo | P13: Alta | Q13: Importante | R13: =IFERROR(VLOOKUP(O13,Naturaleza,2,FALSE)*VLOOKUP('4b. Matriz - Contexto'!P13,Probabilidad,2,FALSE)*VLOOKUP('4b. Matriz - Contexto'!Q13,Severidad,2,FALSE),"") -> 1000 | S13: =IF(A13="Debilidad",IF(R13="","",IF(AND(R13>0,R13<200),"Trivial",IF(OR(R13=200,AND(R13>200,R13<400)),"Tolerable",IF(OR(R13=400,AND(R13>400,R13<600)),"Moderado",IF(OR(R13=600,AND(R13>600,R13<800)),"Importante",IF(OR(R13=800,R13>800,R13<1000,R13=1000),"Intolerable","")))))),IF(A13="Amenaza",IF(R13="","",IF(AND(R13>0,R13<200),"Trivial",IF(OR(R13=200,AND(R13>200,R13<400)),"Tolerable",IF(OR(R13=400,AND(R13>400,R13<600)),"Moderado",IF(OR(R13=600,AND(R13>600,R13<800)),"Importante",IF(OR(R13=800,R13>800,R13<1000,R13=1000),"Intolerable","")))))),IF(A13="Fortaleza",IF(R13="","",IF(AND(R13>0,R13<250),"Limitada",IF(OR(R13=250,AND(R13>250,R13<500)),"Media",IF(OR(R13=500,AND(R13>500,R13<750)),"Potencial",IF(OR(R13=750,AND(R13>750,R13<=1000)),"Sobresaliente", ""))))), IF(A13="Oportunidad",IF(R13="","",IF(AND(R13>0,R13<250),"Limitada",IF(OR(R13=250,AND(R13>250,R13<500)),"Media",IF(OR(R13=500,AND(R13>500,R13<750)),"Potencial",IF(OR(R13=750,AND(R13>750,R13<=1000)),"Sobresaliente",""))))),"")))) -> Sobresaliente | T13: =IFERROR(VLOOKUP(S13,'4a. Parámetros de riesgo'!$B$31:$C$35,2,FALSE),IFERROR(VLOOKUP(S13,'4a. Parámetros de riesgo'!$H$31:$I$35,2,FALSE),"")) -> EXPLOTARLA | U13: =IFERROR(VLOOKUP(T13,'4a. Parámetros de riesgo'!$C$31:$D$35,2,FALSE),IFERROR(VLOOKUP(T13,'4a. Parámetros de riesgo'!$I$31:$J$35,2,FALSE),"")) -> Oportunidad con beneficios claros, generales y específicos en los procesos de varias o todas las áreas de la Delegación INE Puebla, el SGC y/o Partes Interesadas de la cual se obtiene un resultado a corto, mediano y/o largo plazo.
A14: Fortaleza | B14: ='2a. Análisis Foda'!B12:E12 -> Infraestructura tecnológica y de movilidad suficiente para la operación de MAC´s. | C14: Positivo | M14: X | O14: Operativo | P14: Media | Q14: Importante | R14: =IFERROR(VLOOKUP(O14,Naturaleza,2,FALSE)*VLOOKUP('4b. Matriz - Contexto'!P14,Probabilidad,2,FALSE)*VLOOKUP('4b. Matriz - Contexto'!Q14,Severidad,2,FALSE),"") -> 700 | S14: =IF(A14="Debilidad",IF(R14="","",IF(AND(R14>0,R14<200),"Trivial",IF(OR(R14=200,AND(R14>200,R14<400)),"Tolerable",IF(OR(R14=400,AND(R14>400,R14<600)),"Moderado",IF(OR(R14=600,AND(R14>600,R14<800)),"Importante",IF(OR(R14=800,R14>800,R14<1000,R14=1000),"Intolerable","")))))),IF(A14="Amenaza",IF(R14="","",IF(AND(R14>0,R14<200),"Trivial",IF(OR(R14=200,AND(R14>200,R14<400)),"Tolerable",IF(OR(R14=400,AND(R14>400,R14<600)),"Moderado",IF(OR(R14=600,AND(R14>600,R14<800)),"Importante",IF(OR(R14=800,R14>800,R14<1000,R14=1000),"Intolerable","")))))),IF(A14="Fortaleza",IF(R14="","",IF(AND(R14>0,R14<250),"Limitada",IF(OR(R14=250,AND(R14>250,R14<500)),"Media",IF(OR(R14=500,AND(R14>500,R14<750)),"Potencial",IF(OR(R14=750,AND(R14>750,R14<=1000)),"Sobresaliente", ""))))), IF(A14="Oportunidad",IF(R14="","",IF(AND(R14>0,R14<250),"Limitada",IF(OR(R14=250,AND(R14>250,R14<500)),"Media",IF(OR(R14=500,AND(R14>500,R14<750)),"Potencial",IF(OR(R14=750,AND(R14>750,R14<=1000)),"Sobresaliente",""))))),"")))) -> Potencial | T14: =IFERROR(VLOOKUP(S14,'4a. Parámetros de riesgo'!$B$31:$C$35,2,FALSE),IFERROR(VLOOKUP(S14,'4a. Parámetros de riesgo'!$H$31:$I$35,2,FALSE),"")) -> APROPIARSE | U14: =IFERROR(VLOOKUP(T14,'4a. Parámetros de riesgo'!$C$31:$D$35,2,FALSE),IFERROR(VLOOKUP(T14,'4a. Parámetros de riesgo'!$I$31:$J$35,2,FALSE),"")) -> Oportunidad con beneficios claros y específicos en los procesos de una o varias áreas de la Delegación INE Puebla, el SGC y/o Partes Interesadas, de la cual se espera un resultado a corto y mediano plazo.
A15: Fortaleza | B15: ='2a. Análisis Foda'!B13:E13 -> Aplicación de programas de Depuración al Padrón Electoral con la exclusión de las y los ciudadanos fallecidos, suspendidos en sus Derechos Político-Electorales, duplicados, con datos presuntamente irregulares, pérdida de vigencia de la credencial y aplicación del artículo 155 de la LGIPE. | C15: Positivo | D15: X | E15: X | F15: X | G15: X | H15: X | O15: Operativo | P15: Media | Q15: Importante | R15: =IFERROR(VLOOKUP(O15,Naturaleza,2,FALSE)*VLOOKUP('4b. Matriz - Contexto'!P15,Probabilidad,2,FALSE)*VLOOKUP('4b. Matriz - Contexto'!Q15,Severidad,2,FALSE),"") -> 700 | S15: =IF(A15="Debilidad",IF(R15="","",IF(AND(R15>0,R15<200),"Trivial",IF(OR(R15=200,AND(R15>200,R15<400)),"Tolerable",IF(OR(R15=400,AND(R15>400,R15<600)),"Moderado",IF(OR(R15=600,AND(R15>600,R15<800)),"Importante",IF(OR(R15=800,R15>800,R15<1000,R15=1000),"Intolerable","")))))),IF(A15="Amenaza",IF(R15="","",IF(AND(R15>0,R15<200),"Trivial",IF(OR(R15=200,AND(R15>200,R15<400)),"Tolerable",IF(OR(R15=400,AND(R15>400,R15<600)),"Moderado",IF(OR(R15=600,AND(R15>600,R15<800)),"Importante",IF(OR(R15=800,R15>800,R15<1000,R15=1000),"Intolerable","")))))),IF(A15="Fortaleza",IF(R15="","",IF(AND(R15>0,R15<250),"Limitada",IF(OR(R15=250,AND(R15>250,R15<500)),"Media",IF(OR(R15=500,AND(R15>500,R15<750)),"Potencial",IF(OR(R15=750,AND(R15>750,R15<=1000)),"Sobresaliente", ""))))), IF(A15="Oportunidad",IF(R15="","",IF(AND(R15>0,R15<250),"Limitada",IF(OR(R15=250,AND(R15>250,R15<500)),"Media",IF(OR(R15=500,AND(R15>500,R15<750)),"Potencial",IF(OR(R15=750,AND(R15>750,R15<=1000)),"Sobresaliente",""))))),"")))) -> Potencial | T15: =IFERROR(VLOOKUP(S15,'4a. Parámetros de riesgo'!$B$31:$C$35,2,FALSE),IFERROR(VLOOKUP(S15,'4a. Parámetros de riesgo'!$H$31:$I$35,2,FALSE),"")) -> APROPIARSE | U15: =IFERROR(VLOOKUP(T15,'4a. Parámetros de riesgo'!$C$31:$D$35,2,FALSE),IFERROR(VLOOKUP(T15,'4a. Parámetros de riesgo'!$I$31:$J$35,2,FALSE),"")) -> Oportunidad con beneficios claros y específicos en los procesos de una o varias áreas de la Delegación INE Puebla, el SGC y/o Partes Interesadas, de la cual se espera un resultado a corto y mediano plazo.
A16: Fortaleza | B16: ='2a. Análisis Foda'!B14:E14 -> El posicionamiento de la Credencial para Votar como el principal medio de identificación aceptado. | C16: Positivo | N16: X | O16: Social/Cultural | P16: Alta | Q16: Importante | R16: =IFERROR(VLOOKUP(O16,Naturaleza,2,FALSE)*VLOOKUP('4b. Matriz - Contexto'!P16,Probabilidad,2,FALSE)*VLOOKUP('4b. Matriz - Contexto'!Q16,Severidad,2,FALSE),"") -> 600 | S16: =IF(A16="Debilidad",IF(R16="","",IF(AND(R16>0,R16<200),"Trivial",IF(OR(R16=200,AND(R16>200,R16<400)),"Tolerable",IF(OR(R16=400,AND(R16>400,R16<600)),"Moderado",IF(OR(R16=600,AND(R16>600,R16<800)),"Importante",IF(OR(R16=800,R16>800,R16<1000,R16=1000),"Intolerable","")))))),IF(A16="Amenaza",IF(R16="","",IF(AND(R16>0,R16<200),"Trivial",IF(OR(R16=200,AND(R16>200,R16<400)),"Tolerable",IF(OR(R16=400,AND(R16>400,R16<600)),"Moderado",IF(OR(R16=600,AND(R16>600,R16<800)),"Importante",IF(OR(R16=800,R16>800,R16<1000,R16=1000),"Intolerable","")))))),IF(A16="Fortaleza",IF(R16="","",IF(AND(R16>0,R16<250),"Limitada",IF(OR(R16=250,AND(R16>250,R16<500)),"Media",IF(OR(R16=500,AND(R16>500,R16<750)),"Potencial",IF(OR(R16=750,AND(R16>750,R16<=1000)),"Sobresaliente", ""))))), IF(A16="Oportunidad",IF(R16="","",IF(AND(R16>0,R16<250),"Limitada",IF(OR(R16=250,AND(R16>250,R16<500)),"Media",IF(OR(R16=500,AND(R16>500,R16<750)),"Potencial",IF(OR(R16=750,AND(R16>750,R16<=1000)),"Sobresaliente",""))))),"")))) -> Potencial | T16: =IFERROR(VLOOKUP(S16,'4a. Parámetros de riesgo'!$B$31:$C$35,2,FALSE),IFERROR(VLOOKUP(S16,'4a. Parámetros de riesgo'!$H$31:$I$35,2,FALSE),"")) -> APROPIARSE | U16: =IFERROR(VLOOKUP(T16,'4a. Parámetros de riesgo'!$C$31:$D$35,2,FALSE),IFERROR(VLOOKUP(T16,'4a. Parámetros de riesgo'!$I$31:$J$35,2,FALSE),"")) -> Oportunidad con beneficios claros y específicos en los procesos de una o varias áreas de la Delegación INE Puebla, el SGC y/o Partes Interesadas, de la cual se espera un resultado a corto y mediano plazo.
A17: Fortaleza | B17: ='2a. Análisis Foda'!B15:E15 -> Aplicación de protocolos para el regreso a la "nueva normalidad" derivada de la pandemia por COVID-19, para la atención de grupos vulnerables y atención de la ciudadanía en un marco de no discriminación por género u orientación sexual, grupos indígenas, situación religiosa, repatriados, víctimas de violencia, etc. | C17: Positivo | D17: X | E17: X | F17: X | G17: X | H17: X | O17: Operativo | P17: Alta | Q17: Importante | R17: =IFERROR(VLOOKUP(O17,Naturaleza,2,FALSE)*VLOOKUP('4b. Matriz - Contexto'!P17,Probabilidad,2,FALSE)*VLOOKUP('4b. Matriz - Contexto'!Q17,Severidad,2,FALSE),"") -> 1000 | S17: =IF(A17="Debilidad",IF(R17="","",IF(AND(R17>0,R17<200),"Trivial",IF(OR(R17=200,AND(R17>200,R17<400)),"Tolerable",IF(OR(R17=400,AND(R17>400,R17<600)),"Moderado",IF(OR(R17=600,AND(R17>600,R17<800)),"Importante",IF(OR(R17=800,R17>800,R17<1000,R17=1000),"Intolerable","")))))),IF(A17="Amenaza",IF(R17="","",IF(AND(R17>0,R17<200),"Trivial",IF(OR(R17=200,AND(R17>200,R17<400)),"Tolerable",IF(OR(R17=400,AND(R17>400,R17<600)),"Moderado",IF(OR(R17=600,AND(R17>600,R17<800)),"Importante",IF(OR(R17=800,R17>800,R17<1000,R17=1000),"Intolerable","")))))),IF(A17="Fortaleza",IF(R17="","",IF(AND(R17>0,R17<250),"Limitada",IF(OR(R17=250,AND(R17>250,R17<500)),"Media",IF(OR(R17=500,AND(R17>500,R17<750)),"Potencial",IF(OR(R17=750,AND(R17>750,R17<=1000)),"Sobresaliente", ""))))), IF(A17="Oportunidad",IF(R17="","",IF(AND(R17>0,R17<250),"Limitada",IF(OR(R17=250,AND(R17>250,R17<500)),"Media",IF(OR(R17=500,AND(R17>500,R17<750)),"Potencial",IF(OR(R17=750,AND(R17>750,R17<=1000)),"Sobresaliente",""))))),"")))) -> Sobresaliente | T17: =IFERROR(VLOOKUP(S17,'4a. Parámetros de riesgo'!$B$31:$C$35,2,FALSE),IFERROR(VLOOKUP(S17,'4a. Parámetros de riesgo'!$H$31:$I$35,2,FALSE),"")) -> EXPLOTARLA | U17: =IFERROR(VLOOKUP(T17,'4a. Parámetros de riesgo'!$C$31:$D$35,2,FALSE),IFERROR(VLOOKUP(T17,'4a. Parámetros de riesgo'!$I$31:$J$35,2,FALSE),"")) -> Oportunidad con beneficios claros, generales y específicos en los procesos de varias o todas las áreas de la Delegación INE Puebla, el SGC y/o Partes Interesadas de la cual se obtiene un resultado a corto, mediano y/o largo plazo.
